Workbook

Sheet Ringkasan
A1: AntarKita - Model Biaya SDM: Ringkasan Eksekutif
A2: Tanggal penyusunan: 7 September 2026 | Versi model 1.0 | Penyusun: Analis Keuangan SDM AntarKita
A3: PERINGATAN WAJIB DIBACA: seluruh PITA GAJI dalam model ini berlabel [ASUMSI]. Angka tersebut adalah konstruksi penyusun (tabel A.4.3 riset), BUKAN kutipan benchmark pasar, dan tidak boleh disajikan sebagai klaim faktual. Tarif iuran BPJS, plafon upah, UMK dan dasar THR BERSUMBER dan dikutip - lihat lembar 'Sumber & Catatan'.
A5: A. ANGKA KUNCI PER FASE
A6: Metrik | B6: Fase 0 (bulan 1-3) | C6: Fase 1 (bulan 4-12) | D6: Fase 2 (bulan 13-24) | E6: Sumber angka
A7: Jumlah karyawan (kumulatif) | B7: =Headcount!$H$43 -> 9 | C7: =Headcount!$I$43 -> 24 | D7: =Headcount!$J$43 -> 42 | E7: Lembar 'Headcount' - target mengikat DESAIN-ORGANISASI §3
A8: Biaya SDM per bulan (Rp) | B8: ='Biaya Bulanan'!$Y$64 -> 230332093 | C8: ='Biaya Bulanan'!$Z$64 -> 4.3555549e+08 | D8: ='Biaya Bulanan'!$AA$64 -> 6.3627206e+08 | E8: Lembar 'Biaya Bulanan' baris TOTAL (run-rate pada staf penuh fase tsb.)
A9: Biaya SDM per tahun / run-rate 12 bulan (Rp) | B9: ='Biaya Bulanan'!$Y$64*12 -> 2763985116 | C9: ='Biaya Bulanan'!$Z$64*12 -> 5226665838 | D9: ='Biaya Bulanan'!$AA$64*12 -> 7635264741 | E9: Run-rate, bukan biaya aktual fase (fase 0 & 1 lebih pendek dari 12 bulan)
A10: Rata-rata biaya SDM per orang per bulan (Rp) | B10: =IF(B7=0,0,B8/B7) -> 25592455 | C10: =IF(C7=0,0,C8/C7) -> 18148145 | D10: =IF(D7=0,0,D8/D7) -> 15149335 | E10: Turunan: biaya per bulan / jumlah karyawan
A11: Rasio total cost to company : gaji pokok (rata-rata tertimbang) | B11: =IF(SUMPRODUCT('Biaya Bulanan'!$K$26:$K$63,'Biaya Bulanan'!$V$26:$V$63)=0,0,B8/SUMPRODUCT('Biaya Bulanan'!$K$26:$K$63,'Biaya Bulanan'!$V$26:$V$63)) -> 1.2760781 | C11: =C8/SUMPRODUCT('Biaya Bulanan'!$K$26:$K$63,'Biaya Bulanan'!$W$26:$W$63) -> 1.2838776 | D11: =D8/SUMPRODUCT('Biaya Bulanan'!$K$26:$K$63,'Biaya Bulanan'!$X$26:$X$63) -> 1.2892398 | E11: Kebijakan DESAIN §4.3 memakai angka indikatif 1,19x - lihat catatan koreksi
A12: Biaya non-gaji SDM berulang per bulan (Rp) | B12: ='Biaya Non-Gaji'!$I$11 -> 19350000 | C12: ='Biaya Non-Gaji'!$J$11 -> 48000000 | D12: ='Biaya Non-Gaji'!$K$11 -> 78300000 | E12: Lembar 'Biaya Non-Gaji' Subtotal A - SELURUHNYA [ASUMSI]
A14: B. BIAYA KUMULATIF 24 BULAN & PORSI TERHADAP KEBUTUHAN PENDANAAN
A15: Pos | B15: Nilai (Rp) | E15: Sumber / status
A16: Biaya SDM (gaji + iuran + THR) kumulatif bulan 1-24 | B16: ='Proyeksi 24 Bulan'!$D$55 -> 11689208853 | E16: Lembar 'Proyeksi 24 Bulan' - mengikuti jadwal rekrutmen per posisi
A17: Biaya SDM kumulatif bulan 1-12 (tahun pertama) | B17: ='Proyeksi 24 Bulan'!$D$56 -> 4443025431 | E17: Lembar 'Proyeksi 24 Bulan'
A18: Biaya non-gaji SDM kumulatif bulan 1-24 | B18: ='Biaya Non-Gaji'!$M$19 -> 1927050000 | E18: Lembar 'Biaya Non-Gaji' - SELURUHNYA [ASUMSI]
A19: TOTAL BIAYA TERKAIT SDM 24 BULAN | B19: =B16+B18 -> 13616258853 | E19: Jumlah dua baris di atas
A20: Modal minimum sektoral KBLI 53200 Aktivitas Kurir | B20: 500000000 | E20: [S-41] Klinik Hukumonline 20 Apr 2026 - kegiatan berisiko tinggi
A21: Pos non-SDM lainnya 24 bulan (insentif mitra, pemasaran, infrastruktur, perizinan) | B21: 12000000000 | E21: [ASUMSI] INPUT PENGGUNA - WAJIB diganti dengan angka rencana bisnis. Tidak ada sumber (CAC/CAD tidak ditemukan benchmark-nya)
A22: KEBUTUHAN PENDANAAN 24 BULAN | B22: =B19+B20+B21 -> 26116258853 | E22: Total biaya terkait SDM + modal sektoral + pos non-SDM lainnya
A23: Porsi BIAYA SDM (gaji) terhadap kebutuhan pendanaan 24 bulan | B23: =B16/B22 -> 0.44758359 | E23: Sensitif terhadap 'Pos non-SDM lainnya' yang berlabel [ASUMSI]
A24: Porsi TOTAL BIAYA TERKAIT SDM (gaji + non-gaji) terhadap kebutuhan pendanaan 24 bulan | B24: =B19/B22 -> 0.52137096 | E24: Sensitif terhadap 'Pos non-SDM lainnya' yang berlabel [ASUMSI]
A26: C. SKENARIO - HEMAT / DASAR / AGRESIF
A27: Skenario | B27: Posisi pita gaji | C27: Faktor jumlah posisi | D27: Headcount Fase 2 (orang) | E27: Biaya SDM/bulan Fase 2 (Rp) | F27: Biaya SDM/tahun Fase 2 (Rp) | G27: Biaya SDM kumulatif 24 bulan (Rp) | H27: Keterangan
A28: Hemat | B28: P25 | C28: 0.85 | D28: =ROUND(Headcount!$J$43*$C28,0) -> 36 | E28: =$C28*SUMPRODUCT('Biaya Bulanan'!$AG$26:$AG$63,'Biaya Bulanan'!$X$26:$X$63) -> 4.281074e+08 | F28: =$E28*12 -> 5.1372888e+09 | G28: =$C28*SUMPRODUCT('Biaya Bulanan'!$AG$26:$AG$63,'Biaya Bulanan'!$AK$26:$AK$63) -> 8.0212246e+09 | H28: Menawar di batas bawah pita; 6 posisi ditunda ke Fase 3. Risiko: gagal merekrut Senior Engineer & Head, waktu rekrutmen memanjang.
A29: Dasar | B29: P50 | C29: 1 | D29: =ROUND(Headcount!$J$43*$C29,0) -> 42 | E29: =$C29*SUMPRODUCT('Biaya Bulanan'!$AH$26:$AH$63,'Biaya Bulanan'!$X$26:$X$63) -> 6.3627206e+08 | F29: =$E29*12 -> 7635264741 | G29: =$C29*SUMPRODUCT('Biaya Bulanan'!$AH$26:$AH$63,'Biaya Bulanan'!$AK$26:$AK$63) -> 11689208853 | H29: Kebijakan resmi DESAIN-ORGANISASI §4.2 (penawaran default P50; C-Level tetap P25 + ESOP). Ini angka yang dipakai seluruh lembar lain.
A30: Agresif | B30: P75 | C30: 1.15 | D30: =ROUND(Headcount!$J$43*$C30,0) -> 48 | E30: =$C30*SUMPRODUCT('Biaya Bulanan'!$AI$26:$AI$63,'Biaya Bulanan'!$X$26:$X$63) -> 8.8229182e+08 | F30: =$E30*12 -> 1.0587502e+10 | G30: =$C30*SUMPRODUCT('Biaya Bulanan'!$AI$26:$AI$63,'Biaya Bulanan'!$AK$26:$AK$63) -> 1.6002418e+10 | H30: Merebut talenta senior & mempercepat kota kedua; 6 posisi tambahan. Naikkan hanya bila pendanaan sudah pasti.
A31: Uji: skenario Dasar harus sama dengan lembar 'Biaya Bulanan' (selisih = 0) | E31: =E29-'Biaya Bulanan'!$AA$64 -> 0 | G31: =G29-'Proyeksi 24 Bulan'!$D$55 -> 0
A33: D. CATATAN PENTING
A34: 1. Tanggal penyusunan model: 7 September 2026. Seluruh sumber diakses pada tanggal yang sama (lihat lembar 'Sumber & Catatan').
A35: 2. SELURUH PITA GAJI BERLABEL [ASUMSI]. Diturunkan dari tabel A.4.3 riset yang sendiri merupakan konstruksi penyusun, bukan kutipan salary guide. Wajib divalidasi dengan minimal 5 penawaran gaji riil sebelum dipakai sebagai klaim.
A36: 3. Tarif JKK 0,54% (kantor) dan 0,89% (lapangan) juga [ASUMSI]: kelompok risiko ditetapkan BPJS Ketenagakerjaan berdasarkan jenis usaha, bukan deklarasi perusahaan.
A37: 4. PPh 21 (PP 58/2023, skema TER) TIDAK dimodelkan sebagai biaya perusahaan - dipotong dari upah pekerja. Tidak ada kebijakan gross-up dalam model ini.
A38: 5. Biaya mitra pengemudi (BPJS BPU, BHR 25%) BERADA DI LUAR model ini karena berstatus kemitraan, bukan hubungan kerja. Ini adalah risiko regulasi tingkat pertama - bila status berubah menjadi hubungan kerja, struktur biaya berubah fundamental.
A39: 6. Model tidak memuat kenaikan gaji tahunan, insentif variabel (maks. 20% - DESAIN §4.5), lembur, maupun beban ESOP.
A40: 7. Sel bertulisan BIRU adalah input yang boleh diubah investor; sel berlatar KUNING adalah asumsi kunci. Semua angka lain adalah rumus hidup.
A42: Sumber baris: seluruh angka pada lembar ini adalah tautan hidup ke lembar 'Headcount', 'Biaya Bulanan', 'Proyeksi 24 Bulan' dan 'Biaya Non-Gaji'. Dasar statutori: [S-07] s.d. [S-16]; UMK [S-01][S-03][S-04][S-05][S-06]; pita gaji [S-18][S-19] + [ASUMSI] A.4.3.

Sheet Headcount
A1: AntarKita - Daftar Posisi & Rencana Tenaga Kerja Bertahap
A2: Disusun 7 September 2026. Struktur mengikuti docs/organisasi/DESAIN-ORGANISASI.md §2 dan §3 (keputusan mengikat). Angka orang bersifat KUMULATIF per fase.
A4: No | B4: Direktorat | C4: Posisi | D4: Kota Kerja | E4: Kota Payroll | F4: Level | G4: Bulan Mulai | H4: Orang Fase 0 (bln 1-3) | I4: Orang Fase 1 (bln 4-12) | J4: Orang Fase 2 (bln 13-24) | K4: Catatan peran
A5: 1 | B5: Direksi & Tata Kelola | C5: Direktur Utama (CEO) | D5: Pekanbaru | E5: Pekanbaru | F5: C-Level | G5: 1 | H5: ='Biaya Bulanan'!$V$26 -> 1 | I5: ='Biaya Bulanan'!$W$26 -> 1 | J5: ='Biaya Bulanan'!$X$26 -> 1 | K5: Pemegang KPI kas & runway. Gaji tunai ditahan di P25; selisih dikompensasi ESOP (DESAIN-ORGANISASI §4.4).
A6: 2 | B6: Direksi & Tata Kelola | C6: HR & GA Generalist | D6: Pekanbaru | E6: Pekanbaru | F6: Staf Senior | G6: 3 | H6: ='Biaya Bulanan'!$V$27 -> 1 | I6: ='Biaya Bulanan'!$W$27 -> 1 | J6: ='Biaya Bulanan'!$X$27 -> 1 | K6: Garis putus ke seluruh direktorat: rekrutmen, payroll, BPJS, kantor 2 kota.
A7: 3 | B7: Teknologi | C7: Direktur Teknologi (CTO) | D7: Pekanbaru | E7: Pekanbaru | F7: C-Level | G7: 1 | H7: ='Biaya Bulanan'!$V$28 -> 1 | I7: ='Biaya Bulanan'!$W$28 -> 1 | J7: ='Biaya Bulanan'!$X$28 -> 1 | K7: KPI operasional sendiri: crash-free session & waktu balas API p95 (DESAIN §5).
A8: 4 | B8: Teknologi | C8: Engineering Manager | D8: Remote | E8: Pekanbaru | F8: Manajer | G8: 4 | H8: ='Biaya Bulanan'!$V$29 -> 0 | I8: ='Biaya Bulanan'!$W$29 -> 1 | J8: ='Biaya Bulanan'!$X$29 -> 1 | K8: Rentang kendali 3-6 engineer (DESAIN §1.4). Payroll mengikuti struktur Pekanbaru.
A9: 5 | B9: Teknologi | C9: Mobile Engineer (Senior) | D9: Pekanbaru | E9: Pekanbaru | F9: Senior | G9: 1 | H9: ='Biaya Bulanan'!$V$30 -> 1 | I9: ='Biaya Bulanan'!$W$30 -> 1 | J9: ='Biaya Bulanan'!$X$30 -> 1 | K9: Aplikasi pengguna & mitra; wajib ada sejak Fase 0 untuk uji tertutup.
A10: 6 | B10: Teknologi | C10: Mobile Engineer (Mid) | D10: Remote | E10: Pekanbaru | F10: Mid | G10: 5 | H10: ='Biaya Bulanan'!$V$31 -> 0 | I10: ='Biaya Bulanan'!$W$31 -> 1 | J10: ='Biaya Bulanan'!$X$31 -> 1
A11: 7 | B11: Teknologi | C11: Mobile Engineer (Mid) - gelombang 2 | D11: Remote | E11: Pekanbaru | F11: Mid | G11: 14 | H11: ='Biaya Bulanan'!$V$32 -> 0 | I11: ='Biaya Bulanan'!$W$32 -> 0 | J11: ='Biaya Bulanan'!$X$32 -> 1 | K11: Beban fitur dua kota + AntarFood/AntarSend.
A12: 8 | B12: Teknologi | C12: Backend Engineer (Senior) | D12: Pekanbaru | E12: Pekanbaru | F12: Senior | G12: 1 | H12: ='Biaya Bulanan'!$V$33 -> 1 | I12: ='Biaya Bulanan'!$W$33 -> 1 | J12: ='Biaya Bulanan'!$X$33 -> 1 | K12: Pemilik skema dompet & rekonsiliasi; kritikal untuk pemisahan tugas keuangan.
A13: 9 | B13: Teknologi | C13: Backend Engineer (Senior) - gelombang 2 | D13: Remote | E13: Pekanbaru | F13: Senior | G13: 19 | H13: ='Biaya Bulanan'!$V$34 -> 0 | I13: ='Biaya Bulanan'!$W$34 -> 0 | J13: ='Biaya Bulanan'!$X$34 -> 1
A14: 10 | B14: Teknologi | C14: Backend Engineer (Mid) | D14: Remote | E14: Pekanbaru | F14: Mid | G14: 4 | H14: ='Biaya Bulanan'!$V$35 -> 0 | I14: ='Biaya Bulanan'!$W$35 -> 1 | J14: ='Biaya Bulanan'!$X$35 -> 1
A15: 11 | B15: Teknologi | C15: Backend Engineer (Mid) - gelombang 2 | D15: Remote | E15: Pekanbaru | F15: Mid | G15: 13 | H15: ='Biaya Bulanan'!$V$36 -> 0 | I15: ='Biaya Bulanan'!$W$36 -> 0 | J15: ='Biaya Bulanan'!$X$36 -> 1
A16: 12 | B16: Teknologi | C16: QA Engineer | D16: Pekanbaru | E16: Pekanbaru | F16: Mid | G16: 6 | H16: ='Biaya Bulanan'!$V$37 -> 0 | I16: ='Biaya Bulanan'!$W$37 -> 1 | J16: ='Biaya Bulanan'!$X$37 -> 1 | K16: Gerbang rilis; menahan regresi pada alur pembayaran.
A17: 13 | B17: Teknologi | C17: QA Engineer - gelombang 2 | D17: Remote | E17: Pekanbaru | F17: Mid | G17: 15 | H17: ='Biaya Bulanan'!$V$38 -> 0 | I17: ='Biaya Bulanan'!$W$38 -> 0 | J17: ='Biaya Bulanan'!$X$38 -> 1
A18: 14 | B18: Teknologi | C18: Junior Software Engineer | D18: Pekanbaru | E18: Pekanbaru | F18: Junior | G18: 16 | H18: ='Biaya Bulanan'!$V$39 -> 0 | I18: ='Biaya Bulanan'!$W$39 -> 0 | J18: ='Biaya Bulanan'!$X$39 -> 1 | K18: Jalur kaderisasi lokal; menekan biaya rata-rata per engineer.
A19: 15 | B19: Teknologi | C19: Junior Software Engineer - Padang | D19: Padang | E19: Padang | F19: Junior | G19: 18 | H19: ='Biaya Bulanan'!$V$40 -> 0 | I19: ='Biaya Bulanan'!$W$40 -> 0 | J19: ='Biaya Bulanan'!$X$40 -> 1 | K19: Direkrut di Padang; struktur payroll Padang.
A20: 16 | B20: Teknologi | C20: Product Designer (UI/UX) | D20: Pekanbaru | E20: Pekanbaru | F20: Mid | G20: 2 | H20: ='Biaya Bulanan'!$V$41 -> 1 | I20: ='Biaya Bulanan'!$W$41 -> 1 | J20: ='Biaya Bulanan'!$X$41 -> 1
A21: 17 | B21: Teknologi | C21: Product Designer (UI/UX) - gelombang 2 | D21: Remote | E21: Pekanbaru | F21: Mid | G21: 17 | H21: ='Biaya Bulanan'!$V$42 -> 0 | I21: ='Biaya Bulanan'!$W$42 -> 0 | J21: ='Biaya Bulanan'!$X$42 -> 1
A22: 18 | B22: Teknologi | C22: Data Analyst | D22: Pekanbaru | E22: Pekanbaru | F22: Mid | G22: 13 | H22: ='Biaya Bulanan'!$V$43 -> 0 | I22: ='Biaya Bulanan'!$W$43 -> 0 | J22: ='Biaya Bulanan'!$X$43 -> 1 | K22: Menyusun laporan Portal Eksekutif & audit KPI dari tabel orders/tickets.
A23: 19 | B23: Operasi | C23: Direktur Operasi (COO) | D23: Pekanbaru | E23: Pekanbaru | F23: C-Level | G23: 1 | H23: ='Biaya Bulanan'!$V$44 -> 1 | I23: ='Biaya Bulanan'!$W$44 -> 1 | J23: ='Biaya Bulanan'!$X$44 -> 1 | K23: Gaji tunai ditahan di P25 (DESAIN §4.4).
A24: 20 | B24: Operasi | C24: City Manager Pekanbaru | D24: Pekanbaru | E24: Pekanbaru | F24: Manajer | G24: 2 | H24: ='Biaya Bulanan'!$V$45 -> 1 | I24: ='Biaya Bulanan'!$W$45 -> 1 | J24: ='Biaya Bulanan'!$X$45 -> 1 | K24: P&L tingkat kota; target likuiditas pasar Fase 1.
A25: 21 | B25: Operasi | C25: Ops Supervisor Pekanbaru | D25: Pekanbaru | E25: Pekanbaru | F25: Supervisor | G25: 4 | H25: ='Biaya Bulanan'!$V$46 -> 0 | I25: ='Biaya Bulanan'!$W$46 -> 1 | J25: ='Biaya Bulanan'!$X$46 -> 1
A26: 22 | B26: Operasi | C26: Partner Acquisition Pekanbaru | D26: Pekanbaru | E26: Pekanbaru | F26: Staf | G26: 4 | H26: ='Biaya Bulanan'!$V$47 -> 0 | I26: ='Biaya Bulanan'!$W$47 -> 2 | J26: ='Biaya Bulanan'!$X$47 -> 2 | K26: 2 orang. Target dihitung dari mitra AKTIF (hanya +-20% mitra terdaftar aktif, [S-58]). Insentif variabel maks. 20% (DESAIN §4.5) TIDAK dimodelkan di sini.
A27: 23 | B27: Operasi | C27: Head of Customer Experience | D27: Pekanbaru | E27: Pekanbaru | F27: Head | G27: 4 | H27: ='Biaya Bulanan'!$V$48 -> 0 | I27: ='Biaya Bulanan'!$W$48 -> 1 | J27: ='Biaya Bulanan'!$X$48 -> 1 | K27: Merangkap CS Lead pada Fase 1 (tidak ada peran yang hanya mengawasi, DESAIN §1.5).
A28: 24 | B28: Operasi | C28: CS Agent Pekanbaru (shift) | D28: Pekanbaru | E28: Pekanbaru | F28: Staf | G28: 5 | H28: ='Biaya Bulanan'!$V$49 -> 0 | I28: ='Biaya Bulanan'!$W$49 -> 3 | J28: ='Biaya Bulanan'!$X$49 -> 3 | K28: 3 orang untuk 3 shift. Gaji pokok P25 = lantai UMK Pekanbaru.
A29: 25 | B29: Operasi | C29: Trust & Safety Officer | D29: Pekanbaru | E29: Pekanbaru | F29: Staf Senior | G29: 6 | H29: ='Biaya Bulanan'!$V$50 -> 0 | I29: ='Biaya Bulanan'!$W$50 -> 1 | J29: ='Biaya Bulanan'!$X$50 -> 1 | K29: Anti-fraud, penanganan insiden, tombol SOS. Wajib ada sebelum volume order naik.
A30: 26 | B30: Operasi | C30: City Manager Padang | D30: Padang | E30: Padang | F30: Manajer | G30: 13 | H30: ='Biaya Bulanan'!$V$51 -> 0 | I30: ='Biaya Bulanan'!$W$51 -> 0 | J30: ='Biaya Bulanan'!$X$51 -> 1 | K30: Pembuka kota kedua; pola +1 City Manager + 2 Ops per kota baru (DESAIN §1.1).
A31: 27 | B31: Operasi | C31: Partner Acquisition Padang | D31: Padang | E31: Padang | F31: Staf | G31: 13 | H31: ='Biaya Bulanan'!$V$52 -> 0 | I31: ='Biaya Bulanan'!$W$52 -> 0 | J31: ='Biaya Bulanan'!$X$52 -> 1
A32: 28 | B32: Operasi | C32: Ops Supervisor Padang | D32: Padang | E32: Padang | F32: Supervisor | G32: 14 | H32: ='Biaya Bulanan'!$V$53 -> 0 | I32: ='Biaya Bulanan'!$W$53 -> 0 | J32: ='Biaya Bulanan'!$X$53 -> 1
A33: 29 | B33: Operasi | C33: CS Agent Padang (shift) | D33: Padang | E33: Padang | F33: Staf | G33: 14 | H33: ='Biaya Bulanan'!$V$54 -> 0 | I33: ='Biaya Bulanan'!$W$54 -> 0 | J33: ='Biaya Bulanan'!$X$54 -> 2 | K33: 2 orang. CS Pekanbaru menutup shift ketiga lintas kota.
A34: 30 | B34: Operasi | C34: Partner Acquisition Padang - gelombang 2 | D34: Padang | E34: Padang | F34: Staf | G34: 15 | H34: ='Biaya Bulanan'!$V$55 -> 0 | I34: ='Biaya Bulanan'!$W$55 -> 0 | J34: ='Biaya Bulanan'!$X$55 -> 1
A35: 31 | B35: Growth & Partnership | C35: Head of Growth & Partnership | D35: Pekanbaru | E35: Pekanbaru | F35: Head | G35: 4 | H35: ='Biaya Bulanan'!$V$56 -> 0 | I35: ='Biaya Bulanan'!$W$56 -> 1 | J35: ='Biaya Bulanan'!$X$56 -> 1 | K35: Memikul target pendapatan non-komisi - penting karena batas potongan ojek roda dua maks. 8% (Perpres 27/2026, [S-25]).
A36: 32 | B36: Growth & Partnership | C36: Digital Marketing Staff | D36: Pekanbaru | E36: Pekanbaru | F36: Staf | G36: 13 | H36: ='Biaya Bulanan'!$V$57 -> 0 | I36: ='Biaya Bulanan'!$W$57 -> 0 | J36: ='Biaya Bulanan'!$X$57 -> 1
A37: 33 | B37: Growth & Partnership | C37: Merchant Acquisition Officer | D37: Pekanbaru | E37: Pekanbaru | F37: Staf | G37: 13 | H37: ='Biaya Bulanan'!$V$58 -> 0 | I37: ='Biaya Bulanan'!$W$58 -> 0 | J37: ='Biaya Bulanan'!$X$58 -> 1 | K37: Akuisisi merchant AntarFood/AntarShop; pita disamakan dengan Field/Driver Acquisition officer.
A38: 34 | B38: Keuangan | C38: Head of Finance | D38: Pekanbaru | E38: Pekanbaru | F38: C-Level | G38: 2 | H38: ='Biaya Bulanan'!$V$59 -> 1 | I38: ='Biaya Bulanan'!$W$59 -> 1 | J38: ='Biaya Bulanan'!$X$59 -> 1 | K38: Merangkap Direktur Keuangan pada Fase 1-2 (DESAIN §2). Gaji tunai ditahan di P25.
A39: 35 | B39: Keuangan | C39: Finance & Accounting Staff | D39: Pekanbaru | E39: Pekanbaru | F39: Staf | G39: 4 | H39: ='Biaya Bulanan'!$V$60 -> 0 | I39: ='Biaya Bulanan'!$W$60 -> 1 | J39: ='Biaya Bulanan'!$X$60 -> 1 | K39: Pelaksana pencairan - terpisah dari penyetuju dan perekonsiliasi (DESAIN §6).
A40: 36 | B40: Keuangan | C40: Treasury/Settlement Officer | D40: Pekanbaru | E40: Pekanbaru | F40: Staf Senior | G40: 13 | H40: ='Biaya Bulanan'!$V$61 -> 0 | I40: ='Biaya Bulanan'!$W$61 -> 0 | J40: ='Biaya Bulanan'!$X$61 -> 1 | K40: Rekonsiliasi dompet & payout mitra; pemisah tugas ketiga. Relevan dengan ambang dana float Rp1 miliar ([S-31]).
A41: 37 | B41: Keuangan | C41: Finance & Accounting Staff - Padang | D41: Padang | E41: Padang | F41: Staf | G41: 16 | H41: ='Biaya Bulanan'!$V$62 -> 0 | I41: ='Biaya Bulanan'!$W$62 -> 0 | J41: ='Biaya Bulanan'!$X$62 -> 1
...

Sheet Pita Gaji
A1: AntarKita - Pita Gaji per Posisi, Pekanbaru & Padang
A2: Disusun 7 September 2026. SELURUH ANGKA PADA LEMBAR INI ADALAH [ASUMSI] - diturunkan dari tabel A.4.3 docs/riset/RISET-KOMPENSASI-REGULASI.md. Bukan kutipan benchmark pasar. Wajib divalidasi dengan minimal 5 penawaran gaji riil.
C4: PEKANBARU - [ASUMSI] | F4: PADANG - [ASUMSI]
A5: Kunci Pita (posisi rujukan) | B5: Status data | C5: P25 [ASUMSI] (Rp) | D5: P50 [ASUMSI] (Rp) | E5: P75 [ASUMSI] (Rp) | F5: P25 [ASUMSI] (Rp) | G5: P50 [ASUMSI] (Rp) | H5: P75 [ASUMSI] (Rp) | I5: Rasio P50 : UMK Pekanbaru | J5: Rasio P50 : UMP Padang | K5: Uji kewajaran: P25 >= UMK kota? | L5: Basis penurunan / sumber
A6: CEO / Direktur Utama | B6: A.4.3 riset | C6: 35000000 | D6: =(C6+E6)/2 -> 47500000 | E6: 60000000 | F6: 35000000 | G6: =(F6+H6)/2 -> 47500000 | H6: 60000000 | I6: =D6/UMK_Pekanbaru -> 11.880407 | J6: =G6/UMP_Padang -> 14.92324 | K6: =IF(AND(C6>=UMK_Pekanbaru,F6>=UMP_Padang),"OK","PERIKSA") -> OK | L6: A.4.3: tidak ditemukan sumber kredibel; asumsi murni, C-level dikompensasi ekuitas pra-pendanaan
A7: CTO | B7: A.4.3 riset | C7: 30000000 | D7: =(C7+E7)/2 -> 42500000 | E7: 55000000 | F7: 30000000 | G7: =(F7+H7)/2 -> 42500000 | H7: 55000000 | I7: =D7/UMK_Pekanbaru -> 10.629838 | J7: =G7/UMP_Padang -> 13.352372 | K7: =IF(AND(C7>=UMK_Pekanbaru,F7>=UMP_Padang),"OK","PERIKSA") -> OK | L7: A.4.3: ~0,55 x Head of Engineering Jakarta 2025 (Rp81 jt) [S-19]
A8: Engineering Manager | B8: A.4.3 riset | C8: 20000000 | D8: =(C8+E8)/2 -> 27500000 | E8: 35000000 | F8: 20000000 | G8: =(F8+H8)/2 -> 27500000 | H8: 35000000 | I8: =D8/UMK_Pekanbaru -> 6.8781305 | J8: =G8/UMP_Padang -> 8.6397703 | K8: =IF(AND(C8>=UMK_Pekanbaru,F8>=UMP_Padang),"OK","PERIKSA") -> OK | L8: A.4.3: ~0,40 x Engineering Manager Jakarta 2025 (Rp67 jt) [S-19]
A9: Senior Software Engineer | B9: A.4.3 riset | C9: 15000000 | D9: =(C9+E9)/2 -> 20000000 | E9: 25000000 | F9: 15000000 | G9: =(F9+H9)/2 -> 20000000 | H9: 25000000 | I9: =D9/UMK_Pekanbaru -> 5.0022767 | J9: =G9/UMP_Padang -> 6.2834693 | K9: =IF(AND(C9>=UMK_Pekanbaru,F9>=UMP_Padang),"OK","PERIKSA") -> OK | L9: A.4.3: ~0,55 x Senior SWE Jakarta 2023 (Rp35 jt) [S-18] + inflasi upah
A10: Mid Software Engineer | B10: A.4.3 riset | C10: 9000000 | D10: =(C10+E10)/2 -> 12000000 | E10: 15000000 | F10: 9000000 | G10: =(F10+H10)/2 -> 12000000 | H10: 15000000 | I10: =D10/UMK_Pekanbaru -> 3.001366 | J10: =G10/UMP_Padang -> 3.7700816 | K10: =IF(AND(C10>=UMK_Pekanbaru,F10>=UMP_Padang),"OK","PERIKSA") -> OK | L10: A.4.3: ~0,55 x Back-end Developer Jakarta 2025 (Rp25 jt) [S-19]
A11: Junior Software Engineer | B11: A.4.3 riset | C11: 6000000 | D11: =(C11+E11)/2 -> 7500000 | E11: 9000000 | F11: 5500000 | G11: =(F11+H11)/2 -> 7000000 | H11: 8500000 | I11: =D11/UMK_Pekanbaru -> 1.8758538 | J11: =G11/UMP_Padang -> 2.1992143 | K11: =IF(AND(C11>=UMK_Pekanbaru,F11>=UMP_Padang),"OK","PERIKSA") -> OK | L11: A.4.3: 1,5-2,3 x UMK kota [S-05]/[S-03]
A12: Product Designer / UI-UX | B12: A.4.3 riset | C12: 8000000 | D12: =(C12+E12)/2 -> 13000000 | E12: 18000000 | F12: 8000000 | G12: =(F12+H12)/2 -> 13000000 | H12: 18000000 | I12: =D12/UMK_Pekanbaru -> 3.2514799 | J12: =G12/UMP_Padang -> 4.084255 | K12: =IF(AND(C12>=UMK_Pekanbaru,F12>=UMP_Padang),"OK","PERIKSA") -> OK | L12: A.4.3: ~0,25-0,45 x UX/UI Designer Jakarta 2025 (Rp43 jt) [S-19]
A13: QA Engineer | B13: A.4.3 riset | C13: 7000000 | D13: =(C13+E13)/2 -> 10000000 | E13: 13000000 | F13: 6500000 | G13: =(F13+H13)/2 -> 9250000 | H13: 12000000 | I13: =D13/UMK_Pekanbaru -> 2.5011384 | J13: =G13/UMP_Padang -> 2.9061045 | K13: =IF(AND(C13>=UMK_Pekanbaru,F13>=UMP_Padang),"OK","PERIKSA") -> OK | L13: A.4.3: ~0,30-0,50 x QA Engineer Jakarta 2023 (Rp25 jt) [S-18]
A14: Data Analyst | B14: A.4.3 riset | C14: 8000000 | D14: =(C14+E14)/2 -> 11500000 | E14: 15000000 | F14: 8000000 | G14: =(F14+H14)/2 -> 11500000 | H14: 15000000 | I14: =D14/UMK_Pekanbaru -> 2.8763091 | J14: =G14/UMP_Padang -> 3.6129948 | K14: =IF(AND(C14>=UMK_Pekanbaru,F14>=UMP_Padang),"OK","PERIKSA") -> OK | L14: A.4.3: di bawah Lead Data Scientist [S-19]; level analyst tidak tersedia di sumber
A15: Head of Operations | B15: A.4.3 riset | C15: 20000000 | D15: =(C15+E15)/2 -> 27500000 | E15: 35000000 | F15: 20000000 | G15: =(F15+H15)/2 -> 27500000 | H15: 35000000 | I15: =D15/UMK_Pekanbaru -> 6.8781305 | J15: =G15/UMP_Padang -> 8.6397703 | K15: =IF(AND(C15>=UMK_Pekanbaru,F15>=UMP_Padang),"OK","PERIKSA") -> OK | L15: A.4.3: tidak ditemukan sumber kredibel; anchor setara Engineering Manager lokal
A16: City / Area Manager | B16: A.4.3 riset | C16: 10000000 | D16: =(C16+E16)/2 -> 14000000 | E16: 18000000 | F16: 9000000 | G16: =(F16+H16)/2 -> 12500000 | H16: 16000000 | I16: =D16/UMK_Pekanbaru -> 3.5015937 | J16: =G16/UMP_Padang -> 3.9271683 | K16: =IF(AND(C16>=UMK_Pekanbaru,F16>=UMP_Padang),"OK","PERIKSA") -> OK | L16: A.4.3: 2,5-4,5 x UMK kota [S-05]/[S-03]
A17: Ops Supervisor | B17: A.4.3 riset | C17: 6000000 | D17: =(C17+E17)/2 -> 7500000 | E17: 9000000 | F17: 5000000 | G17: =(F17+H17)/2 -> 6500000 | H17: 8000000 | I17: =D17/UMK_Pekanbaru -> 1.8758538 | J17: =G17/UMP_Padang -> 2.0421275 | K17: =IF(AND(C17>=UMK_Pekanbaru,F17>=UMP_Padang),"OK","PERIKSA") -> OK | L17: A.4.3: 1,5-2,3 x UMK kota [S-05]/[S-03]
... A28: Treasury / Settlement Officer | B28: TURUNAN penyusun model | C28: 6250000 | D28: =(C28+E28)/2 -> 8125000 | E28: 10000000 | F28: 5000000 | G28: =(F28+H28)/2 -> 6875000 | H28: 8750000 | I28: =D28/UMK_Pekanbaru -> 2.0321749 | J28: =G28/UMP_Padang -> 2.1599426 | K28: =IF(AND(C28>=UMK_Pekanbaru,F28>=UMP_Padang),"OK","PERIKSA") -> OK | L28: TIDAK ADA baris di A.4.3. [ASUMSI] 1,25 x pita Finance & Accounting staff A.4.3
A30: Metode P50: titik tengah aritmetik antara P25 dan P75 (bukan median pasar - tidak ada data pasar yang dapat dikutip).
A31: Jumlah baris dengan status 'PERIKSA' (harus 0): | D31: =COUNTIF(K6:K28,"PERIKSA") -> 0
A33: Sumber baris: tabel A.4.3 docs/riset/RISET-KOMPENSASI-REGULASI.md - seluruhnya konstruksi penyusun riset, diturunkan dari [S-18] (Michael Page 2023), [S-19] (Michael Page 2025) dan UMK kota [S-01][S-03][S-04][S-05][S-06]. Faktor geografis Jakarta -> Pekanbaru/Padang (0,45-0,70) adalah [ASUMSI] tanpa dasar empiris.
A34: Tiga baris berstatus 'TURUNAN penyusun model' (Head of Customer Experience, Trust & Safety Officer, Treasury / Settlement Officer) TIDAK ADA di A.4.3 dan merupakan asumsi tambahan penyusun model biaya - dasar penurunannya ditulis di kolom terakhir.
A35: Posisi berstatus Remote memakai struktur payroll Pekanbaru (kota induk). UMK Pekanbaru 2026 Rp3.998.179; UMK/UMP Padang 2026 Rp3.182.955 - selisih 25,6%.

Sheet Biaya Bulanan
A1: AntarKita - Biaya SDM Bulanan per Posisi (total cost to company)
A2: Disusun 7 September 2026. Seluruh pita gaji berlabel [ASUMSI] (lihat lembar 'Pita Gaji'). Tulisan BIRU = input yang boleh diubah investor; tulisan hitam = rumus hidup.
A4: BLOK ASUMSI (bernama) - seluruh rumus di berkas ini merujuk ke sel-sel di bawah
A5: Parameter | D5: Nilai | E5: Dasar hukum / sumber / status data
A6: UMK Kota Pekanbaru 2026 (Rp/bulan) | D6: 3998179.5 | E6: [S-01] [S-05] [S-06] - berlaku 1 Januari 2026
A7: UMK/UMP Kota Padang 2026 (Rp/bulan) | D7: 3182955 | E7: [S-03] [S-04] - Sumbar tidak menetapkan UMK tersendiri
A8: Tunjangan tetap (% gaji pokok) | D8: 0.1 | E8: [ASUMSI] penyusun model - transport & komunikasi. Tidak ada sumber. Gaji pokok tetap 90,9% dari upah, memenuhi batas min. 75% PP 36/2021 [S-14]
A9: JKK pemberi kerja - karyawan kantor | D9: 0.0054 | E9: [ASUMSI] kelompok risiko RENDAH, PP 44/2015 [S-08]. Penetapan final oleh BPJS Ketenagakerjaan
A10: JKK pemberi kerja - staf lapangan | D10: 0.0089 | E10: [ASUMSI] kelompok risiko SEDANG, PP 44/2015 [S-08]. Penetapan final oleh BPJS Ketenagakerjaan
A11: JKM pemberi kerja | D11: 0.003 | E11: PP 44/2015 [S-07] [S-08] - tanpa batas upah
A12: JHT pemberi kerja | D12: 0.037 | E12: PP 46/2015 [S-07] - tanpa batas upah
A13: JP pemberi kerja | D13: 0.02 | E13: PP 45/2015 [S-07]
A14: Plafon upah dasar JP (Rp/bulan) | D14: 11086300 | E14: [S-09] [S-10] - berlaku sejak Maret 2026
A15: BPJS Kesehatan pemberi kerja | D15: 0.04 | E15: Perpres 64/2020 Pasal 30 [S-12] (total 5%: 4% pemberi kerja + 1% pekerja)
A16: Plafon upah dasar BPJS Kesehatan (Rp/bulan) | D16: 12000000 | E16: Perpres 64/2020 Pasal 30 & 32 [S-12] [S-13]. Batas bawah = UMK/UMP kota
A17: Akrual THR per bulan (% upah) | D17: 0.0833 | E17: Setara 1/12 upah sebulan. PP 36/2021 [S-14], Permenaker 6/2016 [S-15], SE Menaker M/3/HK.04.00/III/2026 [S-16]
A18: Pita gaji aktif untuk seluruh posisi non-C-Level | D18: P50 | E18: Kebijakan penawaran default (DESAIN-ORGANISASI §4.2). Ubah ke P25 / P75 untuk skenario Hemat / Agresif
A19: Pita gaji untuk posisi C-Level | D19: P25 | E19: DESAIN-ORGANISASI §4.4 - gaji tunai C-level ditahan di P25, selisih dikompensasi ESOP
A21: PPh 21 (skema TER, PP 58/2023 [S-17]) TIDAK dimodelkan sebagai biaya perusahaan - dipotong dari upah pekerja. Tidak ada kebijakan gross-up dalam model ini; bila kelak diterapkan, biaya perusahaan naik di atas angka lembar ini.
A22: Iuran pekerja (JHT 2% + JP 1% + JKN 1%) juga TIDAK termasuk - itu potongan upah, bukan beban pemberi kerja. Mitra pengemudi (BPU/BHR) berada DI LUAR cakupan model ini karena berstatus kemitraan, bukan hubungan kerja.
AC24: BLOK BANTU SKENARIO & SENSITIVITAS (dipakai lembar Ringkasan dan Sensitivitas)
A25: No | B25: Direktorat | C25: Posisi | D25: Kota Kerja | E25: Kota Payroll | F25: Level | G25: Kunci Pita Gaji | H25: Kelompok Risiko JKK | I25: Bulan Mulai | J25: Pita Dipakai | K25: Gaji Pokok /orang (Rp) | L25: Tunjangan Tetap /orang (Rp) | M25: Upah Dasar Perhitungan (Rp) | N25: JKK Pemberi Kerja (Rp) | O25: JKM Pemberi Kerja (Rp) | P25: JHT Pemberi Kerja (Rp) | Q25: JP Pemberi Kerja (Rp) | R25: BPJS Kesehatan Pemberi Kerja (Rp) | S25: Akrual THR (Rp) | T25: TOTAL COST TO COMPANY /orang (Rp) | U25: Rasio CTC : Gaji Pokok | V25: Orang Fase 0 | W25: Orang Fase 1 | X25: Orang Fase 2 | Y25: Biaya/bulan Fase 0 (Rp) | Z25: Biaya/bulan Fase 1 (Rp) | AA25: Biaya/bulan Fase 2 (Rp) | AC25: Gaji P25 (Rp) | AD25: Gaji P50 (Rp) | AE25: Gaji P75 (Rp) | AF25: Gaji pita C-Level (Rp) | AG25: CTC skenario P25 (Rp) | AH25: CTC skenario P50 (Rp) | AI25: CTC skenario P75 (Rp) | AJ25: Bulan-orang bln 1-12 | AK25: Bulan-orang bln 1-24 | AL25: Uji upah vs UMK
A26: 1 | B26: Direksi & Tata Kelola | C26: Direktur Utama (CEO) | D26: Pekanbaru | E26: Pekanbaru | F26: C-Level | G26: CEO / Direktur Utama | H26: Kantor | I26: 1 | J26: =IF($F26="C-Level",Pita_CLevel,Pita_Aktif) -> P25 | K26: =IF($J26="P25",$AC26,IF($J26="P50",$AD26,$AE26)) -> 35000000 | L26: =$K26*Tunjangan_Pct -> 3500000 | M26: =$K26+$L26 -> 38500000 | N26: =$M26*IF($H26="Lapangan",Tarif_JKK_Lapangan,Tarif_JKK_Kantor) -> 207900 | O26: =$M26*Tarif_JKM -> 115500 | P26: =$M26*Tarif_JHT -> 1424500 | Q26: =MIN($M26,Plafon_JP)*Tarif_JP -> 221726 | R26: =MIN(MAX($M26,IF($E26="Padang",UMP_Padang,UMK_Pekanbaru)),Plafon_JKN)*Tarif_JKN -> 480000 | S26: =$M26*Tarif_THR -> 3207050 | T26: =SUM($M26:$S26) -> 44156676 | U26: =$T26/$K26 -> 1.2616193 | V26: 1 | W26: 1 | X26: 1 | Y26: =$T26*$V26 -> 44156676 | Z26: =$T26*$W26 -> 44156676 | AA26: =$T26*$X26 -> 44156676 | AC26: =IF($E26="Padang",INDEX('Pita Gaji'!$F$6:$F$28,MATCH($G26,'Pita Gaji'!$A$6:$A$28,0)),INDEX('Pita Gaji'!$C$6:$C$28,MATCH($G26,'Pita Gaji'!$A$6:$A$28,0))) -> 35000000 | AD26: =IF($E26="Padang",INDEX('Pita Gaji'!$G$6:$G$28,MATCH($G26,'Pita Gaji'!$A$6:$A$28,0)),INDEX('Pita Gaji'!$D$6:$D$28,MATCH($G26,'Pita Gaji'!$A$6:$A$28,0))) -> 47500000 | AE26: =IF($E26="Padang",INDEX('Pita Gaji'!$H$6:$H$28,MATCH($G26,'Pita Gaji'!$A$6:$A$28,0)),INDEX('Pita Gaji'!$E$6:$E$28,MATCH($G26,'Pita Gaji'!$A$6:$A$28,0))) -> 60000000 | AF26: =IF(Pita_CLevel="P25",$AC26,IF(Pita_CLevel="P50",$AD26,$AE26)) -> 35000000 | AG26: =(IF($F26="C-Level",$AF26,$AC26)*(1+Tunjangan_Pct))*(1+IF($H26="Lapangan",Tarif_JKK_Lapangan,Tarif_JKK_Kantor)+Tarif_JKM+Tarif_JHT+Tarif_THR)+MIN((IF($F26="C-Level",$AF26,$AC26)*(1+Tunjangan_Pct)),Plafon_JP)*Tarif_JP+MIN(MAX((IF($F26="C-Level",$AF26,$AC26)*(1+Tunjangan_Pct)),IF($E26="Padang",UMP_Padang,UMK_Pekanbaru)),Plafon_JKN)*Tarif_JKN -> 44156676 | AH26: =(IF($F26="C-Level",$AF26,$AD26)*(1+Tunjangan_Pct))*(1+IF($H26="Lapangan",Tarif_JKK_Lapangan,Tarif_JKK_Kantor)+Tarif_JKM+Tarif_JHT+Tarif_THR)+MIN((IF($F26="C-Level",$AF26,$AD26)*(1+Tunjangan_Pct)),Plafon_JP)*Tarif_JP+MIN(MAX((IF($F26="C-Level",$AF26,$AD26)*(1+Tunjangan_Pct)),IF($E26="Padang",UMP_Padang,UMK_Pekanbaru)),Plafon_JKN)*Tarif_JKN -> 44156676 | AI26: =(IF($F26="C-Level",$AF26,$AE26)*(1+Tunjangan_Pct))*(1+IF($H26="Lapangan",Tarif_JKK_Lapangan,Tarif_JKK_Kantor)+Tarif_JKM+Tarif_JHT+Tarif_THR)+MIN((IF($F26="C-Level",$AF26,$AE26)*(1+Tunjangan_Pct)),Plafon_JP)*Tarif_JP+MIN(MAX((IF($F26="C-Level",$AF26,$AE26)*(1+Tunjangan_Pct)),IF($E26="Padang",UMP_Padang,UMK_Pekanbaru)),Plafon_JKN)*Tarif_JKN -> 44156676 | AJ26: =$V26*MAX(0,MIN(3,4-$I26))+$W26*MAX(0,MIN(9,13-MAX($I26,4))) -> 12 | AK26: =$AJ26+$X26*MAX(0,MIN(12,25-MAX($I26,13))) -> 24 | AL26: =IF($M26>=IF($E26="Padang",UMP_Padang,UMK_Pekanbaru),"OK","DI BAWAH UMK") -> OK
A27: 2 | B27: Direksi & Tata Kelola | C27: HR & GA Generalist | D27: Pekanbaru | E27: Pekanbaru | F27: Staf Senior | G27: HR generalist | H27: Kantor | I27: 3 | J27: =IF($F27="C-Level",Pita_CLevel,Pita_Aktif) -> P50 | K27: =IF($J27="P25",$AC27,IF($J27="P50",$AD27,$AE27)) -> 8500000 | L27: =$K27*Tunjangan_Pct -> 850000 | M27: =$K27+$L27 -> 9350000 | N27: =$M27*IF($H27="Lapangan",Tarif_JKK_Lapangan,Tarif_JKK_Kantor) -> 50490 | O27: =$M27*Tarif_JKM -> 28050 | P27: =$M27*Tarif_JHT -> 345950 | Q27: =MIN($M27,Plafon_JP)*Tarif_JP -> 187000 | R27: =MIN(MAX($M27,IF($E27="Padang",UMP_Padang,UMK_Pekanbaru)),Plafon_JKN)*Tarif_JKN -> 374000 | S27: =$M27*Tarif_THR -> 778855 | T27: =SUM($M27:$S27) -> 11114345 | U27: =$T27/$K27 -> 1.30757 | V27: 1 | W27: 1 | X27: 1 | Y27: =$T27*$V27 -> 11114345 | Z27: =$T27*$W27 -> 11114345 | AA27: =$T27*$X27 -> 11114345 | AC27: =IF($E27="Padang",INDEX('Pita Gaji'!$F$6:$F$28,MATCH($G27,'Pita Gaji'!$A$6:$A$28,0)),INDEX('Pita Gaji'!$C$6:$C$28,MATCH($G27,'Pita Gaji'!$A$6:$A$28,0))) -> 6000000 | AD27: =IF($E27="Padang",INDEX('Pita Gaji'!$G$6:$G$28,MATCH($G27,'Pita Gaji'!$A$6:$A$28,0)),INDEX('Pita Gaji'!$D$6:$D$28,MATCH($G27,'Pita Gaji'!$A$6:$A$28,0))) -> 8500000 | AE27: =IF($E27="Padang",INDEX('Pita Gaji'!$H$6:$H$28,MATCH($G27,'Pita Gaji'!$A$6:$A$28,0)),INDEX('Pita Gaji'!$E$6:$E$28,MATCH($G27,'Pita Gaji'!$A$6:$A$28,0))) -> 11000000 | AF27: =IF(Pita_CLevel="P25",$AC27,IF(Pita_CLevel="P50",$AD27,$AE27)) -> 6000000 | AG27: =(IF($F27="C-Level",$AF27,$AC27)*(1+Tunjangan_Pct))*(1+IF($H27="Lapangan",Tarif_JKK_Lapangan,Tarif_JKK_Kantor)+Tarif_JKM+Tarif_JHT+Tarif_THR)+MIN((IF($F27="C-Level",$AF27,$AC27)*(1+Tunjangan_Pct)),Plafon_JP)*Tarif_JP+MIN(MAX((IF($F27="C-Level",$AF27,$AC27)*(1+Tunjangan_Pct)),IF($E27="Padang",UMP_Padang,UMK_Pekanbaru)),Plafon_JKN)*Tarif_JKN -> 7845420 | AH27: =(IF($F27="C-Level",$AF27,$AD27)*(1+Tunjangan_Pct))*(1+IF($H27="Lapangan",Tarif_JKK_Lapangan,Tarif_JKK_Kantor)+Tarif_JKM+Tarif_JHT+Tarif_THR)+MIN((IF($F27="C-Level",$AF27,$AD27)*(1+Tunjangan_Pct)),Plafon_JP)*Tarif_JP+MIN(MAX((IF($F27="C-Level",$AF27,$AD27)*(1+Tunjangan_Pct)),IF($E27="Padang",UMP_Padang,UMK_Pekanbaru)),Plafon_JKN)*Tarif_JKN -> 11114345 | AI27: =(IF($F27="C-Level",$AF27,$AE27)*(1+Tunjangan_Pct))*(1+IF($H27="Lapangan",Tarif_JKK_Lapangan,Tarif_JKK_Kantor)+Tarif_JKM+Tarif_JHT+Tarif_THR)+MIN((IF($F27="C-Level",$AF27,$AE27)*(1+Tunjangan_Pct)),Plafon_JP)*Tarif_JP+MIN(MAX((IF($F27="C-Level",$AF27,$AE27)*(1+Tunjangan_Pct)),IF($E27="Padang",UMP_Padang,UMK_Pekanbaru)),Plafon_JKN)*Tarif_JKN -> 14358996 | AJ27: =$V27*MAX(0,MIN(3,4-$I27))+$W27*MAX(0,MIN(9,13-MAX($I27,4))) -> 10 | AK27: =$AJ27+$X27*MAX(0,MIN(12,25-MAX($I27,13))) -> 22 | AL27: =IF($M27>=IF($E27="Padang",UMP_Padang,UMK_Pekanbaru),"OK","DI BAWAH UMK") -> OK
A28: 3 | B28: Teknologi | C28: Direktur Teknologi (CTO) | D28: Pekanbaru | E28: Pekanbaru | F28: C-Level | G28: CTO | H28: Kantor | I28: 1 | J28: =IF($F28="C-Level",Pita_CLevel,Pita_Aktif) -> P25 | K28: =IF($J28="P25",$AC28,IF($J28="P50",$AD28,$AE28)) -> 30000000 | L28: =$K28*Tunjangan_Pct -> 3000000 | M28: =$K28+$L28 -> 33000000 | N28: =$M28*IF($H28="Lapangan",Tarif_JKK_Lapangan,Tarif_JKK_Kantor) -> 178200 | O28: =$M28*Tarif_JKM -> 99000 | P28: =$M28*Tarif_JHT -> 1221000 | Q28: =MIN($M28,Plafon_JP)*Tarif_JP -> 221726 | R28: =MIN(MAX($M28,IF($E28="Padang",UMP_Padang,UMK_Pekanbaru)),Plafon_JKN)*Tarif_JKN -> 480000 | S28: =$M28*Tarif_THR -> 2748900 | T28: =SUM($M28:$S28) -> 37948826 | U28: =$T28/$K28 -> 1.2649609 | V28: 1 | W28: 1 | X28: 1 | Y28: =$T28*$V28 -> 37948826 | Z28: =$T28*$W28 -> 37948826 | AA28: =$T28*$X28 -> 37948826 | AC28: =IF($E28="Padang",INDEX('Pita Gaji'!$F$6:$F$28,MATCH($G28,'Pita Gaji'!$A$6:$A$28,0)),INDEX('Pita Gaji'!$C$6:$C$28,MATCH($G28,'Pita Gaji'!$A$6:$A$28,0))) -> 30000000 | AD28: =IF($E28="Padang",INDEX('Pita Gaji'!$G$6:$G$28,MATCH($G28,'Pita Gaji'!$A$6:$A$28,0)),INDEX('Pita Gaji'!$D$6:$D$28,MATCH($G28,'Pita Gaji'!$A$6:$A$28,0))) -> 42500000 | AE28: =IF($E28="Padang",INDEX('Pita Gaji'!$H$6:$H$28,MATCH($G28,'Pita Gaji'!$A$6:$A$28,0)),INDEX('Pita Gaji'!$E$6:$E$28,MATCH($G28,'Pita Gaji'!$A$6:$A$28,0))) -> 55000000 | AF28: =IF(Pita_CLevel="P25",$AC28,IF(Pita_CLevel="P50",$AD28,$AE28)) -> 30000000 | AG28: =(IF($F28="C-Level",$AF28,$AC28)*(1+Tunjangan_Pct))*(1+IF($H28="Lapangan",Tarif_JKK_Lapangan,Tarif_JKK_Kantor)+Tarif_JKM+Tarif_JHT+Tarif_THR)+MIN((IF($F28="C-Level",$AF28,$AC28)*(1+Tunjangan_Pct)),Plafon_JP)*Tarif_JP+MIN(MAX((IF($F28="C-Level",$AF28,$AC28)*(1+Tunjangan_Pct)),IF($E28="Padang",UMP_Padang,UMK_Pekanbaru)),Plafon_JKN)*Tarif_JKN -> 37948826 | AH28: =(IF($F28="C-Level",$AF28,$AD28)*(1+Tunjangan_Pct))*(1+IF($H28="Lapangan",Tarif_JKK_Lapangan,Tarif_JKK_Kantor)+Tarif_JKM+Tarif_JHT+Tarif_THR)+MIN((IF($F28="C-Level",$AF28,$AD28)*(1+Tunjangan_Pct)),Plafon_JP)*Tarif_JP+MIN(MAX((IF($F28="C-Level",$AF28,$AD28)*(1+Tunjangan_Pct)),IF($E28="Padang",UMP_Padang,UMK_Pekanbaru)),Plafon_JKN)*Tarif_JKN -> 37948826 | AI28: =(IF($F28="C-Level",$AF28,$AE28)*(1+Tunjangan_Pct))*(1+IF($H28="Lapangan",Tarif_JKK_Lapangan,Tarif_JKK_Kantor)+Tarif_JKM+Tarif_JHT+Tarif_THR)+MIN((IF($F28="C-Level",$AF28,$AE28)*(1+Tunjangan_Pct)),Plafon_JP)*Tarif_JP+MIN(MAX((IF($F28="C-Level",$AF28,$AE28)*(1+Tunjangan_Pct)),IF($E28="Padang",UMP_Padang,UMK_Pekanbaru)),Plafon_JKN)*Tarif_JKN -> 37948826 | AJ28: =$V28*MAX(0,MIN(3,4-$I28))+$W28*MAX(0,MIN(9,13-MAX($I28,4))) -> 12 | AK28: =$AJ28+$X28*MAX(0,MIN(12,25-MAX($I28,13))) -> 24 | AL28: =IF($M28>=IF($E28="Padang",UMP_Padang,UMK_Pekanbaru),"OK","DI BAWAH UMK") -> OK
A29: 4 | B29: Teknologi | C29: Engineering Manager | D29: Remote | E29: Pekanbaru | F29: Manajer | G29: Engineering Manager | H29: Kantor | I29: 4 | J29: =IF($F29="C-Level",Pita_CLevel,Pita_Aktif) -> P50 | K29: =IF($J29="P25",$AC29,IF($J29="P50",$AD29,$AE29)) -> 27500000 | L29: =$K29*Tunjangan_Pct -> 2750000 | M29: =$K29+$L29 -> 30250000 | N29: =$M29*IF($H29="Lapangan",Tarif_JKK_Lapangan,Tarif_JKK_Kantor) -> 163350 | O29: =$M29*Tarif_JKM -> 90750 | P29: =$M29*Tarif_JHT -> 1119250 | Q29: =MIN($M29,Plafon_JP)*Tarif_JP -> 221726 | R29: =MIN(MAX($M29,IF($E29="Padang",UMP_Padang,UMK_Pekanbaru)),Plafon_JKN)*Tarif_JKN -> 480000 | S29: =$M29*Tarif_THR -> 2519825 | T29: =SUM($M29:$S29) -> 34844901 | U29: =$T29/$K29 -> 1.2670873 | V29: 0 | W29: 1 | X29: 1 | Y29: =$T29*$V29 -> 0 | Z29: =$T29*$W29 -> 34844901 | AA29: =$T29*$X29 -> 34844901 | AC29: =IF($E29="Padang",INDEX('Pita Gaji'!$F$6:$F$28,MATCH($G29,'Pita Gaji'!$A$6:$A$28,0)),INDEX('Pita Gaji'!$C$6:$C$28,MATCH($G29,'Pita Gaji'!$A$6:$A$28,0))) -> 20000000 | AD29: =IF($E29="Padang",INDEX('Pita Gaji'!$G$6:$G$28,MATCH($G29,'Pita Gaji'!$A$6:$A$28,0)),INDEX('Pita Gaji'!$D$6:$D$28,MATCH($G29,'Pita Gaji'!$A$6:$A$28,0))) -> 27500000 | AE29: =IF($E29="Padang",INDEX('Pita Gaji'!$H$6:$H$28,MATCH($G29,'Pita Gaji'!$A$6:$A$28,0)),INDEX('Pita Gaji'!$E$6:$E$28,MATCH($G29,'Pita Gaji'!$A$6:$A$28,0))) -> 35000000 | AF29: =IF(Pita_CLevel="P25",$AC29,IF(Pita_CLevel="P50",$AD29,$AE29)) -> 20000000 | AG29: =(IF($F29="C-Level",$AF29,$AC29)*(1+Tunjangan_Pct))*(1+IF($H29="Lapangan",Tarif_JKK_Lapangan,Tarif_JKK_Kantor)+Tarif_JKM+Tarif_JHT+Tarif_THR)+MIN((IF($F29="C-Level",$AF29,$AC29)*(1+Tunjangan_Pct)),Plafon_JP)*Tarif_JP+MIN(MAX((IF($F29="C-Level",$AF29,$AC29)*(1+Tunjangan_Pct)),IF($E29="Padang",UMP_Padang,UMK_Pekanbaru)),Plafon_JKN)*Tarif_JKN -> 25533126 | AH29: =(IF($F29="C-Level",$AF29,$AD29)*(1+Tunjangan_Pct))*(1+IF($H29="Lapangan",Tarif_JKK_Lapangan,Tarif_JKK_Kantor)+Tarif_JKM+Tarif_JHT+Tarif_THR)+MIN((IF($F29="C-Level",$AF29,$AD29)*(1+Tunjangan_Pct)),Plafon_JP)*Tarif_JP+MIN(MAX((IF($F29="C-Level",$AF29,$AD29)*(1+Tunjangan_Pct)),IF($E29="Padang",UMP_Padang,UMK_Pekanbaru)),Plafon_JKN)*Tarif_JKN -> 34844901 | AI29: =(IF($F29="C-Level",$AF29,$AE29)*(1+Tunjangan_Pct))*(1+IF($H29="Lapangan",Tarif_JKK_Lapangan,Tarif_JKK_Kantor)+Tarif_JKM+Tarif_JHT+Tarif_THR)+MIN((IF($F29="C-Level",$AF29,$AE29)*(1+Tunjangan_Pct)),Plafon_JP)*Tarif_JP+MIN(MAX((IF($F29="C-Level",$AF29,$AE29)*(1+Tunjangan_Pct)),IF($E29="Padang",UMP_Padang,UMK_Pekanbaru)),Plafon_JKN)*Tarif_JKN -> 44156676 | AJ29: =$V29*MAX(0,MIN(3,4-$I29))+$W29*MAX(0,MIN(9,13-MAX($I29,4))) -> 9 | AK29: =$AJ29+$X29*MAX(0,MIN(12,25-MAX($I29,13))) -> 21 | AL29: =IF($M29>=IF($E29="Padang",UMP_Padang,UMK_Pekanbaru),"OK","DI BAWAH UMK") -> OK
A30: 5 | B30: Teknologi | C30: Mobile Engineer (Senior) | D30: Pekanbaru | E30: Pekanbaru | F30: Senior | G30: Senior Software Engineer | H30: Kantor | I30: 1 | J30: =IF($F30="C-Level",Pita_CLevel,Pita_Aktif) -> P50 | K30: =IF($J30="P25",$AC30,IF($J30="P50",$AD30,$AE30)) -> 20000000 | L30: =$K30*Tunjangan_Pct -> 2000000 | M30: =$K30+$L30 -> 22000000 | N30: =$M30*IF($H30="Lapangan",Tarif_JKK_Lapangan,Tarif_JKK_Kantor) -> 118800 | O30: =$M30*Tarif_JKM -> 66000 | P30: =$M30*Tarif_JHT -> 814000 | Q30: =MIN($M30,Plafon_JP)*Tarif_JP -> 221726 | R30: =MIN(MAX($M30,IF($E30="Padang",UMP_Padang,UMK_Pekanbaru)),Plafon_JKN)*Tarif_JKN -> 480000 | S30: =$M30*Tarif_THR -> 1832600 | T30: =SUM($M30:$S30) -> 25533126 | U30: =$T30/$K30 -> 1.2766563 | V30: 1 | W30: 1 | X30: 1 | Y30: =$T30*$V30 -> 25533126 | Z30: =$T30*$W30 -> 25533126 | AA30: =$T30*$X30 -> 25533126 | AC30: =IF($E30="Padang",INDEX('Pita Gaji'!$F$6:$F$28,MATCH($G30,'Pita Gaji'!$A$6:$A$28,0)),INDEX('Pita Gaji'!$C$6:$C$28,MATCH($G30,'Pita Gaji'!$A$6:$A$28,0))) -> 15000000 | AD30: =IF($E30="Padang",INDEX('Pita Gaji'!$G$6:$G$28,MATCH($G30,'Pita Gaji'!$A$6:$A$28,0)),INDEX('Pita Gaji'!$D$6:$D$28,MATCH($G30,'Pita Gaji'!$A$6:$A$28,0))) -> 20000000 | AE30: =IF($E30="Padang",INDEX('Pita Gaji'!$H$6:$H$28,MATCH($G30,'Pita Gaji'!$A$6:$A$28,0)),INDEX('Pita Gaji'!$E$6:$E$28,MATCH($G30,'Pita Gaji'!$A$6:$A$28,0))) -> 25000000 | AF30: =IF(Pita_CLevel="P25",$AC30,IF(Pita_CLevel="P50",$AD30,$AE30)) -> 15000000 | AG30: =(IF($F30="C-Level",$AF30,$AC30)*(1+Tunjangan_Pct))*(1+IF($H30="Lapangan",Tarif_JKK_Lapangan,Tarif_JKK_Kantor)+Tarif_JKM+Tarif_JHT+Tarif_THR)+MIN((IF($F30="C-Level",$AF30,$AC30)*(1+Tunjangan_Pct)),Plafon_JP)*Tarif_JP+MIN(MAX((IF($F30="C-Level",$AF30,$AC30)*(1+Tunjangan_Pct)),IF($E30="Padang",UMP_Padang,UMK_Pekanbaru)),Plafon_JKN)*Tarif_JKN -> 19325276 | AH30: =(IF($F30="C-Level",$AF30,$AD30)*(1+Tunjangan_Pct))*(1+IF($H30="Lapangan",Tarif_JKK_Lapangan,Tarif_JKK_Kantor)+Tarif_JKM+Tarif_JHT+Tarif_THR)+MIN((IF($F30="C-Level",$AF30,$AD30)*(1+Tunjangan_Pct)),Plafon_JP)*Tarif_JP+MIN(MAX((IF($F30="C-Level",$AF30,$AD30)*(1+Tunjangan_Pct)),IF($E30="Padang",UMP_Padang,UMK_Pekanbaru)),Plafon_JKN)*Tarif_JKN -> 25533126 | AI30: =(IF($F30="C-Level",$AF30,$AE30)*(1+Tunjangan_Pct))*(1+IF($H30="Lapangan",Tarif_JKK_Lapangan,Tarif_JKK_Kantor)+Tarif_JKM+Tarif_JHT+Tarif_THR)+MIN((IF($F30="C-Level",$AF30,$AE30)*(1+Tunjangan_Pct)),Plafon_JP)*Tarif_JP+MIN(MAX((IF($F30="C-Level",$AF30,$AE30)*(1+Tunjangan_Pct)),IF($E30="Padang",UMP_Padang,UMK_Pekanbaru)),Plafon_JKN)*Tarif_JKN -> 31740976 | AJ30: =$V30*MAX(0,MIN(3,4-$I30))+$W30*MAX(0,MIN(9,13-MAX($I30,4))) -> 12 | AK30: =$AJ30+$X30*MAX(0,MIN(12,25-MAX($I30,13))) -> 24 | AL30: =IF($M30>=IF($E30="Padang",UMP_Padang,UMK_Pekanbaru),"OK","DI BAWAH UMK") -> OK
A31: 6 | B31: Teknologi | C31: Mobile Engineer (Mid) | D31: Remote | E31: Pekanbaru | F31: Mid | G31: Mid Software Engineer | H31: Kantor | I31: 5 | J31: =IF($F31="C-Level",Pita_CLevel,Pita_Aktif) -> P50 | K31: =IF($J31="P25",$AC31,IF($J31="P50",$AD31,$AE31)) -> 12000000 | L31: =$K31*Tunjangan_Pct -> 1200000 | M31: =$K31+$L31 -> 13200000 | N31: =$M31*IF($H31="Lapangan",Tarif_JKK_Lapangan,Tarif_JKK_Kantor) -> 71280 | O31: =$M31*Tarif_JKM -> 39600 | P31: =$M31*Tarif_JHT -> 488400 | Q31: =MIN($M31,Plafon_JP)*Tarif_JP -> 221726 | R31: =MIN(MAX($M31,IF($E31="Padang",UMP_Padang,UMK_Pekanbaru)),Plafon_JKN)*Tarif_JKN -> 480000 | S31: =$M31*Tarif_THR -> 1099560 | T31: =SUM($M31:$S31) -> 15600566 | U31: =$T31/$K31 -> 1.3000472 | V31: 0 | W31: 1 | X31: 1 | Y31: =$T31*$V31 -> 0 | Z31: =$T31*$W31 -> 15600566 | AA31: =$T31*$X31 -> 15600566 | AC31: =IF($E31="Padang",INDEX('Pita Gaji'!$F$6:$F$28,MATCH($G31,'Pita Gaji'!$A$6:$A$28,0)),INDEX('Pita Gaji'!$C$6:$C$28,MATCH($G31,'Pita Gaji'!$A$6:$A$28,0))) -> 9000000 | AD31: =IF($E31="Padang",INDEX('Pita Gaji'!$G$6:$G$28,MATCH($G31,'Pita Gaji'!$A$6:$A$28,0)),INDEX('Pita Gaji'!$D$6:$D$28,MATCH($G31,'Pita Gaji'!$A$6:$A$28,0))) -> 12000000 | AE31: =IF($E31="Padang",INDEX('Pita Gaji'!$H$6:$H$28,MATCH($G31,'Pita Gaji'!$A$6:$A$28,0)),INDEX('Pita Gaji'!$E$6:$E$28,MATCH($G31,'Pita Gaji'!$A$6:$A$28,0))) -> 15000000 | AF31: =IF(Pita_CLevel="P25",$AC31,IF(Pita_CLevel="P50",$AD31,$AE31)) -> 9000000 | AG31: =(IF($F31="C-Level",$AF31,$AC31)*(1+Tunjangan_Pct))*(1+IF($H31="Lapangan",Tarif_JKK_Lapangan,Tarif_JKK_Kantor)+Tarif_JKM+Tarif_JHT+Tarif_THR)+MIN((IF($F31="C-Level",$AF31,$AC31)*(1+Tunjangan_Pct)),Plafon_JP)*Tarif_JP+MIN(MAX((IF($F31="C-Level",$AF31,$AC31)*(1+Tunjangan_Pct)),IF($E31="Padang",UMP_Padang,UMK_Pekanbaru)),Plafon_JKN)*Tarif_JKN -> 11768130 | AH31: =(IF($F31="C-Level",$AF31,$AD31)*(1+Tunjangan_Pct))*(1+IF($H31="Lapangan",Tarif_JKK_Lapangan,Tarif_JKK_Kantor)+Tarif_JKM+Tarif_JHT+Tarif_THR)+MIN((IF($F31="C-Level",$AF31,$AD31)*(1+Tunjangan_Pct)),Plafon_JP)*Tarif_JP+MIN(MAX((IF($F31="C-Level",$AF31,$AD31)*(1+Tunjangan_Pct)),IF($E31="Padang",UMP_Padang,UMK_Pekanbaru)),Plafon_JKN)*Tarif_JKN -> 15600566 | AI31: =(IF($F31="C-Level",$AF31,$AE31)*(1+Tunjangan_Pct))*(1+IF($H31="Lapangan",Tarif_JKK_Lapangan,Tarif_JKK_Kantor)+Tarif_JKM+Tarif_JHT+Tarif_THR)+MIN((IF($F31="C-Level",$AF31,$AE31)*(1+Tunjangan_Pct)),Plafon_JP)*Tarif_JP+MIN(MAX((IF($F31="C-Level",$AF31,$AE31)*(1+Tunjangan_Pct)),IF($E31="Padang",UMP_Padang,UMK_Pekanbaru)),Plafon_JKN)*Tarif_JKN -> 19325276 | AJ31: =$V31*MAX(0,MIN(3,4-$I31))+$W31*MAX(0,MIN(9,13-MAX($I31,4))) -> 8 | AK31: =$AJ31+$X31*MAX(0,MIN(12,25-MAX($I31,13))) -> 20 | AL31: =IF($M31>=IF($E31="Padang",UMP_Padang,UMK_Pekanbaru),"OK","DI BAWAH UMK") -> OK
A32: 7 | B32: Teknologi | C32: Mobile Engineer (Mid) - gelombang 2 | D32: Remote | E32: Pekanbaru | F32: Mid | G32: Mid Software Engineer | H32: Kantor | I32: 14 | J32: =IF($F32="C-Level",Pita_CLevel,Pita_Aktif) -> P50 | K32: =IF($J32="P25",$AC32,IF($J32="P50",$AD32,$AE32)) -> 12000000 | L32: =$K32*Tunjangan_Pct -> 1200000 | M32: =$K32+$L32 -> 13200000 | N32: =$M32*IF($H32="Lapangan",Tarif_JKK_Lapangan,Tarif_JKK_Kantor) -> 71280 | O32: =$M32*Tarif_JKM -> 39600 | P32: =$M32*Tarif_JHT -> 488400 | Q32: =MIN($M32,Plafon_JP)*Tarif_JP -> 221726 | R32: =MIN(MAX($M32,IF($E32="Padang",UMP_Padang,UMK_Pekanbaru)),Plafon_JKN)*Tarif_JKN -> 480000 | S32: =$M32*Tarif_THR -> 1099560 | T32: =SUM($M32:$S32) -> 15600566 | U32: =$T32/$K32 -> 1.3000472 | V32: 0 | W32: 0 | X32: 1 | Y32: =$T32*$V32 -> 0 | Z32: =$T32*$W32 -> 0 | AA32: =$T32*$X32 -> 15600566 | AC32: =IF($E32="Padang",INDEX('Pita Gaji'!$F$6:$F$28,MATCH($G32,'Pita Gaji'!$A$6:$A$28,0)),INDEX('Pita Gaji'!$C$6:$C$28,MATCH($G32,'Pita Gaji'!$A$6:$A$28,0))) -> 9000000 | AD32: =IF($E32="Padang",INDEX('Pita Gaji'!$G$6:$G$28,MATCH($G32,'Pita Gaji'!$A$6:$A$28,0)),INDEX('Pita Gaji'!$D$6:$D$28,MATCH($G32,'Pita Gaji'!$A$6:$A$28,0))) -> 12000000 | AE32: =IF($E32="Padang",INDEX('Pita Gaji'!$H$6:$H$28,MATCH($G32,'Pita Gaji'!$A$6:$A$28,0)),INDEX('Pita Gaji'!$E$6:$E$28,MATCH($G32,'Pita Gaji'!$A$6:$A$28,0))) -> 15000000 | AF32: =IF(Pita_CLevel="P25",$AC32,IF(Pita_CLevel="P50",$AD32,$AE32)) -> 9000000 | AG32: =(IF($F32="C-Level",$AF32,$AC32)*(1+Tunjangan_Pct))*(1+IF($H32="Lapangan",Tarif_JKK_Lapangan,Tarif_JKK_Kantor)+Tarif_JKM+Tarif_JHT+Tarif_THR)+MIN((IF($F32="C-Level",$AF32,$AC32)*(1+Tunjangan_Pct)),Plafon_JP)*Tarif_JP+MIN(MAX((IF($F32="C-Level",$AF32,$AC32)*(1+Tunjangan_Pct)),IF($E32="Padang",UMP_Padang,UMK_Pekanbaru)),Plafon_JKN)*Tarif_JKN -> 11768130 | AH32: =(IF($F32="C-Level",$AF32,$AD32)*(1+Tunjangan_Pct))*(1+IF($H32="Lapangan",Tarif_JKK_Lapangan,Tarif_JKK_Kantor)+Tarif_JKM+Tarif_JHT+Tarif_THR)+MIN((IF($F32="C-Level",$AF32,$AD32)*(1+Tunjangan_Pct)),Plafon_JP)*Tarif_JP+MIN(MAX((IF($F32="C-Level",$AF32,$AD32)*(1+Tunjangan_Pct)),IF($E32="Padang",UMP_Padang,UMK_Pekanbaru)),Plafon_JKN)*Tarif_JKN -> 15600566 | AI32: =(IF($F32="C-Level",$AF32,$AE32)*(1+Tunjangan_Pct))*(1+IF($H32="Lapangan",Tarif_JKK_Lapangan,Tarif_JKK_Kantor)+Tarif_JKM+Tarif_JHT+Tarif_THR)+MIN((IF($F32="C-Level",$AF32,$AE32)*(1+Tunjangan_Pct)),Plafon_JP)*Tarif_JP+MIN(MAX((IF($F32="C-Level",$AF32,$AE32)*(1+Tunjangan_Pct)),IF($E32="Padang",UMP_Padang,UMK_Pekanbaru)),Plafon_JKN)*Tarif_JKN -> 19325276 | AJ32: =$V32*MAX(0,MIN(3,4-$I32))+$W32*MAX(0,MIN(9,13-MAX($I32,4))) -> 0 | AK32: =$AJ32+$X32*MAX(0,MIN(12,25-MAX($I32,13))) -> 11 | AL32: =IF($M32>=IF($E32="Padang",UMP_Padang,UMK_Pekanbaru),"OK","DI BAWAH UMK") -> OK
A33: 8 | B33: Teknologi | C33: Backend Engineer (Senior) | D33: Pekanbaru | E33: Pekanbaru | F33: Senior | G33: Senior Software Engineer | H33: Kantor | I33: 1 | J33: =IF($F33="C-Level",Pita_CLevel,Pita_Aktif) -> P50 | K33: =IF($J33="P25",$AC33,IF($J33="P50",$AD33,$AE33)) -> 20000000 | L33: =$K33*Tunjangan_Pct -> 2000000 | M33: =$K33+$L33 -> 22000000 | N33: =$M33*IF($H33="Lapangan",Tarif_JKK_Lapangan,Tarif_JKK_Kantor) -> 118800 | O33: =$M33*Tarif_JKM -> 66000 | P33: =$M33*Tarif_JHT -> 814000 | Q33: =MIN($M33,Plafon_JP)*Tarif_JP -> 221726 | R33: =MIN(MAX($M33,IF($E33="Padang",UMP_Padang,UMK_Pekanbaru)),Plafon_JKN)*Tarif_JKN -> 480000 | S33: =$M33*Tarif_THR -> 1832600 | T33: =SUM($M33:$S33) -> 25533126 | U33: =$T33/$K33 -> 1.2766563 | V33: 1 | W33: 1 | X33: 1 | Y33: =$T33*$V33 -> 25533126 | Z33: =$T33*$W33 -> 25533126 | AA33: =$T33*$X33 -> 25533126 | AC33: =IF($E33="Padang",INDEX('Pita Gaji'!$F$6:$F$28,MATCH($G33,'Pita Gaji'!$A$6:$A$28,0)),INDEX('Pita Gaji'!$C$6:$C$28,MATCH($G33,'Pita Gaji'!$A$6:$A$28,0))) -> 15000000 | AD33: =IF($E33="Padang",INDEX('Pita Gaji'!$G$6:$G$28,MATCH($G33,'Pita Gaji'!$A$6:$A$28,0)),INDEX('Pita Gaji'!$D$6:$D$28,MATCH($G33,'Pita Gaji'!$A$6:$A$28,0))) -> 20000000 | AE33: =IF($E33="Padang",INDEX('Pita Gaji'!$H$6:$H$28,MATCH($G33,'Pita Gaji'!$A$6:$A$28,0)),INDEX('Pita Gaji'!$E$6:$E$28,MATCH($G33,'Pita Gaji'!$A$6:$A$28,0))) -> 25000000 | AF33: =IF(Pita_CLevel="P25",$AC33,IF(Pita_CLevel="P50",$AD33,$AE33)) -> 15000000 | AG33: =(IF($F33="C-Level",$AF33,$AC33)*(1+Tunjangan_Pct))*(1+IF($H33="Lapangan",Tarif_JKK_Lapangan,Tarif_JKK_Kantor)+Tarif_JKM+Tarif_JHT+Tarif_THR)+MIN((IF($F33="C-Level",$AF33,$AC33)*(1+Tunjangan_Pct)),Plafon_JP)*Tarif_JP+MIN(MAX((IF($F33="C-Level",$AF33,$AC33)*(1+Tunjangan_Pct)),IF($E33="Padang",UMP_Padang,UMK_Pekanbaru)),Plafon_JKN)*Tarif_JKN -> 19325276 | AH33: =(IF($F33="C-Level",$AF33,$AD33)*(1+Tunjangan_Pct))*(1+IF($H33="Lapangan",Tarif_JKK_Lapangan,Tarif_JKK_Kantor)+Tarif_JKM+Tarif_JHT+Tarif_THR)+MIN((IF($F33="C-Level",$AF33,$AD33)*(1+Tunjangan_Pct)),Plafon_JP)*Tarif_JP+MIN(MAX((IF($F33="C-Level",$AF33,$AD33)*(1+Tunjangan_Pct)),IF($E33="Padang",UMP_Padang,UMK_Pekanbaru)),Plafon_JKN)*Tarif_JKN -> 25533126 | AI33: =(IF($F33="C-Level",$AF33,$AE33)*(1+Tunjangan_Pct))*(1+IF($H33="Lapangan",Tarif_JKK_Lapangan,Tarif_JKK_Kantor)+Tarif_JKM+Tarif_JHT+Tarif_THR)+MIN((IF($F33="C-Level",$AF33,$AE33)*(1+Tunjangan_Pct)),Plafon_JP)*Tarif_JP+MIN(MAX((IF($F33="C-Level",$AF33,$AE33)*(1+Tunjangan_Pct)),IF($E33="Padang",UMP_Padang,UMK_Pekanbaru)),Plafon_JKN)*Tarif_JKN -> 31740976 | AJ33: =$V33*MAX(0,MIN(3,4-$I33))+$W33*MAX(0,MIN(9,13-MAX($I33,4))) -> 12 | AK33: =$AJ33+$X33*MAX(0,MIN(12,25-MAX($I33,13))) -> 24 | AL33: =IF($M33>=IF($E33="Padang",UMP_Padang,UMK_Pekanbaru),"OK","DI BAWAH UMK") -> OK
A34: 9 | B34: Teknologi | C34: Backend Engineer (Senior) - gelombang 2 | D34: Remote | E34: Pekanbaru | F34: Senior | G34: Senior Software Engineer | H34: Kantor | I34: 19 | J34: =IF($F34="C-Level",Pita_CLevel,Pita_Aktif) -> P50 | K34: =IF($J34="P25",$AC34,IF($J34="P50",$AD34,$AE34)) -> 20000000 | L34: =$K34*Tunjangan_Pct -> 2000000 | M34: =$K34+$L34 -> 22000000 | N34: =$M34*IF($H34="Lapangan",Tarif_JKK_Lapangan,Tarif_JKK_Kantor) -> 118800 | O34: =$M34*Tarif_JKM -> 66000 | P34: =$M34*Tarif_JHT -> 814000 | Q34: =MIN($M34,Plafon_JP)*Tarif_JP -> 221726 | R34: =MIN(MAX($M34,IF($E34="Padang",UMP_Padang,UMK_Pekanbaru)),Plafon_JKN)*Tarif_JKN -> 480000 | S34: =$M34*Tarif_THR -> 1832600 | T34: =SUM($M34:$S34) -> 25533126 | U34: =$T34/$K34 -> 1.2766563 | V34: 0 | W34: 0 | X34: 1 | Y34: =$T34*$V34 -> 0 | Z34: =$T34*$W34 -> 0 | AA34: =$T34*$X34 -> 25533126 | AC34: =IF($E34="Padang",INDEX('Pita Gaji'!$F$6:$F$28,MATCH($G34,'Pita Gaji'!$A$6:$A$28,0)),INDEX('Pita Gaji'!$C$6:$C$28,MATCH($G34,'Pita Gaji'!$A$6:$A$28,0))) -> 15000000 | AD34: =IF($E34="Padang",INDEX('Pita Gaji'!$G$6:$G$28,MATCH($G34,'Pita Gaji'!$A$6:$A$28,0)),INDEX('Pita Gaji'!$D$6:$D$28,MATCH($G34,'Pita Gaji'!$A$6:$A$28,0))) -> 20000000 | AE34: =IF($E34="Padang",INDEX('Pita Gaji'!$H$6:$H$28,MATCH($G34,'Pita Gaji'!$A$6:$A$28,0)),INDEX('Pita Gaji'!$E$6:$E$28,MATCH($G34,'Pita Gaji'!$A$6:$A$28,0))) -> 25000000 | AF34: =IF(Pita_CLevel="P25",$AC34,IF(Pita_CLevel="P50",$AD34,$AE34)) -> 15000000 | AG34: =(IF($F34="C-Level",$AF34,$AC34)*(1+Tunjangan_Pct))*(1+IF($H34="Lapangan",Tarif_JKK_Lapangan,Tarif_JKK_Kantor)+Tarif_JKM+Tarif_JHT+Tarif_THR)+MIN((IF($F34="C-Level",$AF34,$AC34)*(1+Tunjangan_Pct)),Plafon_JP)*Tarif_JP+MIN(MAX((IF($F34="C-Level",$AF34,$AC34)*(1+Tunjangan_Pct)),IF($E34="Padang",UMP_Padang,UMK_Pekanbaru)),Plafon_JKN)*Tarif_JKN -> 19325276 | AH34: =(IF($F34="C-Level",$AF34,$AD34)*(1+Tunjangan_Pct))*(1+IF($H34="Lapangan",Tarif_JKK_Lapangan,Tarif_JKK_Kantor)+Tarif_JKM+Tarif_JHT+Tarif_THR)+MIN((IF($F34="C-Level",$AF34,$AD34)*(1+Tunjangan_Pct)),Plafon_JP)*Tarif_JP+MIN(MAX((IF($F34="C-Level",$AF34,$AD34)*(1+Tunjangan_Pct)),IF($E34="Padang",UMP_Padang,UMK_Pekanbaru)),Plafon_JKN)*Tarif_JKN -> 25533126 | AI34: =(IF($F34="C-Level",$AF34,$AE34)*(1+Tunjangan_Pct))*(1+IF($H34="Lapangan",Tarif_JKK_Lapangan,Tarif_JKK_Kantor)+Tarif_JKM+Tarif_JHT+Tarif_THR)+MIN((IF($F34="C-Level",$AF34,$AE34)*(1+Tunjangan_Pct)),Plafon_JP)*Tarif_JP+MIN(MAX((IF($F34="C-Level",$AF34,$AE34)*(1+Tunjangan_Pct)),IF($E34="Padang",UMP_Padang,UMK_Pekanbaru)),Plafon_JKN)*Tarif_JKN -> 31740976 | AJ34: =$V34*MAX(0,MIN(3,4-$I34))+$W34*MAX(0,MIN(9,13-MAX($I34,4))) -> 0 | AK34: =$AJ34+$X34*MAX(0,MIN(12,25-MAX($I34,13))) -> 6 | AL34: =IF($M34>=IF($E34="Padang",UMP_Padang,UMK_Pekanbaru),"OK","DI BAWAH UMK") -> OK
A35: 10 | B35: Teknologi | C35: Backend Engineer (Mid) | D35: Remote | E35: Pekanbaru | F35: Mid | G35: Mid Software Engineer | H35: Kantor | I35: 4 | J35: =IF($F35="C-Level",Pita_CLevel,Pita_Aktif) -> P50 | K35: =IF($J35="P25",$AC35,IF($J35="P50",$AD35,$AE35)) -> 12000000 | L35: =$K35*Tunjangan_Pct -> 1200000 | M35: =$K35+$L35 -> 13200000 | N35: =$M35*IF($H35="Lapangan",Tarif_JKK_Lapangan,Tarif_JKK_Kantor) -> 71280 | O35: =$M35*Tarif_JKM -> 39600 | P35: =$M35*Tarif_JHT -> 488400 | Q35: =MIN($M35,Plafon_JP)*Tarif_JP -> 221726 | R35: =MIN(MAX($M35,IF($E35="Padang",UMP_Padang,UMK_Pekanbaru)),Plafon_JKN)*Tarif_JKN -> 480000 | S35: =$M35*Tarif_THR -> 1099560 | T35: =SUM($M35:$S35) -> 15600566 | U35: =$T35/$K35 -> 1.3000472 | V35: 0 | W35: 1 | X35: 1 | Y35: =$T35*$V35 -> 0 | Z35: =$T35*$W35 -> 15600566 | AA35: =$T35*$X35 -> 15600566 | AC35: =IF($E35="Padang",INDEX('Pita Gaji'!$F$6:$F$28,MATCH($G35,'Pita Gaji'!$A$6:$A$28,0)),INDEX('Pita Gaji'!$C$6:$C$28,MATCH($G35,'Pita Gaji'!$A$6:$A$28,0))) -> 9000000 | AD35: =IF($E35="Padang",INDEX('Pita Gaji'!$G$6:$G$28,MATCH($G35,'Pita Gaji'!$A$6:$A$28,0)),INDEX('Pita Gaji'!$D$6:$D$28,MATCH($G35,'Pita Gaji'!$A$6:$A$28,0))) -> 12000000 | AE35: =IF($E35="Padang",INDEX('Pita Gaji'!$H$6:$H$28,MATCH($G35,'Pita Gaji'!$A$6:$A$28,0)),INDEX('Pita Gaji'!$E$6:$E$28,MATCH($G35,'Pita Gaji'!$A$6:$A$28,0))) -> 15000000 | AF35: =IF(Pita_CLevel="P25",$AC35,IF(Pita_CLevel="P50",$AD35,$AE35)) -> 9000000 | AG35: =(IF($F35="C-Level",$AF35,$AC35)*(1+Tunjangan_Pct))*(1+IF($H35="Lapangan",Tarif_JKK_Lapangan,Tarif_JKK_Kantor)+Tarif_JKM+Tarif_JHT+Tarif_THR)+MIN((IF($F35="C-Level",$AF35,$AC35)*(1+Tunjangan_Pct)),Plafon_JP)*Tarif_JP+MIN(MAX((IF($F35="C-Level",$AF35,$AC35)*(1+Tunjangan_Pct)),IF($E35="Padang",UMP_Padang,UMK_Pekanbaru)),Plafon_JKN)*Tarif_JKN -> 11768130 | AH35: =(IF($F35="C-Level",$AF35,$AD35)*(1+Tunjangan_Pct))*(1+IF($H35="Lapangan",Tarif_JKK_Lapangan,Tarif_JKK_Kantor)+Tarif_JKM+Tarif_JHT+Tarif_THR)+MIN((IF($F35="C-Level",$AF35,$AD35)*(1+Tunjangan_Pct)),Plafon_JP)*Tarif_JP+MIN(MAX((IF($F35="C-Level",$AF35,$AD35)*(1+Tunjangan_Pct)),IF($E35="Padang",UMP_Padang,UMK_Pekanbaru)),Plafon_JKN)*Tarif_JKN -> 15600566 | AI35: =(IF($F35="C-Level",$AF35,$AE35)*(1+Tunjangan_Pct))*(1+IF($H35="Lapangan",Tarif_JKK_Lapangan,Tarif_JKK_Kantor)+Tarif_JKM+Tarif_JHT+Tarif_THR)+MIN((IF($F35="C-Level",$AF35,$AE35)*(1+Tunjangan_Pct)),Plafon_JP)*Tarif_JP+MIN(MAX((IF($F35="C-Level",$AF35,$AE35)*(1+Tunjangan_Pct)),IF($E35="Padang",UMP_Padang,UMK_Pekanbaru)),Plafon_JKN)*Tarif_JKN -> 19325276 | AJ35: =$V35*MAX(0,MIN(3,4-$I35))+$W35*MAX(0,MIN(9,13-MAX($I35,4))) -> 9 | AK35: =$AJ35+$X35*MAX(0,MIN(12,25-MAX($I35,13))) -> 21 | AL35: =IF($M35>=IF($E35="Padang",UMP_Padang,UMK_Pekanbaru),"OK","DI BAWAH UMK") -> OK
A36: 11 | B36: Teknologi | C36: Backend Engineer (Mid) - gelombang 2 | D36: Remote | E36: Pekanbaru | F36: Mid | G36: Mid Software Engineer | H36: Kantor | I36: 13 | J36: =IF($F36="C-Level",Pita_CLevel,Pita_Aktif) -> P50 | K36: =IF($J36="P25",$AC36,IF($J36="P50",$AD36,$AE36)) -> 12000000 | L36: =$K36*Tunjangan_Pct -> 1200000 | M36: =$K36+$L36 -> 13200000 | N36: =$M36*IF($H36="Lapangan",Tarif_JKK_Lapangan,Tarif_JKK_Kantor) -> 71280 | O36: =$M36*Tarif_JKM -> 39600 | P36: =$M36*Tarif_JHT -> 488400 | Q36: =MIN($M36,Plafon_JP)*Tarif_JP -> 221726 | R36: =MIN(MAX($M36,IF($E36="Padang",UMP_Padang,UMK_Pekanbaru)),Plafon_JKN)*Tarif_JKN -> 480000 | S36: =$M36*Tarif_THR -> 1099560 | T36: =SUM($M36:$S36) -> 15600566 | U36: =$T36/$K36 -> 1.3000472 | V36: 0 | W36: 0 | X36: 1 | Y36: =$T36*$V36 -> 0 | Z36: =$T36*$W36 -> 0 | AA36: =$T36*$X36 -> 15600566 | AC36: =IF($E36="Padang",INDEX('Pita Gaji'!$F$6:$F$28,MATCH($G36,'Pita Gaji'!$A$6:$A$28,0)),INDEX('Pita Gaji'!$C$6:$C$28,MATCH($G36,'Pita Gaji'!$A$6:$A$28,0))) -> 9000000 | AD36: =IF($E36="Padang",INDEX('Pita Gaji'!$G$6:$G$28,MATCH($G36,'Pita Gaji'!$A$6:$A$28,0)),INDEX('Pita Gaji'!$D$6:$D$28,MATCH($G36,'Pita Gaji'!$A$6:$A$28,0))) -> 12000000 | AE36: =IF($E36="Padang",INDEX('Pita Gaji'!$H$6:$H$28,MATCH($G36,'Pita Gaji'!$A$6:$A$28,0)),INDEX('Pita Gaji'!$E$6:$E$28,MATCH($G36,'Pita Gaji'!$A$6:$A$28,0))) -> 15000000 | AF36: =IF(Pita_CLevel="P25",$AC36,IF(Pita_CLevel="P50",$AD36,$AE36)) -> 9000000 | AG36: =(IF($F36="C-Level",$AF36,$AC36)*(1+Tunjangan_Pct))*(1+IF($H36="Lapangan",Tarif_JKK_Lapangan,Tarif_JKK_Kantor)+Tarif_JKM+Tarif_JHT+Tarif_THR)+MIN((IF($F36="C-Level",$AF36,$AC36)*(1+Tunjangan_Pct)),Plafon_JP)*Tarif_JP+MIN(MAX((IF($F36="C-Level",$AF36,$AC36)*(1+Tunjangan_Pct)),IF($E36="Padang",UMP_Padang,UMK_Pekanbaru)),Plafon_JKN)*Tarif_JKN -> 11768130 | AH36: =(IF($F36="C-Level",$AF36,$AD36)*(1+Tunjangan_Pct))*(1+IF($H36="Lapangan",Tarif_JKK_Lapangan,Tarif_JKK_Kantor)+Tarif_JKM+Tarif_JHT+Tarif_THR)+MIN((IF($F36="C-Level",$AF36,$AD36)*(1+Tunjangan_Pct)),Plafon_JP)*Tarif_JP+MIN(MAX((IF($F36="C-Level",$AF36,$AD36)*(1+Tunjangan_Pct)),IF($E36="Padang",UMP_Padang,UMK_Pekanbaru)),Plafon_JKN)*Tarif_JKN -> 15600566 | AI36: =(IF($F36="C-Level",$AF36,$AE36)*(1+Tunjangan_Pct))*(1+IF($H36="Lapangan",Tarif_JKK_Lapangan,Tarif_JKK_Kantor)+Tarif_JKM+Tarif_JHT+Tarif_THR)+MIN((IF($F36="C-Level",$AF36,$AE36)*(1+Tunjangan_Pct)),Plafon_JP)*Tarif_JP+MIN(MAX((IF($F36="C-Level",$AF36,$AE36)*(1+Tunjangan_Pct)),IF($E36="Padang",UMP_Padang,UMK_Pekanbaru)),Plafon_JKN)*Tarif_JKN -> 19325276 | AJ36: =$V36*MAX(0,MIN(3,4-$I36))+$W36*MAX(0,MIN(9,13-MAX($I36,4))) -> 0 | AK36: =$AJ36+$X36*MAX(0,MIN(12,25-MAX($I36,13))) -> 12 | AL36: =IF($M36>=IF($E36="Padang",UMP_Padang,UMK_Pekanbaru),"OK","DI BAWAH UMK") -> OK
