Workbook
Name Kurs: 'Tumpukan Tool AI'!$D$7
Name PPN_PMSE: 'Tumpukan Tool AI'!$D$8
Name Buffer_Kurs: 'Tumpukan Tool AI'!$D$9
Name GrossUp_PPh26: 'Tumpukan Tool AI'!$D$10
Name Hari_Bulan: 'Tumpukan Tool AI'!$D$11
Name Order_Hari_F0: 'Tumpukan Tool AI'!$D$12
Name Order_Hari_F1: 'Tumpukan Tool AI'!$D$13
Name Order_Hari_F2: 'Tumpukan Tool AI'!$D$14
Name Tiket_Per1000_Th1: 'Tumpukan Tool AI'!$D$15
Name Tiket_Per1000_Th2: 'Tumpukan Tool AI'!$D$16
Name Deflection_CS: 'Tumpukan Tool AI'!$D$17
Name Verif_F0: 'Tumpukan Tool AI'!$D$18
Name Verif_F1: 'Tumpukan Tool AI'!$D$19
Name Verif_F2: 'Tumpukan Tool AI'!$D$20
Name Merchant_F0: 'Tumpukan Tool AI'!$D$21
Name Merchant_F1: 'Tumpukan Tool AI'!$D$22
Name Merchant_F2: 'Tumpukan Tool AI'!$D$23
Name Harga_LLM_In: 'Tumpukan Tool AI'!$D$24
Name Harga_LLM_Out: 'Tumpukan Tool AI'!$D$25
Name Faktor_Token: 'Tumpukan Tool AI'!$D$26
Name Tarif_KYC: 'Tumpukan Tool AI'!$D$27
Name Tarif_WA_Utility: 'Tumpukan Tool AI'!$D$28
Name Porsi_WA: 'Tumpukan Tool AI'!$D$29
Name Faktor_Tool_C: 'Tumpukan Tool AI'!$D$30
Name Faktor_Sembunyi_C: 'Tumpukan Tool AI'!$D$31
Name AI_Satu_Kali: 'Tumpukan Tool AI'!$H$90
Name AI_Var_F0: 'Tumpukan Tool AI'!$H$94
Name AI_Var_F1: 'Tumpukan Tool AI'!$I$94
Name AI_Var_F2: 'Tumpukan Tool AI'!$J$94
Name AI_Tetap_F0: 'Tumpukan Tool AI'!$H$95
Name AI_Tetap_F1: 'Tumpukan Tool AI'!$I$95
Name AI_Tetap_F2: 'Tumpukan Tool AI'!$J$95
Name AI_Sembunyi_F0: 'Tumpukan Tool AI'!$H$96
Name AI_Sembunyi_F1: 'Tumpukan Tool AI'!$I$96
Name AI_Sembunyi_F2: 'Tumpukan Tool AI'!$J$96
Name AI_B_F0: 'Tumpukan Tool AI'!$H$97
Name AI_B_F1: 'Tumpukan Tool AI'!$I$97
Name AI_B_F2: 'Tumpukan Tool AI'!$J$97
Name AI_C_F0: 'Tumpukan Tool AI'!$H$98
Name AI_C_F1: 'Tumpukan Tool AI'!$I$98
Name AI_C_F2: 'Tumpukan Tool AI'!$J$98
Name HC_A_F2: 'Skenario A B C'!$J$44
Name T24_A: 'Perbandingan 24 Bulan'!$D$167
Name T24_B: 'Perbandingan 24 Bulan'!$D$168
Name T24_C: 'Perbandingan 24 Bulan'!$D$169

Sheet Ringkasan Eksekutif
A1: AntarKita - Analisis AI vs SDM: Ringkasan Eksekutif
A2: Disusun 7 September 2026. Turunan dari AntarKita-Model-Biaya-SDM.xlsx v1.0, AntarKita-Manual-Organisasi-dan-SOP.docx, dan DESAIN-ORGANISASI.md.
A3: STATUS: USULAN ANALIS. Tidak satu pun pemangkasan posisi atau pembelian tool pada berkas ini telah diputuskan. Kewenangan ada pada Dewan Komisaris (DESAIN-ORGANISASI 6).
A5: A. REKOMENDASI
A6: 1. Ambil Skenario B (Hibrida): headcount Fase 2 turun dari 42 menjadi 30 orang, dengan tumpukan AI yang dibangun sendiri di atas API LLM, bukan dibeli per-resolusi.
A7: 2. JANGAN mengotomasi pada Fase 0 dan Fase 1. Pada dua fase itu otomasi LEBIH MAHAL daripada manusia karena biaya implementasi terjadi lebih dulu daripada penghematannya. Mulai bangun pada kuartal 2, panen pada kuartal 5.
A8: 3. Penghematan yang jujur adalah sekitar 12-14% biaya terkait SDM, bukan 40-50%. Sebagian besar biaya AntarKita melekat pada peran lapangan, direksi, dan kepatuhan yang TIDAK dapat diotomasi.
A9: 4. Tolak Skenario C. Ia menghapus Treasury/Settlement Officer (melanggar pemisahan tugas DESAIN 6 dan SOP-07) dan menipiskan cakupan shift kanal darurat (SOP-05). Penghematannya nyata, tetapi harganya adalah temuan pada uji tuntas investor.
A11: B. PERBANDINGAN TIGA SKENARIO
A12: Ukuran | B12: Skenario A - Semua manusia | C12: Skenario B - Hibrida (rekomendasi) | D12: Skenario C - AI-maksimal | E12: Sumber angka
A13: Headcount Fase 0 (bulan 1-3) | B13: ='Skenario A B C'!F49 | C13: ='Skenario A B C'!G49 | D13: ='Skenario A B C'!H49 | E13: Lembar 'Skenario A B C'
A14: Headcount Fase 1 (bulan 4-12) | B14: ='Skenario A B C'!I49 | C14: ='Skenario A B C'!J49 | D14: ='Skenario A B C'!K49 | E14: Lembar 'Skenario A B C'
A15: Headcount Fase 2 (bulan 13-24) | B15: ='Skenario A B C'!L49 | C15: ='Skenario A B C'!M49 | D15: ='Skenario A B C'!N49 | E15: Lembar 'Skenario A B C'
A16: Biaya SDM per bulan Fase 2 (Rp) | B16: ='Skenario A B C'!L50 | C16: ='Skenario A B C'!M50 | D16: ='Skenario A B C'!N50 | E16: Model biaya SDM lama (A) & rumus hidup
A17: Biaya non-gaji melekat SDM per bulan Fase 2 (Rp) | B17: ='Skenario A B C'!L51 | C17: ='Skenario A B C'!M51 | D17: ='Skenario A B C'!N51 | E17: Lembar 'Biaya Non-Gaji' model lama
A18: Biaya AI per bulan Fase 2 (Rp) | B18: ='Skenario A B C'!L52 | C18: ='Skenario A B C'!M52 | D18: ='Skenario A B C'!N52 | E18: Lembar 'Tumpukan Tool AI'
A19: TOTAL per bulan Fase 2 (Rp) | B19: ='Skenario A B C'!L53 | C19: ='Skenario A B C'!M53 | D19: ='Skenario A B C'!N53 | E19: Jumlah tiga baris di atas
A20: TOTAL KUMULATIF 24 BULAN (Rp) | B20: =T24_A | C20: =T24_B | D20: =T24_C | E20: Lembar 'Perbandingan 24 Bulan'
A21: Penghematan 24 bulan vs A (Rp) | B21: =0 | C21: =T24_A-T24_B | D21: =T24_A-T24_C | E21: Turunan
A22: Penghematan 24 bulan vs A (%) | B22: =0 | C22: =(T24_A-T24_B)/T24_A | D22: =(T24_A-T24_C)/T24_A | E22: Turunan
A23: Pengurangan headcount bulan 24 (orang) | B23: =0 | C23: ='Perbandingan 24 Bulan'!AA130-'Perbandingan 24 Bulan'!AA131 | D23: ='Perbandingan 24 Bulan'!AA130-'Perbandingan 24 Bulan'!AA132 | E23: Turunan
A24: Titik impas (bulan kumulatif mulai lebih murah dari A) | B24: - | C24: =IFERROR(MATCH(TRUE,INDEX('Perbandingan 24 Bulan'!D153:AA153>0,0),0),"tidak tercapai") | D24: =IFERROR(MATCH(TRUE,INDEX('Perbandingan 24 Bulan'!D154:AA154>0,0),0),"tidak tercapai") | E24: Lembar 'Perbandingan 24 Bulan'
A26: C. APA YANG PECAH LEBIH DULU DAN KAPAN (pada Skenario B yang direkomendasikan)
A27: Urutan | B27: Titik pecah | C27: Pemicu berangka | D27: Perkiraan waktu | E27: Peringatan dini yang harus dipasang | F27: Mitigasi
A28: 1 | B28: Kanal darurat 24 jam (SOP-05) kehilangan penutup shift | C28: Dengan 2 CS Agent Pekanbaru + 1 Padang, shift ketiga di salah satu kota ditutup lintas kota. Satu orang sakit atau resign = shift kosong. | D28: Kapan saja setelah bulan 14 - risiko harian, bukan risiko volume | E28: Persentase peringatan darurat ditangani <=15 menit turun di bawah 95% (target Bab 5) | F28: Anggarkan 1 CS Agent cadangan lintas kota; jangan pangkas di bawah 3 total.
A29: 2 | B29: Agen CS otomatis kewalahan pada kategori di luar naskah baku | C29: Pada 2.400 order/hari, 1.584 tiket/bulan, eskalasi 634/bulan = 21/hari. Aman. Yang pecah lebih dulu adalah KERAGAMAN kasus, bukan jumlahnya: peluncuran AntarTravel/AntarBox memunculkan kategori tiket yang belum ada di basis pengetahuan. | D29: Bulan ke-2 setelah setiap peluncuran layanan baru | E29: Tingkat tiket dibuka ulang naik melewati 8%; deflection turun di bawah 50% | F29: Basis pengetahuan wajib diperbarui SEBELUM rilis layanan baru - masukkan sebagai gerbang di SOP-11.
A30: 3 | B30: Pemelihara otomasi menjadi titik tunggal kegagalan | C30: Satu Backend Engineer (Mid) yang dialihfungsikan memelihara 13 komponen AI sekaligus mengerjakan fitur. Beban lebih dari 1 FTE sejak bulan 16. | D30: Bulan 16-18 | E30: Antrean cacat otomasi > 5 terbuka lebih dari 2 pekan | F30: Kontraktor 0,5 FTE sudah dianggarkan (H-1); naikkan ke 1,0 FTE pada bulan 16 atau kembalikan 1 Backend Mid.
A31: 4 | B31: Beban kepatuhan UU PDP melampaui kapasitas DPO merangkap | C31: Head of Legal & Compliance merangkap DPO sudah memikul perizinan, kontrak, dan hak subjek data. Otomasi menambah DPIA berkala, register keputusan otomatis (Pasal 10), dan uji transfer data (Pasal 56). | D31: Bulan 15-18, atau seketika bila ada insiden data | E31: Permintaan hak subjek data lewat SLA 14 hari; DPIA fitur baru tertunda >1 kuartal | F31: 0,2 FTE sudah dianggarkan (H-3); bila lewat, pisahkan DPO dari Head of Legal - ini konsekuensi biaya, bukan pilihan.
A32: 5 | B32: Gerbang rilis tanpa QA manusia meloloskan cacat pada alur uang | C32: QA Engineer dihapus; hak veto pindah ke Engineering Manager yang juga menulis kode. Pemisahan penulis-penguji hilang. | D32: Rilis besar pertama yang menyentuh dompet setelah bulan 13 | E32: Proporsi rilis tanpa cacat kritikal turun; simulasi e2e tidak 100% lolos | F32: Aturan mutlak: perubahan yang menyentuh dompet WAJIB ditinjau Backend Engineer Senior yang bukan penulisnya. Tuliskan di SOP-11.
A34: D. PERAN YANG TIDAK BOLEH DIOTOMASI (dengan dasarnya)
A35: Peran | B35: Dasar | C35: Jenis dasar
A36: JD-22 Head of Legal & Compliance merangkap DPO | B36: UU 27/2022 Pasal 53 mewajibkan penunjukan pejabat/petugas yang menjalankan fungsi pelindungan data pribadi; Putusan MK 151/PUU-XXII/2024 memperluas tafsirnya. Jabatan melekat pada orang. | F36: Hukum eksplisit
A37: JD-01 Direktur Utama, JD-02 CTO, JD-03 COO, JD-19 Head of Finance | B37: Organ perseroan dan penanggung jawab laporan keuangan serta pajak. Menandatangani perjanjian dan memikul akuntabilitas yang tidak dapat dialihkan ke sistem. | F37: Hukum & tata kelola
A38: JD-18 Trust & Safety Officer - keputusan penangguhan akun | B38: UU 27/2022 Pasal 10: subjek data berhak keberatan atas keputusan yang HANYA didasarkan pemrosesan otomatis dan berdampak signifikan. Penangguhan mitra menghilangkan penghasilan - jelas berdampak signifikan. | F38: Hukum eksplisit
A39: JD-17 CS Agent - penerimaan peringatan darurat | B39: SOP-05: peringatan darurat wajib ditangani manusia dalam 15 menit, kanal aktif 24 jam. CS Agent adalah penerima pertama di luar jam Trust & Safety. | F39: Keselamatan jiwa
A40: JD-21 Treasury/Settlement Officer | B40: DESAIN-ORGANISASI 6 dan SOP-07: penyetuju != pelaksana != perekonsiliasi. Mesin boleh merekonsiliasi; penanggung jawab yang menahan tutup buku harus orang yang berbeda. | F40: Kontrol internal wajib
A41: JD-13 City Manager, JD-14 Ops Supervisor, JD-15 Partner Acquisition, JD-25 Merchant Acquisition | B41: Rekrutmen dan pembinaan mitra, pemeriksaan fisik kendaraan, penanganan kecelakaan, hubungan pemerintah daerah dan pengelola pasar, negosiasi merchant. Risiko R-07 menjadikan pasokan mitra sebagai risiko dengan kemungkinan TERTINGGI pada register risiko - ini posisi terakhir yang boleh dipangkas. | F41: Sifat pekerjaan lapangan

Sheet Tumpukan Tool AI
A1: AntarKita - Tumpukan Tool AI, Volume, dan Biaya Bulanan
A2: Disusun 7 September 2026. Seluruh harga penyedia DIVERIFIKASI pada tanggal tersebut - lihat lembar 'Sumber & Catatan' [S-62] s.d. [S-77]. Angka yang tidak dapat diverifikasi ditandai [ASUMSI] pada kolom Status. Sel berlatar kuning adalah input yang boleh diubah pemilik.
A3: USULAN ANALIS - BUKAN KEPUTUSAN. Seluruh pemilihan tool masih menunggu keputusan Dewan Komisaris.
A5: A. BLOK ASUMSI (bernama - seluruh rumus merujuk ke sel-sel di bawah)
A6: Parameter | D6: Nilai | E6: Satuan | F6: Status data / sumber
A7: Kurs USD/IDR (4 September 2026) | D7: 17631 | E7: Rp/USD | F7: [S-74] exchange-rates.org, diakses 7 Sep 2026
A8: PPN PMSE efektif atas langganan digital luar negeri | D8: 0.11 | E8: % dari nilai | F8: [S-75] 12% x DPP nilai lain 11/12 (UU HPP, PMK 131/2024, PER-12/PJ/2025)
A9: Buffer risiko kurs | D9: 0.08 | E9: % dari nilai | F9: [ASUMSI] penyusun - tidak ada sumber proyeksi kurs yang dapat dipakai
A10: Cadangan gross-up PPh Pasal 26 | D10: 0.1 | E10: % dari nilai | F10: [ASUMSI] tarif umum 20% [S-77]; dicadangkan 10% karena sebagian penyedia berada di negara P3B dan sebagian pembayaran bukan objek royalti
A11: Hari operasi per bulan | D11: 30 | E11: hari | F11: [ASUMSI]
A12: Order selesai per hari - akhir Fase 0 | D12: 30 | E12: order/hari | F12: [ASUMSI] uji tertutup Pekanbaru
A13: Order selesai per hari - akhir Fase 1 | D13: 600 | E13: order/hari | F13: Manual SOP Bab 5, target akhir tahun 1 [ASUMSI penyusun manual]
A14: Order selesai per hari - akhir Fase 2 | D14: 2400 | E14: order/hari | F14: Manual SOP Bab 5, target akhir tahun 2 [ASUMSI penyusun manual]
A15: Tiket per 1.000 order - tahun 1 | D15: 35 | E15: tiket | F15: Manual SOP Bab 5 (batas atas) [ASUMSI]
A16: Tiket per 1.000 order - tahun 2 | D16: 22 | E16: tiket | F16: Manual SOP Bab 5 (batas atas) [ASUMSI]
A17: Tingkat deflection agen CS otomatis | D17: 0.6 | E17: % tiket selesai tanpa manusia | F17: [ASUMSI] rentang wajar 50-70%. JANGAN memakai klaim vendor 90%+
A18: Verifikasi identitas mitra+merchant per bulan - Fase 0 | D18: 40 | E18: verifikasi | F18: [ASUMSI] turunan target mitra Bab 5 & rasio mitra aktif 20% [S-58]
... A31: Faktor biaya tersembunyi Skenario C | D31: 1.8 | E31: x | F31: [ASUMSI] eskalasi & kegagalan lebih sering, beban kepatuhan lebih besar
A33: B. VOLUME TURUNAN PER BULAN (run-rate pada akhir fase)
A34: Ukuran | D34: Fase 0 | E34: Fase 1 | F34: Fase 2 | G34: Rumus / catatan
A35: Order selesai per bulan | D35: =Order_Hari_F0*Hari_Bulan | E35: =Order_Hari_F1*Hari_Bulan | F35: =Order_Hari_F2*Hari_Bulan | G35: order/hari x hari operasi
A36: Tiket masuk per bulan | D36: =D35*Tiket_Per1000_Th1/1000 | E36: =E35*Tiket_Per1000_Th1/1000 | F36: =F35*Tiket_Per1000_Th2/1000 | G36: order/bulan x tiket per 1.000 order
A37: Tiket ditangani agen AI (deflection) | D37: =D36*Deflection_CS | E37: =E36*Deflection_CS | F37: =F36*Deflection_CS | G37: tiket x tingkat deflection
A38: Tiket dieskalasi ke manusia | D38: =D36-D37 | E38: =E36-E37 | F38: =F36-F37 | G38: tiket - tiket yang dideflect
A39: Verifikasi identitas per bulan | D39: =Verif_F0 | E39: =Verif_F1 | F39: =Verif_F2 | G39: blok asumsi
A40: Merchant baru per bulan | D40: =Merchant_F0 | E40: =Merchant_F1 | F40: =Merchant_F2 | G40: blok asumsi
A41: Item katalog diperiksa per bulan | D41: =D40*15 | E41: =E40*15 | F41: =F40*15 | G41: merchant baru x 15 item [ASUMSI]
A42: Kueri analitik bahasa alami per bulan | D42: 30 | E42: 100 | F42: 200 | G42: [ASUMSI] pengganti pekerjaan pelaporan rutin JD-12
A43: Aset konten pemasaran per bulan | D43: 20 | E43: 120 | F43: 300 | G43: [ASUMSI] pengganti pekerjaan produksi konten JD-24
A44: Order ditriase anti-fraud per bulan | D44: =D35*0.03 | E44: =E35*0.03 | F44: =F35*0.03 | G44: 3% order [ASUMSI]
A46: C. PERHITUNGAN VOLUME TOKEN LLM PER BULAN
A47: Kegunaan | B47: Token input per unit | C47: Token output per unit | D47: Basis volume | E47: Token IN Fase 0 | F47: Token IN Fase 1 | G47: Token IN Fase 2 | H47: Token OUT Fase 0 | I47: Token OUT Fase 1 | J47: Token OUT Fase 2
A48: Agen CS tingkat 1 (rata-rata 3 giliran + konteks basis pengetahuan) | B48: 8000 | C48: 900 | D48: baris 37 | E48: =D37*$B48 | F48: =E37*$B48 | G48: =F37*$B48 | H48: =D37*$C48 | I48: =E37*$C48 | J48: =F37*$C48
A49: Triase & ringkasan tiket yang dieskalasi | B49: 3000 | C49: 400 | D49: baris 38 | E49: =D38*$B49 | F49: =E38*$B49 | G49: =F38*$B49 | H49: =D38*$C49 | I49: =E38*$C49 | J49: =F38*$C49
A50: Moderasi katalog & pemeriksaan kewajaran harga | B50: 1200 | C50: 150 | D50: baris 41 | E50: =D41*$B50 | F50: =E41*$B50 | G50: =F41*$B50 | H50: =D41*$C50 | I50: =E41*$C50 | J50: =F41*$C50
A51: Analitik & laporan bahasa alami | B51: 15000 | C51: 2000 | D51: baris 42 | E51: =D42*$B51 | F51: =E42*$B51 | G51: =F42*$B51 | H51: =D42*$C51 | I51: =E42*$C51 | J51: =F42*$C51
A52: Produksi konten pemasaran & naskah kampanye | B52: 3000 | C52: 1500 | D52: baris 43 | E52: =D43*$B52 | F52: =E43*$B52 | G52: =F43*$B52 | H52: =D43*$C52 | I52: =E43*$C52 | J52: =F43*$C52
A53: Triase sinyal anti-fraud (pemeringkatan, bukan keputusan) | B53: 4000 | C53: 500 | D53: baris 44 | E53: =D44*$B53 | F53: =E44*$B53 | G53: =F44*$B53 | H53: =D44*$C53 | I53: =E44*$C53 | J53: =F44*$C53
A54: TOTAL TOKEN PER BULAN | E54: =SUM(E48:E53) | F54: =SUM(F48:F53) | G54: =SUM(G48:G53) | H54: =SUM(H48:H53) | I54: =SUM(I48:I53) | J54: =SUM(J48:J53)
D55: Fase 0 | E55: Fase 1 | F55: Fase 2
...

Sheet Penilaian Peran
A1: AntarKita - Penilaian Otomatisasi 26 Uraian Jabatan (JD-01 s.d. JD-26)
A2: Metode: tiap peran dibongkar menjadi tugas, lalu dinilai pada empat sumbu. Skor = 0,35xA + 0,25xB + 0,25x(100-C) + 0,15x(100-D). Kategori otomatis dari skor, KECUALI bila kolom 'Pembatas' memuat syarat hukum atau keselamatan - kolom 'Kategori final' adalah yang mengikat.
A3: USULAN ANALIS - keputusan mengurangi atau menghapus posisi ada pada Dewan Komisaris (DESAIN-ORGANISASI 6).
A5: Kode | B5: Jabatan | C5: Tugas inti (ringkas, dari Bab 3 manual) | D5: A. Sifat tugas rutin/terstruktur (0-100) | E5: B. Volume & prediktabilitas (0-100) | F5: C. Risiko bila salah (0-100) | G5: D. Syarat hukum/keselamatan yang mengharuskan manusia (0-100) | H5: Skor otomatisasi (0-100) | I5: Kategori dari skor | J5: Pembatas hukum / operasional | K5: KATEGORI FINAL (mengikat) | L5: Tindakan yang diusulkan
A6: JD-01 | B6: Direktur Utama (CEO) | C6: RKAT, kas & runway, hubungan investor, tanda tangan perjanjian kemitraan & PJP, persetujuan >Rp50 jt ke Komisaris | D6: 15 | E6: 20 | F6: 95 | G6: 95 | H6: =0.35*D6+0.25*E6+0.25*(100-F6)+0.15*(100-G6) | I6: =IF(G6>=80,"WAJIB MANUSIA",IF(H6>=70,"OTOMATIS PENUH",IF(H6>=50,"AUGMENTASI TINGGI",IF(H6>=35,"AUGMENTASI RENDAH","WAJIB MANUSIA")))) | J6: Organ perseroan; menandatangani perjanjian; akuntabilitas hukum tidak dapat didelegasikan ke sistem | K6: WAJIB MANUSIA | L6: Tetap 1 orang. AI dipakai untuk penyusunan paket laporan & analisis skenario.
A7: JD-02 | B7: Direktur Teknologi (CTO) | C7: Peta jalan, keandalan, pengendali teknis kepatuhan UU PDP, incident commander S1, hak akses & PIN admin | D7: 25 | E7: 30 | F7: 90 | G7: 90 | H7: =0.35*D7+0.25*E7+0.25*(100-F7)+0.15*(100-G7) | I7: =IF(G7>=80,"WAJIB MANUSIA",IF(H7>=70,"OTOMATIS PENUH",IF(H7>=50,"AUGMENTASI TINGGI",IF(H7>=35,"AUGMENTASI RENDAH","WAJIB MANUSIA")))) | J7: Pengendali teknis UU PDP; penetapan keparahan insiden; direksi | K7: WAJIB MANUSIA | L7: Tetap 1 orang. Rentang kendali teknis naik karena agen koding; tetap pemilik akuntabilitas.
A8: JD-03 | B8: Direktur Operasi (COO) | C8: Target kota, sakelar layanan darurat, pemilik SOP-03/SOP-05, eskalasi tingkat 3, playbook kota | D8: 25 | E8: 35 | F8: 90 | G8: 90 | H8: =0.35*D8+0.25*E8+0.25*(100-F8)+0.15*(100-G8) | I8: =IF(G8>=80,"WAJIB MANUSIA",IF(H8>=70,"OTOMATIS PENUH",IF(H8>=50,"AUGMENTASI TINGGI",IF(H8>=35,"AUGMENTASI RENDAH","WAJIB MANUSIA")))) | J8: Keputusan darurat operasional & keselamatan; direksi | K8: WAJIB MANUSIA | L8: Tetap 1 orang. Pada Skenario C merangkap Head of CX - inilah titik pecah pertama.
A9: JD-04 | B9: Engineering Manager | C9: Siklus rilis, migrasi bernomor, tinjauan kode, wakil incident commander, pembinaan | D9: 40 | E9: 45 | F9: 70 | G9: 25 | H9: =0.35*D9+0.25*E9+0.25*(100-F9)+0.15*(100-G9) | I9: =IF(G9>=80,"WAJIB MANUSIA",IF(H9>=70,"OTOMATIS PENUH",IF(H9>=50,"AUGMENTASI TINGGI",IF(H9>=35,"AUGMENTASI RENDAH","WAJIB MANUSIA")))) | J9: Pemilik postmortem & gerbang penggabungan kode | K9: AUGMENTASI RENDAH | L9: Tetap 1 orang, mengambil alih gerbang rilis dari QA Engineer.
A10: JD-05 | B10: Mobile Engineer - Senior | C10: Arsitektur aplikasi, ErrorBoundary, langganan realtime, alur kritikal yang menyentuh uang | D10: 55 | E10: 60 | F10: 55 | G10: 10 | H10: =0.35*D10+0.25*E10+0.25*(100-F10)+0.15*(100-G10) | I10: =IF(G10>=80,"WAJIB MANUSIA",IF(H10>=70,"OTOMATIS PENUH",IF(H10>=50,"AUGMENTASI TINGGI",IF(H10>=35,"AUGMENTASI RENDAH","WAJIB MANUSIA")))) | J10: - | K10: AUGMENTASI TINGGI | L10: Tetap 1 orang; menyerap pekerjaan 1 Mobile Mid dengan agen koding.
A11: JD-06 | B11: Mobile Engineer - Mid | C11: Membangun layar & alur baru, memperbaiki cacat, skenario sapuan rute, teks antarmuka | D11: 65 | E11: 68 | F11: 45 | G11: 5 | H11: =0.35*D11+0.25*E11+0.25*(100-F11)+0.15*(100-G11) | I11: =IF(G11>=80,"WAJIB MANUSIA",IF(H11>=70,"OTOMATIS PENUH",IF(H11>=50,"AUGMENTASI TINGGI",IF(H11>=35,"AUGMENTASI RENDAH","WAJIB MANUSIA")))) | J11: - | K11: AUGMENTASI TINGGI | L11: Kedua baris (dasar + gelombang 2) dihapus pada Skenario B.
A12: JD-07 | B12: Backend Engineer - Senior | C12: Skema dompet & pembagian hasil, RLS, idempotensi, aturan anti-fraud, simulasi ujung-ke-ujung | D12: 45 | E12: 50 | F12: 85 | G12: 15 | H12: =0.35*D12+0.25*E12+0.25*(100-F12)+0.15*(100-G12) | I12: =IF(G12>=80,"WAJIB MANUSIA",IF(H12>=70,"OTOMATIS PENUH",IF(H12>=50,"AUGMENTASI TINGGI",IF(H12>=35,"AUGMENTASI RENDAH","WAJIB MANUSIA")))) | J12: Perubahan yang menyentuh uang wajib ditinjau manusia (SOP-11, DESAIN 6) | K12: AUGMENTASI RENDAH | L12: Tetap. Gelombang 2 dipertahankan di Skenario B (titik tunggal kegagalan bila dihapus).
A13: JD-08 | B13: Backend Engineer - Mid | C13: Fungsi panel admin non-keuangan, tiket, notifikasi, indeks, temuan advisor | D13: 65 | E13: 65 | F13: 55 | G13: 10 | H13: =0.35*D13+0.25*E13+0.25*(100-F13)+0.15*(100-G13) | I13: =IF(G13>=80,"WAJIB MANUSIA",IF(H13>=70,"OTOMATIS PENUH",IF(H13>=50,"AUGMENTASI TINGGI",IF(H13>=35,"AUGMENTASI RENDAH","WAJIB MANUSIA")))) | J13: - | K13: AUGMENTASI TINGGI | L13: Baris dasar dipertahankan & dialihfungsikan jadi pemelihara otomasi; gelombang 2 dihapus.
A14: JD-09 | B14: QA Engineer | C14: Menjalankan simulasi e2e, sapuan rute otomatis, uji alur uang, daftar periksa rilis, bukti uji | D14: 80 | E14: 85 | F14: 50 | G14: 10 | H14: =0.35*D14+0.25*E14+0.25*(100-F14)+0.15*(100-G14) | I14: =IF(G14>=80,"WAJIB MANUSIA",IF(H14>=70,"OTOMATIS PENUH",IF(H14>=50,"AUGMENTASI TINGGI",IF(H14>=35,"AUGMENTASI RENDAH","WAJIB MANUSIA")))) | J14: Hak menahan rilis (SOP-11) berpindah ke Engineering Manager | K14: OTOMATIS PENUH | L14: Kedua baris dihapus; gerbang rilis dijalankan pipeline uji + Engineering Manager.
A15: JD-10 | B15: Junior Software Engineer | C15: Perbaikan cacat kecil, pengujian dasar, membantu QA, pembinaan, catatan teknis | D15: 85 | E15: 85 | F15: 35 | G15: 0 | H15: =0.35*D15+0.25*E15+0.25*(100-F15)+0.15*(100-G15) | I15: =IF(G15>=80,"WAJIB MANUSIA",IF(H15>=70,"OTOMATIS PENUH",IF(H15>=50,"AUGMENTASI TINGGI",IF(H15>=35,"AUGMENTASI RENDAH","WAJIB MANUSIA")))) | J15: Nilai kaderisasi lokal (keputusan strategis, bukan teknis) | K15: OTOMATIS PENUH | L15: Baris Pekanbaru dihapus; baris Padang dipertahankan sebagai keputusan kaderisasi - MENUNGGU KOMISARIS.
A16: JD-11 | B16: Product Designer (UI/UX) | C16: Sistem desain, alur pemesanan, panel admin, teks antarmuka, uji 5 pengguna per kota | D16: 50 | E16: 55 | F16: 45 | G16: 5 | H16: =0.35*D16+0.25*E16+0.25*(100-F16)+0.15*(100-G16) | I16: =IF(G16>=80,"WAJIB MANUSIA",IF(H16>=70,"OTOMATIS PENUH",IF(H16>=50,"AUGMENTASI TINGGI",IF(H16>=35,"AUGMENTASI RENDAH","WAJIB MANUSIA")))) | J16: Uji dengan pengguna nyata tidak dapat disimulasikan | K16: AUGMENTASI TINGGI | L16: Baris dasar tetap; gelombang 2 dihapus.
A17: JD-12 | B17: Data Analyst | C17: Portal Eksekutif & Laba Rugi, audit KPI bulanan, rasio mitra aktif, data uji tuntas, definisi metrik | D17: 75 | E17: 80 | F17: 45 | G17: 10 | H17: =0.35*D17+0.25*E17+0.25*(100-F17)+0.15*(100-G17) | I17: =IF(G17>=80,"WAJIB MANUSIA",IF(H17>=70,"OTOMATIS PENUH",IF(H17>=50,"AUGMENTASI TINGGI",IF(H17>=35,"AUGMENTASI RENDAH","WAJIB MANUSIA")))) | J17: Definisi resmi metrik butuh pemilik manusia yang dapat dimintai pertanggungjawaban | K17: OTOMATIS PENUH | L17: Posisi dihapus; kepemilikan definisi metrik pindah ke Head of Finance, produksi laporan ke BI bahasa alami.
... A31: JD-26 | B31: HR & GA Generalist | C31: Rekrutmen bertahap, dua struktur payroll, pendaftaran BPJS, THR, kontrak & arsip, kantor 2 kota, pelatihan PDP | D31: 60 | E31: 65 | F31: 70 | G31: 55 | H31: =0.35*D31+0.25*E31+0.25*(100-F31)+0.15*(100-G31) | I31: =IF(G31>=80,"WAJIB MANUSIA",IF(H31>=70,"OTOMATIS PENUH",IF(H31>=50,"AUGMENTASI TINGGI",IF(H31>=35,"AUGMENTASI RENDAH","WAJIB MANUSIA")))) | J31: Penanggung jawab kepatuhan pengupahan & pelaporan jaminan sosial | K31: AUGMENTASI TINGGI | L31: Tetap 1 orang (tidak dapat dipangkas lebih jauh); payroll & administrasi diotomasi.
B32: Rekap jumlah peran per kategori final
B33: OTOMATIS PENUH | H33: =COUNTIF($K$6:$K$31,B33)
B34: AUGMENTASI TINGGI | H34: =COUNTIF($K$6:$K$31,B34)
B35: AUGMENTASI RENDAH | H35: =COUNTIF($K$6:$K$31,B35)
B36: WAJIB MANUSIA | H36: =COUNTIF($K$6:$K$31,B36)
B37: TOTAL | H37: =SUM(H33:H36)
A39: Catatan sumbu D (syarat manusia): 95-100 = kewajiban hukum eksplisit (UU 27/2022 Pasal 53 untuk DPO; organ perseroan; penanggung jawab laporan keuangan & pajak). 60-90 = keputusan yang menimbulkan akibat hukum atau berdampak signifikan pada subjek data (UU 27/2022 Pasal 10 - hak keberatan atas keputusan yang hanya berdasar pemrosesan otomatis), atau keselamatan jiwa (SOP-05). 20-55 = kontrol internal wajib (pemisahan tugas keuangan DESAIN 6 / SOP-07). 0-15 = tidak ada syarat manusia.

Sheet Skenario A B C
A1: AntarKita - Skenario A (semua manusia) / B (hibrida - rekomendasi) / C (AI-maksimal)
A2: Baris posisi, CTC per orang, bulan mulai, dan jumlah orang per fase adalah SALINAN PERSIS dari AntarKita-Model-Biaya-SDM.xlsx lembar 'Biaya Bulanan' baris 26-63. Kolom 'Potong B' dan 'Potong C' adalah INPUT yang boleh diubah pemilik; seluruh angka lain adalah rumus hidup.
A3: Uji A vs model lama harus menghasilkan 0 pada baris UJI di bawah.
A5: No | B5: Direktorat | C5: Posisi | D5: Level | E5: Bulan Mulai | F5: CTC per orang (Rp) | G5: Bulan aktif per orang (bln 1-24) | H5: Orang A F0 | I5: Orang A F1 | J5: Orang A F2 | K5: POTONG B | L5: POTONG C | M5: Orang B F0 | N5: Orang B F1 | O5: Orang B F2 | P5: Orang C F0 | Q5: Orang C F1 | R5: Orang C F2 | S5: Biaya A F0 | T5: Biaya A F1 | U5: Biaya A F2 | V5: Biaya B F0 | W5: Biaya B F1 | X5: Biaya B F2 | Y5: Biaya C F0 | Z5: Biaya C F1 | AA5: Biaya C F2 | AB5: Kum 24 bln A | AC5: Kum 24 bln B | AD5: Kum 24 bln C
A6: 1 | B6: Direksi & Tata Kelola | C6: Direktur Utama (CEO) | D6: C-Level | E6: 1 | F6: 44156676 | G6: 24 | H6: 1 | I6: 1 | J6: 1 | K6: 0 | L6: 0 | M6: =MAX(0,H6-$K6) | N6: =MAX(0,I6-$K6) | O6: =MAX(0,J6-$K6) | P6: =MAX(0,H6-$L6) | Q6: =MAX(0,I6-$L6) | R6: =MAX(0,J6-$L6) | S6: =$F6*H6 | T6: =$F6*I6 | U6: =$F6*J6 | V6: =$F6*M6 | W6: =$F6*N6 | X6: =$F6*O6 | Y6: =$F6*P6 | Z6: =$F6*Q6 | AA6: =$F6*R6 | AB6: =$F6*$G6*$J6 | AC6: =$F6*$G6*MAX(0,$J6-$K6) | AD6: =$F6*$G6*MAX(0,$J6-$L6)
A7: 2 | B7: Direksi & Tata Kelola | C7: HR & GA Generalist | D7: Staf Senior | E7: 3 | F7: 11114345 | G7: 22 | H7: 1 | I7: 1 | J7: 1 | K7: 0 | L7: 0 | M7: =MAX(0,H7-$K7) | N7: =MAX(0,I7-$K7) | O7: =MAX(0,J7-$K7) | P7: =MAX(0,H7-$L7) | Q7: =MAX(0,I7-$L7) | R7: =MAX(0,J7-$L7) | S7: =$F7*H7 | T7: =$F7*I7 | U7: =$F7*J7 | V7: =$F7*M7 | W7: =$F7*N7 | X7: =$F7*O7 | Y7: =$F7*P7 | Z7: =$F7*Q7 | AA7: =$F7*R7 | AB7: =$F7*$G7*$J7 | AC7: =$F7*$G7*MAX(0,$J7-$K7) | AD7: =$F7*$G7*MAX(0,$J7-$L7)
A8: 3 | B8: Teknologi | C8: Direktur Teknologi (CTO) | D8: C-Level | E8: 1 | F8: 37948826 | G8: 24 | H8: 1 | I8: 1 | J8: 1 | K8: 0 | L8: 0 | M8: =MAX(0,H8-$K8) | N8: =MAX(0,I8-$K8) | O8: =MAX(0,J8-$K8) | P8: =MAX(0,H8-$L8) | Q8: =MAX(0,I8-$L8) | R8: =MAX(0,J8-$L8) | S8: =$F8*H8 | T8: =$F8*I8 | U8: =$F8*J8 | V8: =$F8*M8 | W8: =$F8*N8 | X8: =$F8*O8 | Y8: =$F8*P8 | Z8: =$F8*Q8 | AA8: =$F8*R8 | AB8: =$F8*$G8*$J8 | AC8: =$F8*$G8*MAX(0,$J8-$K8) | AD8: =$F8*$G8*MAX(0,$J8-$L8)
A9: 4 | B9: Teknologi | C9: Engineering Manager | D9: Manajer | E9: 4 | F9: 34844901 | G9: 21 | H9: 0 | I9: 1 | J9: 1 | K9: 0 | L9: 0 | M9: =MAX(0,H9-$K9) | N9: =MAX(0,I9-$K9) | O9: =MAX(0,J9-$K9) | P9: =MAX(0,H9-$L9) | Q9: =MAX(0,I9-$L9) | R9: =MAX(0,J9-$L9) | S9: =$F9*H9 | T9: =$F9*I9 | U9: =$F9*J9 | V9: =$F9*M9 | W9: =$F9*N9 | X9: =$F9*O9 | Y9: =$F9*P9 | Z9: =$F9*Q9 | AA9: =$F9*R9 | AB9: =$F9*$G9*$J9 | AC9: =$F9*$G9*MAX(0,$J9-$K9) | AD9: =$F9*$G9*MAX(0,$J9-$L9)
A10: 5 | B10: Teknologi | C10: Mobile Engineer (Senior) | D10: Senior | E10: 1 | F10: 25533126 | G10: 24 | H10: 1 | I10: 1 | J10: 1 | K10: 0 | L10: 0 | M10: =MAX(0,H10-$K10) | N10: =MAX(0,I10-$K10) | O10: =MAX(0,J10-$K10) | P10: =MAX(0,H10-$L10) | Q10: =MAX(0,I10-$L10) | R10: =MAX(0,J10-$L10) | S10: =$F10*H10 | T10: =$F10*I10 | U10: =$F10*J10 | V10: =$F10*M10 | W10: =$F10*N10 | X10: =$F10*O10 | Y10: =$F10*P10 | Z10: =$F10*Q10 | AA10: =$F10*R10 | AB10: =$F10*$G10*$J10 | AC10: =$F10*$G10*MAX(0,$J10-$K10) | AD10: =$F10*$G10*MAX(0,$J10-$L10)
A11: 6 | B11: Teknologi | C11: Mobile Engineer (Mid) | D11: Mid | E11: 5 | F11: 15600566 | G11: 20 | H11: 0 | I11: 1 | J11: 1 | K11: 1 | L11: 1 | M11: =MAX(0,H11-$K11) | N11: =MAX(0,I11-$K11) | O11: =MAX(0,J11-$K11) | P11: =MAX(0,H11-$L11) | Q11: =MAX(0,I11-$L11) | R11: =MAX(0,J11-$L11) | S11: =$F11*H11 | T11: =$F11*I11 | U11: =$F11*J11 | V11: =$F11*M11 | W11: =$F11*N11 | X11: =$F11*O11 | Y11: =$F11*P11 | Z11: =$F11*Q11 | AA11: =$F11*R11 | AB11: =$F11*$G11*$J11 | AC11: =$F11*$G11*MAX(0,$J11-$K11) | AD11: =$F11*$G11*MAX(0,$J11-$L11)
A12: 7 | B12: Teknologi | C12: Mobile Engineer (Mid) - gelombang 2 | D12: Mid | E12: 14 | F12: 15600566 | G12: 11 | H12: 0 | I12: 0 | J12: 1 | K12: 1 | L12: 1 | M12: =MAX(0,H12-$K12) | N12: =MAX(0,I12-$K12) | O12: =MAX(0,J12-$K12) | P12: =MAX(0,H12-$L12) | Q12: =MAX(0,I12-$L12) | R12: =MAX(0,J12-$L12) | S12: =$F12*H12 | T12: =$F12*I12 | U12: =$F12*J12 | V12: =$F12*M12 | W12: =$F12*N12 | X12: =$F12*O12 | Y12: =$F12*P12 | Z12: =$F12*Q12 | AA12: =$F12*R12 | AB12: =$F12*$G12*$J12 | AC12: =$F12*$G12*MAX(0,$J12-$K12) | AD12: =$F12*$G12*MAX(0,$J12-$L12)
A13: 8 | B13: Teknologi | C13: Backend Engineer (Senior) | D13: Senior | E13: 1 | F13: 25533126 | G13: 24 | H13: 1 | I13: 1 | J13: 1 | K13: 0 | L13: 0 | M13: =MAX(0,H13-$K13) | N13: =MAX(0,I13-$K13) | O13: =MAX(0,J13-$K13) | P13: =MAX(0,H13-$L13) | Q13: =MAX(0,I13-$L13) | R13: =MAX(0,J13-$L13) | S13: =$F13*H13 | T13: =$F13*I13 | U13: =$F13*J13 | V13: =$F13*M13 | W13: =$F13*N13 | X13: =$F13*O13 | Y13: =$F13*P13 | Z13: =$F13*Q13 | AA13: =$F13*R13 | AB13: =$F13*$G13*$J13 | AC13: =$F13*$G13*MAX(0,$J13-$K13) | AD13: =$F13*$G13*MAX(0,$J13-$L13)
A14: 9 | B14: Teknologi | C14: Backend Engineer (Senior) - gelombang 2 | D14: Senior | E14: 19 | F14: 25533126 | G14: 6 | H14: 0 | I14: 0 | J14: 1 | K14: 0 | L14: 1 | M14: =MAX(0,H14-$K14) | N14: =MAX(0,I14-$K14) | O14: =MAX(0,J14-$K14) | P14: =MAX(0,H14-$L14) | Q14: =MAX(0,I14-$L14) | R14: =MAX(0,J14-$L14) | S14: =$F14*H14 | T14: =$F14*I14 | U14: =$F14*J14 | V14: =$F14*M14 | W14: =$F14*N14 | X14: =$F14*O14 | Y14: =$F14*P14 | Z14: =$F14*Q14 | AA14: =$F14*R14 | AB14: =$F14*$G14*$J14 | AC14: =$F14*$G14*MAX(0,$J14-$K14) | AD14: =$F14*$G14*MAX(0,$J14-$L14)
A15: 10 | B15: Teknologi | C15: Backend Engineer (Mid) | D15: Mid | E15: 4 | F15: 15600566 | G15: 21 | H15: 0 | I15: 1 | J15: 1 | K15: 0 | L15: 1 | M15: =MAX(0,H15-$K15) | N15: =MAX(0,I15-$K15) | O15: =MAX(0,J15-$K15) | P15: =MAX(0,H15-$L15) | Q15: =MAX(0,I15-$L15) | R15: =MAX(0,J15-$L15) | S15: =$F15*H15 | T15: =$F15*I15 | U15: =$F15*J15 | V15: =$F15*M15 | W15: =$F15*N15 | X15: =$F15*O15 | Y15: =$F15*P15 | Z15: =$F15*Q15 | AA15: =$F15*R15 | AB15: =$F15*$G15*$J15 | AC15: =$F15*$G15*MAX(0,$J15-$K15) | AD15: =$F15*$G15*MAX(0,$J15-$L15)
A16: 11 | B16: Teknologi | C16: Backend Engineer (Mid) - gelombang 2 | D16: Mid | E16: 13 | F16: 15600566 | G16: 12 | H16: 0 | I16: 0 | J16: 1 | K16: 1 | L16: 1 | M16: =MAX(0,H16-$K16) | N16: =MAX(0,I16-$K16) | O16: =MAX(0,J16-$K16) | P16: =MAX(0,H16-$L16) | Q16: =MAX(0,I16-$L16) | R16: =MAX(0,J16-$L16) | S16: =$F16*H16 | T16: =$F16*I16 | U16: =$F16*J16 | V16: =$F16*M16 | W16: =$F16*N16 | X16: =$F16*O16 | Y16: =$F16*P16 | Z16: =$F16*Q16 | AA16: =$F16*R16 | AB16: =$F16*$G16*$J16 | AC16: =$F16*$G16*MAX(0,$J16-$K16) | AD16: =$F16*$G16*MAX(0,$J16-$L16)
A17: 12 | B17: Teknologi | C17: QA Engineer | D17: Mid | E17: 6 | F17: 13075700 | G17: 19 | H17: 0 | I17: 1 | J17: 1 | K17: 1 | L17: 1 | M17: =MAX(0,H17-$K17) | N17: =MAX(0,I17-$K17) | O17: =MAX(0,J17-$K17) | P17: =MAX(0,H17-$L17) | Q17: =MAX(0,I17-$L17) | R17: =MAX(0,J17-$L17) | S17: =$F17*H17 | T17: =$F17*I17 | U17: =$F17*J17 | V17: =$F17*M17 | W17: =$F17*N17 | X17: =$F17*O17 | Y17: =$F17*P17 | Z17: =$F17*Q17 | AA17: =$F17*R17 | AB17: =$F17*$G17*$J17 | AC17: =$F17*$G17*MAX(0,$J17-$K17) | AD17: =$F17*$G17*MAX(0,$J17-$L17)
... A43: 38 | B43: Legal & Kepatuhan | C43: Head of Legal & Compliance (merangkap DPO) | D43: Head | E43: 4 | F43: 17462921 | G43: 21 | H43: 0 | I43: 1 | J43: 1 | K43: 0 | L43: 0 | M43: =MAX(0,H43-$K43) | N43: =MAX(0,I43-$K43) | O43: =MAX(0,J43-$K43) | P43: =MAX(0,H43-$L43) | Q43: =MAX(0,I43-$L43) | R43: =MAX(0,J43-$L43) | S43: =$F43*H43 | T43: =$F43*I43 | U43: =$F43*J43 | V43: =$F43*M43 | W43: =$F43*N43 | X43: =$F43*O43 | Y43: =$F43*P43 | Z43: =$F43*Q43 | AA43: =$F43*R43 | AB43: =$F43*$G43*$J43 | AC43: =$F43*$G43*MAX(0,$J43-$K43) | AD43: =$F43*$G43*MAX(0,$J43-$L43)
C44: TOTAL | H44: =SUM(H6:H43) | I44: =SUM(I6:I43) | J44: =SUM(J6:J43) | M44: =SUM(M6:M43) | N44: =SUM(N6:N43) | O44: =SUM(O6:O43) | P44: =SUM(P6:P43) | Q44: =SUM(Q6:Q43) | R44: =SUM(R6:R43) | S44: =SUM(S6:S43) | T44: =SUM(T6:T43) | ... AD44: =SUM(AD6:AD43)
C45: UJI vs model lama (harus 0) | J45: =J44-42 | U45: =U44-636272061.75 | AB45: =AB44-11689208853
A47: PERBANDINGAN TIGA SKENARIO (run-rate per bulan pada akhir tiap fase)
A48: Pos | F48: Fase 0 - A | G48: Fase 0 - B | H48: Fase 0 - C | I48: Fase 1 - A | J48: Fase 1 - B | K48: Fase 1 - C | L48: Fase 2 - A | M48: Fase 2 - B | N48: Fase 2 - C
A49: Jumlah karyawan (headcount) | F49: =H44 | G49: =M44 | H49: =P44 | I49: =I44 | J49: =N44 | K49: =Q44 | L49: =J44 | M49: =O44 | N49: =R44
A50: Biaya SDM per bulan (gaji + iuran + THR), Rp | F50: =S44 | G50: =V44 | H50: =Y44 | I50: =T44 | J50: =W44 | K50: =Z44 | L50: =U44 | M50: =X44 | N50: =AA44
A51: Biaya non-gaji melekat SDM per bulan, Rp (kursi, lisensi dasar, asuransi, pelatihan) | F51: =F49*2150000.000000 | G51: =G49*2150000.000000 | H51: =H49*2150000.000000 | I51: =I49*2000000.000000 | J51: =J49*2000000.000000 | K51: =K49*2000000.000000 | L51: =L49*1864285.714286 | M51: =M49*1864285.714286 | N51: =N49*1864285.714286
A52: Biaya AI per bulan (tool + biaya tersembunyi berulang), Rp | F52: 0 | G52: =AI_B_F0 | H52: =AI_C_F0 | I52: 0 | J52: =AI_B_F1 | K52: =AI_C_F1 | L52: 0 | M52: =AI_B_F2 | N52: =AI_C_F2
A53: TOTAL BIAYA TERKAIT SDM + AI PER BULAN, Rp | F53: =F50+F51+F52 | G53: =G50+G51+G52 | H53: =H50+H51+H52 | I53: =I50+I51+I52 | J53: =J50+J51+J52 | K53: =K50+K51+K52 | L53: =L50+L51+L52 | M53: =M50+M51+M52 | N53: =N50+N51+N52
A54: Penghematan terhadap Skenario A per bulan, Rp (negatif = lebih mahal) | F54: =F53-F53 | G54: =F53-G53 | H54: =F53-H53 | I54: =I53-I53 | J54: =I53-J53 | K54: =I53-K53 | L54: =L53-L53 | M54: =L53-M53 | N54: =L53-N53
A55: Penghematan terhadap Skenario A, % | F55: =IF(F53=0,0,(F53-F53)/F53) | G55: =IF(F53=0,0,(F53-G53)/F53) | H55: =IF(F53=0,0,(F53-H53)/F53) | I55: =IF(I53=0,0,(I53-I53)/I53) | J55: =IF(I53=0,0,(I53-J53)/I53) | K55: =IF(I53=0,0,(I53-K53)/I53) | L55: =IF(L53=0,0,(L53-L53)/L53) | M55: =IF(L53=0,0,(L53-M53)/L53) | N55: =IF(L53=0,0,(L53-N53)/L53)
A56: Pengurangan headcount terhadap Skenario A (orang) | F56: =F49-F49 | G56: =F49-G49 | H56: =F49-H49 | I56: =I49-I49 | J56: =I49-J49 | K56: =I49-K49 | L56: =L49-L49 | M56: =L49-M49 | N56: =L49-N49
A58: Risiko utama tiap skenario
A59: A - Semua manusia | B59: Biaya tetap tertinggi; runway terpendek. Perpres 27/2026 membatasi potongan roda dua 8% [S-25] sehingga pendapatan per order tertekan - struktur biaya ini paling rentan bila likuiditas pasar terlambat terbentuk. Tidak ada risiko baru dari otomasi.
A60: B - Hibrida (REKOMENDASI) | B60: Ketergantungan pada 1 kontraktor pemelihara otomasi; kewajiban baru UU PDP (DPIA, Pasal 10, Pasal 56); mutu jawaban CS turun bila basis pengetahuan tidak dirawat. Pemisahan tugas keuangan TETAP utuh.
A61: C - AI-maksimal | B61: MELANGGAR pemisahan tugas keuangan (Treasury/Settlement dihapus - DESAIN 6 & SOP-07). Kanal darurat 24 jam tidak lagi terjamin (SOP-05). Backend Senior menjadi titik tunggal kegagalan pada modul dompet. Tidak layak diajukan ke uji tuntas investor.

Sheet Perbandingan 24 Bulan
A1: AntarKita - Perbandingan Bulan 1-24: Skenario A / B / C
A2: Aturan aktivasi posisi identik dengan model lama: orang(bulan m) = 0 bila m < Bulan Mulai; selain itu = jumlah orang fase yang berlaku pada bulan m (Fase 0 = bulan 1-3, Fase 1 = bulan 4-12, Fase 2 = bulan 13-24), dikurangi kolom POTONG pada lembar 'Skenario A B C'.
C4: BULAN KE- | D4: 1 | E4: 2 | F4: 3 | G4: 4 | H4: 5 | I4: 6 | J4: 7 | K4: 8 | L4: 9 | M4: 10 | N4: 11 | O4: 12 | P4: 13 | Q4: 14 | R4: 15 | S4: 16 | T4: 17 | U4: 18 | V4: 19 | W4: 20 | X4: 21 | Y4: 22 | Z4: 23 | AA4: 24
A5: Order selesai per hari (jalur pertumbuhan) | B5: [ASUMSI] jalur naik ke 600 pada bulan 12 dan 2.400 pada bulan 24 (target Bab 5) | D5: 0 | E5: 10 | F5: 30 | G5: 60 | H5: 100 | I5: 150 | J5: 210 | K5: 280 | L5: 350 | M5: 430 | N5: 510 | O5: 600 | P5: 700 | Q5: 820 | R5: 950 | S5: 1090 | T5: 1240 | U5: 1400 | V5: 1570 | W5: 1750 | X5: 1940 | Y5: 2100 | Z5: 2250 | AA5: 2400
A6: Order selesai per bulan | D6: =D5*Hari_Bulan | E6: =E5*Hari_Bulan | F6: =F5*Hari_Bulan | G6: =G5*Hari_Bulan | H6: =H5*Hari_Bulan | I6: =I5*Hari_Bulan | J6: =J5*Hari_Bulan | K6: =K5*Hari_Bulan | ... AA6: =AA5*Hari_Bulan
A7: Tiket masuk per bulan | D7: =D6*Tiket_Per1000_Th1/1000 | E7: =E6*Tiket_Per1000_Th1/1000 | F7: =F6*Tiket_Per1000_Th1/1000 | G7: =G6*Tiket_Per1000_Th1/1000 | H7: =H6*Tiket_Per1000_Th1/1000 | I7: =I6*Tiket_Per1000_Th1/1000 | J7: =J6*Tiket_Per1000_Th1/1000 | K7: =K6*Tiket_Per1000_Th1/1000 | ... O7: =O6*Tiket_Per1000_Th1/1000 | P7: =P6*Tiket_Per1000_Th2/1000 | Q7: =Q6*Tiket_Per1000_Th2/1000 | R7: =R6*Tiket_Per1000_Th2/1000 | S7: =S6*Tiket_Per1000_Th2/1000 | T7: =T6*Tiket_Per1000_Th2/1000 | U7: =U6*Tiket_Per1000_Th2/1000 | V7: =V6*Tiket_Per1000_Th2/1000 | W7: =W6*Tiket_Per1000_Th2/1000 | ... AA7: =AA6*Tiket_Per1000_Th2/1000
A9: A. JUMLAH ORANG AKTIF PER BULAN - SKENARIO A (semua manusia)
A10: Direktur Utama (CEO) | B10: ='Skenario A B C'!$F$6 | D10: =IF(1<'Skenario A B C'!$E$6,0,MAX(0,'Skenario A B C'!$H$6-'Skenario A B C'!$AE$6)) | E10: =IF(2<'Skenario A B C'!$E$6,0,MAX(0,'Skenario A B C'!$H$6-'Skenario A B C'!$AE$6)) | F10: =IF(3<'Skenario A B C'!$E$6,0,MAX(0,'Skenario A B C'!$H$6-'Skenario A B C'!$AE$6)) | G10: =IF(4<'Skenario A B C'!$E$6,0,MAX(0,'Skenario A B C'!$I$6-'Skenario A B C'!$AE$6)) | H10: =IF(5<'Skenario A B C'!$E$6,0,MAX(0,'Skenario A B C'!$I$6-'Skenario A B C'!$AE$6)) | I10: =IF(6<'Skenario A B C'!$E$6,0,MAX(0,'Skenario A B C'!$I$6-'Skenario A B C'!$AE$6)) | J10: =IF(7<'Skenario A B C'!$E$6,0,MAX(0,'Skenario A B C'!$I$6-'Skenario A B C'!$AE$6)) | K10: =IF(8<'Skenario A B C'!$E$6,0,MAX(0,'Skenario A B C'!$I$6-'Skenario A B C'!$AE$6)) | L10: =IF(9<'Skenario A B C'!$E$6,0,MAX(0,'Skenario A B C'!$I$6-'Skenario A B C'!$AE$6)) | M10: =IF(10<'Skenario A B C'!$E$6,0,MAX(0,'Skenario A B C'!$I$6-'Skenario A B C'!$AE$6)) | N10: =IF(11<'Skenario A B C'!$E$6,0,MAX(0,'Skenario A B C'!$I$6-'Skenario A B C'!$AE$6)) | O10: =IF(12<'Skenario A B C'!$E$6,0,MAX(0,'Skenario A B C'!$I$6-'Skenario A B C'!$AE$6)) | P10: =IF(13<'Skenario A B C'!$E$6,0,MAX(0,'Skenario A B C'!$J$6-'Skenario A B C'!$AE$6)) | Q10: =IF(14<'Skenario A B C'!$E$6,0,MAX(0,'Skenario A B C'!$J$6-'Skenario A B C'!$AE$6)) | R10: =IF(15<'Skenario A B C'!$E$6,0,MAX(0,'Skenario A B C'!$J$6-'Skenario A B C'!$AE$6)) | S10: =IF(16<'Skenario A B C'!$E$6,0,MAX(0,'Skenario A B C'!$J$6-'Skenario A B C'!$AE$6)) | T10: =IF(17<'Skenario A B C'!$E$6,0,MAX(0,'Skenario A B C'!$J$6-'Skenario A B C'!$AE$6)) | U10: =IF(18<'Skenario A B C'!$E$6,0,MAX(0,'Skenario A B C'!$J$6-'Skenario A B C'!$AE$6)) | V10: =IF(19<'Skenario A B C'!$E$6,0,MAX(0,'Skenario A B C'!$J$6-'Skenario A B C'!$AE$6)) | W10: =IF(20<'Skenario A B C'!$E$6,0,MAX(0,'Skenario A B C'!$J$6-'Skenario A B C'!$AE$6)) | X10: =IF(21<'Skenario A B C'!$E$6,0,MAX(0,'Skenario A B C'!$J$6-'Skenario A B C'!$AE$6)) | Y10: =IF(22<'Skenario A B C'!$E$6,0,MAX(0,'Skenario A B C'!$J$6-'Skenario A B C'!$AE$6)) | Z10: =IF(23<'Skenario A B C'!$E$6,0,MAX(0,'Skenario A B C'!$J$6-'Skenario A B C'!$AE$6)) | AA10: =IF(24<'Skenario A B C'!$E$6,0,MAX(0,'Skenario A B C'!$J$6-'Skenario A B C'!$AE$6))
A11: HR & GA Generalist | B11: ='Skenario A B C'!$F$7 | D11: =IF(1<'Skenario A B C'!$E$7,0,MAX(0,'Skenario A B C'!$H$7-'Skenario A B C'!$AE$7)) | E11: =IF(2<'Skenario A B C'!$E$7,0,MAX(0,'Skenario A B C'!$H$7-'Skenario A B C'!$AE$7)) | F11: =IF(3<'Skenario A B C'!$E$7,0,MAX(0,'Skenario A B C'!$H$7-'Skenario A B C'!$AE$7)) | G11: =IF(4<'Skenario A B C'!$E$7,0,MAX(0,'Skenario A B C'!$I$7-'Skenario A B C'!$AE$7)) | H11: =IF(5<'Skenario A B C'!$E$7,0,MAX(0,'Skenario A B C'!$I$7-'Skenario A B C'!$AE$7)) | I11: =IF(6<'Skenario A B C'!$E$7,0,MAX(0,'Skenario A B C'!$I$7-'Skenario A B C'!$AE$7)) | J11: =IF(7<'Skenario A B C'!$E$7,0,MAX(0,'Skenario A B C'!$I$7-'Skenario A B C'!$AE$7)) | K11: =IF(8<'Skenario A B C'!$E$7,0,MAX(0,'Skenario A B C'!$I$7-'Skenario A B C'!$AE$7)) | L11: =IF(9<'Skenario A B C'!$E$7,0,MAX(0,'Skenario A B C'!$I$7-'Skenario A B C'!$AE$7)) | M11: =IF(10<'Skenario A B C'!$E$7,0,MAX(0,'Skenario A B C'!$I$7-'Skenario A B C'!$AE$7)) | N11: =IF(11<'Skenario A B C'!$E$7,0,MAX(0,'Skenario A B C'!$I$7-'Skenario A B C'!$AE$7)) | O11: =IF(12<'Skenario A B C'!$E$7,0,MAX(0,'Skenario A B C'!$I$7-'Skenario A B C'!$AE$7)) | P11: =IF(13<'Skenario A B C'!$E$7,0,MAX(0,'Skenario A B C'!$J$7-'Skenario A B C'!$AE$7)) | Q11: =IF(14<'Skenario A B C'!$E$7,0,MAX(0,'Skenario A B C'!$J$7-'Skenario A B C'!$AE$7)) | R11: =IF(15<'Skenario A B C'!$E$7,0,MAX(0,'Skenario A B C'!$J$7-'Skenario A B C'!$AE$7)) | S11: =IF(16<'Skenario A B C'!$E$7,0,MAX(0,'Skenario A B C'!$J$7-'Skenario A B C'!$AE$7)) | T11: =IF(17<'Skenario A B C'!$E$7,0,MAX(0,'Skenario A B C'!$J$7-'Skenario A B C'!$AE$7)) | U11: =IF(18<'Skenario A B C'!$E$7,0,MAX(0,'Skenario A B C'!$J$7-'Skenario A B C'!$AE$7)) | V11: =IF(19<'Skenario A B C'!$E$7,0,MAX(0,'Skenario A B C'!$J$7-'Skenario A B C'!$AE$7)) | W11: =IF(20<'Skenario A B C'!$E$7,0,MAX(0,'Skenario A B C'!$J$7-'Skenario A B C'!$AE$7)) | X11: =IF(21<'Skenario A B C'!$E$7,0,MAX(0,'Skenario A B C'!$J$7-'Skenario A B C'!$AE$7)) | Y11: =IF(22<'Skenario A B C'!$E$7,0,MAX(0,'Skenario A B C'!$J$7-'Skenario A B C'!$AE$7)) | Z11: =IF(23<'Skenario A B C'!$E$7,0,MAX(0,'Skenario A B C'!$J$7-'Skenario A B C'!$AE$7)) | AA11: =IF(24<'Skenario A B C'!$E$7,0,MAX(0,'Skenario A B C'!$J$7-'Skenario A B C'!$AE$7))
A12: Direktur Teknologi (CTO) | B12: ='Skenario A B C'!$F$8 | D12: =IF(1<'Skenario A B C'!$E$8,0,MAX(0,'Skenario A B C'!$H$8-'Skenario A B C'!$AE$8)) | E12: =IF(2<'Skenario A B C'!$E$8,0,MAX(0,'Skenario A B C'!$H$8-'Skenario A B C'!$AE$8)) | F12: =IF(3<'Skenario A B C'!$E$8,0,MAX(0,'Skenario A B C'!$H$8-'Skenario A B C'!$AE$8)) | G12: =IF(4<'Skenario A B C'!$E$8,0,MAX(0,'Skenario A B C'!$I$8-'Skenario A B C'!$AE$8)) | H12: =IF(5<'Skenario A B C'!$E$8,0,MAX(0,'Skenario A B C'!$I$8-'Skenario A B C'!$AE$8)) | I12: =IF(6<'Skenario A B C'!$E$8,0,MAX(0,'Skenario A B C'!$I$8-'Skenario A B C'!$AE$8)) | J12: =IF(7<'Skenario A B C'!$E$8,0,MAX(0,'Skenario A B C'!$I$8-'Skenario A B C'!$AE$8)) | K12: =IF(8<'Skenario A B C'!$E$8,0,MAX(0,'Skenario A B C'!$I$8-'Skenario A B C'!$AE$8)) | L12: =IF(9<'Skenario A B C'!$E$8,0,MAX(0,'Skenario A B C'!$I$8-'Skenario A B C'!$AE$8)) | M12: =IF(10<'Skenario A B C'!$E$8,0,MAX(0,'Skenario A B C'!$I$8-'Skenario A B C'!$AE$8)) | N12: =IF(11<'Skenario A B C'!$E$8,0,MAX(0,'Skenario A B C'!$I$8-'Skenario A B C'!$AE$8)) | O12: =IF(12<'Skenario A B C'!$E$8,0,MAX(0,'Skenario A B C'!$I$8-'Skenario A B C'!$AE$8)) | P12: =IF(13<'Skenario A B C'!$E$8,0,MAX(0,'Skenario A B C'!$J$8-'Skenario A B C'!$AE$8)) | Q12: =IF(14<'Skenario A B C'!$E$8,0,MAX(0,'Skenario A B C'!$J$8-'Skenario A B C'!$AE$8)) | R12: =IF(15<'Skenario A B C'!$E$8,0,MAX(0,'Skenario A B C'!$J$8-'Skenario A B C'!$AE$8)) | S12: =IF(16<'Skenario A B C'!$E$8,0,MAX(0,'Skenario A B C'!$J$8-'Skenario A B C'!$AE$8)) | T12: =IF(17<'Skenario A B C'!$E$8,0,MAX(0,'Skenario A B C'!$J$8-'Skenario A B C'!$AE$8)) | U12: =IF(18<'Skenario A B C'!$E$8,0,MAX(0,'Skenario A B C'!$J$8-'Skenario A B C'!$AE$8)) | V12: =IF(19<'Skenario A B C'!$E$8,0,MAX(0,'Skenario A B C'!$J$8-'Skenario A B C'!$AE$8)) | W12: =IF(20<'Skenario A B C'!$E$8,0,MAX(0,'Skenario A B C'!$J$8-'Skenario A B C'!$AE$8)) | X12: =IF(21<'Skenario A B C'!$E$8,0,MAX(0,'Skenario A B C'!$J$8-'Skenario A B C'!$AE$8)) | Y12: =IF(22<'Skenario A B C'!$E$8,0,MAX(0,'Skenario A B C'!$J$8-'Skenario A B C'!$AE$8)) | Z12: =IF(23<'Skenario A B C'!$E$8,0,MAX(0,'Skenario A B C'!$J$8-'Skenario A B C'!$AE$8)) | AA12: =IF(24<'Skenario A B C'!$E$8,0,MAX(0,'Skenario A B C'!$J$8-'Skenario A B C'!$AE$8))
A13: Engineering Manager | B13: ='Skenario A B C'!$F$9 | D13: =IF(1<'Skenario A B C'!$E$9,0,MAX(0,'Skenario A B C'!$H$9-'Skenario A B C'!$AE$9)) | E13: =IF(2<'Skenario A B C'!$E$9,0,MAX(0,'Skenario A B C'!$H$9-'Skenario A B C'!$AE$9)) | F13: =IF(3<'Skenario A B C'!$E$9,0,MAX(0,'Skenario A B C'!$H$9-'Skenario A B C'!$AE$9)) | G13: =IF(4<'Skenario A B C'!$E$9,0,MAX(0,'Skenario A B C'!$I$9-'Skenario A B C'!$AE$9)) | H13: =IF(5<'Skenario A B C'!$E$9,0,MAX(0,'Skenario A B C'!$I$9-'Skenario A B C'!$AE$9)) | I13: =IF(6<'Skenario A B C'!$E$9,0,MAX(0,'Skenario A B C'!$I$9-'Skenario A B C'!$AE$9)) | J13: =IF(7<'Skenario A B C'!$E$9,0,MAX(0,'Skenario A B C'!$I$9-'Skenario A B C'!$AE$9)) | K13: =IF(8<'Skenario A B C'!$E$9,0,MAX(0,'Skenario A B C'!$I$9-'Skenario A B C'!$AE$9)) | L13: =IF(9<'Skenario A B C'!$E$9,0,MAX(0,'Skenario A B C'!$I$9-'Skenario A B C'!$AE$9)) | M13: =IF(10<'Skenario A B C'!$E$9,0,MAX(0,'Skenario A B C'!$I$9-'Skenario A B C'!$AE$9)) | N13: =IF(11<'Skenario A B C'!$E$9,0,MAX(0,'Skenario A B C'!$I$9-'Skenario A B C'!$AE$9)) | O13: =IF(12<'Skenario A B C'!$E$9,0,MAX(0,'Skenario A B C'!$I$9-'Skenario A B C'!$AE$9)) | P13: =IF(13<'Skenario A B C'!$E$9,0,MAX(0,'Skenario A B C'!$J$9-'Skenario A B C'!$AE$9)) | Q13: =IF(14<'Skenario A B C'!$E$9,0,MAX(0,'Skenario A B C'!$J$9-'Skenario A B C'!$AE$9)) | R13: =IF(15<'Skenario A B C'!$E$9,0,MAX(0,'Skenario A B C'!$J$9-'Skenario A B C'!$AE$9)) | S13: =IF(16<'Skenario A B C'!$E$9,0,MAX(0,'Skenario A B C'!$J$9-'Skenario A B C'!$AE$9)) | T13: =IF(17<'Skenario A B C'!$E$9,0,MAX(0,'Skenario A B C'!$J$9-'Skenario A B C'!$AE$9)) | U13: =IF(18<'Skenario A B C'!$E$9,0,MAX(0,'Skenario A B C'!$J$9-'Skenario A B C'!$AE$9)) | V13: =IF(19<'Skenario A B C'!$E$9,0,MAX(0,'Skenario A B C'!$J$9-'Skenario A B C'!$AE$9)) | W13: =IF(20<'Skenario A B C'!$E$9,0,MAX(0,'Skenario A B C'!$J$9-'Skenario A B C'!$AE$9)) | X13: =IF(21<'Skenario A B C'!$E$9,0,MAX(0,'Skenario A B C'!$J$9-'Skenario A B C'!$AE$9)) | Y13: =IF(22<'Skenario A B C'!$E$9,0,MAX(0,'Skenario A B C'!$J$9-'Skenario A B C'!$AE$9)) | Z13: =IF(23<'Skenario A B C'!$E$9,0,MAX(0,'Skenario A B C'!$J$9-'Skenario A B C'!$AE$9)) | AA13: =IF(24<'Skenario A B C'!$E$9,0,MAX(0,'Skenario A B C'!$J$9-'Skenario A B C'!$AE$9))
A14: Mobile Engineer (Senior) | B14: ='Skenario A B C'!$F$10 | D14: =IF(1<'Skenario A B C'!$E$10,0,MAX(0,'Skenario A B C'!$H$10-'Skenario A B C'!$AE$10)) | E14: =IF(2<'Skenario A B C'!$E$10,0,MAX(0,'Skenario A B C'!$H$10-'Skenario A B C'!$AE$10)) | F14: =IF(3<'Skenario A B C'!$E$10,0,MAX(0,'Skenario A B C'!$H$10-'Skenario A B C'!$AE$10)) | G14: =IF(4<'Skenario A B C'!$E$10,0,MAX(0,'Skenario A B C'!$I$10-'Skenario A B C'!$AE$10)) | H14: =IF(5<'Skenario A B C'!$E$10,0,MAX(0,'Skenario A B C'!$I$10-'Skenario A B C'!$AE$10)) | I14: =IF(6<'Skenario A B C'!$E$10,0,MAX(0,'Skenario A B C'!$I$10-'Skenario A B C'!$AE$10)) | J14: =IF(7<'Skenario A B C'!$E$10,0,MAX(0,'Skenario A B C'!$I$10-'Skenario A B C'!$AE$10)) | K14: =IF(8<'Skenario A B C'!$E$10,0,MAX(0,'Skenario A B C'!$I$10-'Skenario A B C'!$AE$10)) | L14: =IF(9<'Skenario A B C'!$E$10,0,MAX(0,'Skenario A B C'!$I$10-'Skenario A B C'!$AE$10)) | M14: =IF(10<'Skenario A B C'!$E$10,0,MAX(0,'Skenario A B C'!$I$10-'Skenario A B C'!$AE$10)) | N14: =IF(11<'Skenario A B C'!$E$10,0,MAX(0,'Skenario A B C'!$I$10-'Skenario A B C'!$AE$10)) | O14: =IF(12<'Skenario A B C'!$E$10,0,MAX(0,'Skenario A B C'!$I$10-'Skenario A B C'!$AE$10)) | P14: =IF(13<'Skenario A B C'!$E$10,0,MAX(0,'Skenario A B C'!$J$10-'Skenario A B C'!$AE$10)) | Q14: =IF(14<'Skenario A B C'!$E$10,0,MAX(0,'Skenario A B C'!$J$10-'Skenario A B C'!$AE$10)) | R14: =IF(15<'Skenario A B C'!$E$10,0,MAX(0,'Skenario A B C'!$J$10-'Skenario A B C'!$AE$10)) | S14: =IF(16<'Skenario A B C'!$E$10,0,MAX(0,'Skenario A B C'!$J$10-'Skenario A B C'!$AE$10)) | T14: =IF(17<'Skenario A B C'!$E$10,0,MAX(0,'Skenario A B C'!$J$10-'Skenario A B C'!$AE$10)) | U14: =IF(18<'Skenario A B C'!$E$10,0,MAX(0,'Skenario A B C'!$J$10-'Skenario A B C'!$AE$10)) | V14: =IF(19<'Skenario A B C'!$E$10,0,MAX(0,'Skenario A B C'!$J$10-'Skenario A B C'!$AE$10)) | W14: =IF(20<'Skenario A B C'!$E$10,0,MAX(0,'Skenario A B C'!$J$10-'Skenario A B C'!$AE$10)) | X14: =IF(21<'Skenario A B C'!$E$10,0,MAX(0,'Skenario A B C'!$J$10-'Skenario A B C'!$AE$10)) | Y14: =IF(22<'Skenario A B C'!$E$10,0,MAX(0,'Skenario A B C'!$J$10-'Skenario A B C'!$AE$10)) | Z14: =IF(23<'Skenario A B C'!$E$10,0,MAX(0,'Skenario A B C'!$J$10-'Skenario A B C'!$AE$10)) | AA14: =IF(24<'Skenario A B C'!$E$10,0,MAX(0,'Skenario A B C'!$J$10-'Skenario A B C'!$AE$10))
A15: Mobile Engineer (Mid) | B15: ='Skenario A B C'!$F$11 | D15: =IF(1<'Skenario A B C'!$E$11,0,MAX(0,'Skenario A B C'!$H$11-'Skenario A B C'!$AE$11)) | E15: =IF(2<'Skenario A B C'!$E$11,0,MAX(0,'Skenario A B C'!$H$11-'Skenario A B C'!$AE$11)) | F15: =IF(3<'Skenario A B C'!$E$11,0,MAX(0,'Skenario A B C'!$H$11-'Skenario A B C'!$AE$11)) | G15: =IF(4<'Skenario A B C'!$E$11,0,MAX(0,'Skenario A B C'!$I$11-'Skenario A B C'!$AE$11)) | H15: =IF(5<'Skenario A B C'!$E$11,0,MAX(0,'Skenario A B C'!$I$11-'Skenario A B C'!$AE$11)) | I15: =IF(6<'Skenario A B C'!$E$11,0,MAX(0,'Skenario A B C'!$I$11-'Skenario A B C'!$AE$11)) | J15: =IF(7<'Skenario A B C'!$E$11,0,MAX(0,'Skenario A B C'!$I$11-'Skenario A B C'!$AE$11)) | K15: =IF(8<'Skenario A B C'!$E$11,0,MAX(0,'Skenario A B C'!$I$11-'Skenario A B C'!$AE$11)) | L15: =IF(9<'Skenario A B C'!$E$11,0,MAX(0,'Skenario A B C'!$I$11-'Skenario A B C'!$AE$11)) | M15: =IF(10<'Skenario A B C'!$E$11,0,MAX(0,'Skenario A B C'!$I$11-'Skenario A B C'!$AE$11)) | N15: =IF(11<'Skenario A B C'!$E$11,0,MAX(0,'Skenario A B C'!$I$11-'Skenario A B C'!$AE$11)) | O15: =IF(12<'Skenario A B C'!$E$11,0,MAX(0,'Skenario A B C'!$I$11-'Skenario A B C'!$AE$11)) | P15: =IF(13<'Skenario A B C'!$E$11,0,MAX(0,'Skenario A B C'!$J$11-'Skenario A B C'!$AE$11)) | Q15: =IF(14<'Skenario A B C'!$E$11,0,MAX(0,'Skenario A B C'!$J$11-'Skenario A B C'!$AE$11)) | R15: =IF(15<'Skenario A B C'!$E$11,0,MAX(0,'Skenario A B C'!$J$11-'Skenario A B C'!$AE$11)) | S15: =IF(16<'Skenario A B C'!$E$11,0,MAX(0,'Skenario A B C'!$J$11-'Skenario A B C'!$AE$11)) | T15: =IF(17<'Skenario A B C'!$E$11,0,MAX(0,'Skenario A B C'!$J$11-'Skenario A B C'!$AE$11)) | U15: =IF(18<'Skenario A B C'!$E$11,0,MAX(0,'Skenario A B C'!$J$11-'Skenario A B C'!$AE$11)) | V15: =IF(19<'Skenario A B C'!$E$11,0,MAX(0,'Skenario A B C'!$J$11-'Skenario A B C'!$AE$11)) | W15: =IF(20<'Skenario A B C'!$E$11,0,MAX(0,'Skenario A B C'!$J$11-'Skenario A B C'!$AE$11)) | X15: =IF(21<'Skenario A B C'!$E$11,0,MAX(0,'Skenario A B C'!$J$11-'Skenario A B C'!$AE$11)) | Y15: =IF(22<'Skenario A B C'!$E$11,0,MAX(0,'Skenario A B C'!$J$11-'Skenario A B C'!$AE$11)) | Z15: =IF(23<'Skenario A B C'!$E$11,0,MAX(0,'Skenario A B C'!$J$11-'Skenario A B C'!$AE$11)) | AA15: =IF(24<'Skenario A B C'!$E$11,0,MAX(0,'Skenario A B C'!$J$11-'Skenario A B C'!$AE$11))
A16: Mobile Engineer (Mid) - gelombang 2 | B16: ='Skenario A B C'!$F$12 | D16: =IF(1<'Skenario A B C'!$E$12,0,MAX(0,'Skenario A B C'!$H$12-'Skenario A B C'!$AE$12)) | E16: =IF(2<'Skenario A B C'!$E$12,0,MAX(0,'Skenario A B C'!$H$12-'Skenario A B C'!$AE$12)) | F16: =IF(3<'Skenario A B C'!$E$12,0,MAX(0,'Skenario A B C'!$H$12-'Skenario A B C'!$AE$12)) | G16: =IF(4<'Skenario A B C'!$E$12,0,MAX(0,'Skenario A B C'!$I$12-'Skenario A B C'!$AE$12)) | H16: =IF(5<'Skenario A B C'!$E$12,0,MAX(0,'Skenario A B C'!$I$12-'Skenario A B C'!$AE$12)) | I16: =IF(6<'Skenario A B C'!$E$12,0,MAX(0,'Skenario A B C'!$I$12-'Skenario A B C'!$AE$12)) | J16: =IF(7<'Skenario A B C'!$E$12,0,MAX(0,'Skenario A B C'!$I$12-'Skenario A B C'!$AE$12)) | K16: =IF(8<'Skenario A B C'!$E$12,0,MAX(0,'Skenario A B C'!$I$12-'Skenario A B C'!$AE$12)) | L16: =IF(9<'Skenario A B C'!$E$12,0,MAX(0,'Skenario A B C'!$I$12-'Skenario A B C'!$AE$12)) | M16: =IF(10<'Skenario A B C'!$E$12,0,MAX(0,'Skenario A B C'!$I$12-'Skenario A B C'!$AE$12)) | N16: =IF(11<'Skenario A B C'!$E$12,0,MAX(0,'Skenario A B C'!$I$12-'Skenario A B C'!$AE$12)) | O16: =IF(12<'Skenario A B C'!$E$12,0,MAX(0,'Skenario A B C'!$I$12-'Skenario A B C'!$AE$12)) | P16: =IF(13<'Skenario A B C'!$E$12,0,MAX(0,'Skenario A B C'!$J$12-'Skenario A B C'!$AE$12)) | Q16: =IF(14<'Skenario A B C'!$E$12,0,MAX(0,'Skenario A B C'!$J$12-'Skenario A B C'!$AE$12)) | R16: =IF(15<'Skenario A B C'!$E$12,0,MAX(0,'Skenario A B C'!$J$12-'Skenario A B C'!$AE$12)) | S16: =IF(16<'Skenario A B C'!$E$12,0,MAX(0,'Skenario A B C'!$J$12-'Skenario A B C'!$AE$12)) | T16: =IF(17<'Skenario A B C'!$E$12,0,MAX(0,'Skenario A B C'!$J$12-'Skenario A B C'!$AE$12)) | U16: =IF(18<'Skenario A B C'!$E$12,0,MAX(0,'Skenario A B C'!$J$12-'Skenario A B C'!$AE$12)) | V16: =IF(19<'Skenario A B C'!$E$12,0,MAX(0,'Skenario A B C'!$J$12-'Skenario A B C'!$AE$12)) | W16: =IF(20<'Skenario A B C'!$E$12,0,MAX(0,'Skenario A B C'!$J$12-'Skenario A B C'!$AE$12)) | X16: =IF(21<'Skenario A B C'!$E$12,0,MAX(0,'Skenario A B C'!$J$12-'Skenario A B C'!$AE$12)) | Y16: =IF(22<'Skenario A B C'!$E$12,0,MAX(0,'Skenario A B C'!$J$12-'Skenario A B C'!$AE$12)) | Z16: =IF(23<'Skenario A B C'!$E$12,0,MAX(0,'Skenario A B C'!$J$12-'Skenario A B C'!$AE$12)) | AA16: =IF(24<'Skenario A B C'!$E$12,0,MAX(0,'Skenario A B C'!$J$12-'Skenario A B C'!$AE$12))
A17: Backend Engineer (Senior) | B17: ='Skenario A B C'!$F$13 | D17: =IF(1<'Skenario A B C'!$E$13,0,MAX(0,'Skenario A B C'!$H$13-'Skenario A B C'!$AE$13)) | E17: =IF(2<'Skenario A B C'!$E$13,0,MAX(0,'Skenario A B C'!$H$13-'Skenario A B C'!$AE$13)) | F17: =IF(3<'Skenario A B C'!$E$13,0,MAX(0,'Skenario A B C'!$H$13-'Skenario A B C'!$AE$13)) | G17: =IF(4<'Skenario A B C'!$E$13,0,MAX(0,'Skenario A B C'!$I$13-'Skenario A B C'!$AE$13)) | H17: =IF(5<'Skenario A B C'!$E$13,0,MAX(0,'Skenario A B C'!$I$13-'Skenario A B C'!$AE$13)) | I17: =IF(6<'Skenario A B C'!$E$13,0,MAX(0,'Skenario A B C'!$I$13-'Skenario A B C'!$AE$13)) | J17: =IF(7<'Skenario A B C'!$E$13,0,MAX(0,'Skenario A B C'!$I$13-'Skenario A B C'!$AE$13)) | K17: =IF(8<'Skenario A B C'!$E$13,0,MAX(0,'Skenario A B C'!$I$13-'Skenario A B C'!$AE$13)) | L17: =IF(9<'Skenario A B C'!$E$13,0,MAX(0,'Skenario A B C'!$I$13-'Skenario A B C'!$AE$13)) | M17: =IF(10<'Skenario A B C'!$E$13,0,MAX(0,'Skenario A B C'!$I$13-'Skenario A B C'!$AE$13)) | N17: =IF(11<'Skenario A B C'!$E$13,0,MAX(0,'Skenario A B C'!$I$13-'Skenario A B C'!$AE$13)) | O17: =IF(12<'Skenario A B C'!$E$13,0,MAX(0,'Skenario A B C'!$I$13-'Skenario A B C'!$AE$13)) | P17: =IF(13<'Skenario A B C'!$E$13,0,MAX(0,'Skenario A B C'!$J$13-'Skenario A B C'!$AE$13)) | Q17: =IF(14<'Skenario A B C'!$E$13,0,MAX(0,'Skenario A B C'!$J$13-'Skenario A B C'!$AE$13)) | R17: =IF(15<'Skenario A B C'!$E$13,0,MAX(0,'Skenario A B C'!$J$13-'Skenario A B C'!$AE$13)) | S17: =IF(16<'Skenario A B C'!$E$13,0,MAX(0,'Skenario A B C'!$J$13-'Skenario A B C'!$AE$13)) | T17: =IF(17<'Skenario A B C'!$E$13,0,MAX(0,'Skenario A B C'!$J$13-'Skenario A B C'!$AE$13)) | U17: =IF(18<'Skenario A B C'!$E$13,0,MAX(0,'Skenario A B C'!$J$13-'Skenario A B C'!$AE$13)) | V17: =IF(19<'Skenario A B C'!$E$13,0,MAX(0,'Skenario A B C'!$J$13-'Skenario A B C'!$AE$13)) | W17: =IF(20<'Skenario A B C'!$E$13,0,MAX(0,'Skenario A B C'!$J$13-'Skenario A B C'!$AE$13)) | X17: =IF(21<'Skenario A B C'!$E$13,0,MAX(0,'Skenario A B C'!$J$13-'Skenario A B C'!$AE$13)) | Y17: =IF(22<'Skenario A B C'!$E$13,0,MAX(0,'Skenario A B C'!$J$13-'Skenario A B C'!$AE$13)) | Z17: =IF(23<'Skenario A B C'!$E$13,0,MAX(0,'Skenario A B C'!$J$13-'Skenario A B C'!$AE$13)) | AA17: =IF(24<'Skenario A B C'!$E$13,0,MAX(0,'Skenario A B C'!$J$13-'Skenario A B C'!$AE$13))
A18: Backend Engineer (Senior) - gelombang 2 | B18: ='Skenario A B C'!$F$14 | D18: =IF(1<'Skenario A B C'!$E$14,0,MAX(0,'Skenario A B C'!$H$14-'Skenario A B C'!$AE$14)) | E18: =IF(2<'Skenario A B C'!$E$14,0,MAX(0,'Skenario A B C'!$H$14-'Skenario A B C'!$AE$14)) | F18: =IF(3<'Skenario A B C'!$E$14,0,MAX(0,'Skenario A B C'!$H$14-'Skenario A B C'!$AE$14)) | G18: =IF(4<'Skenario A B C'!$E$14,0,MAX(0,'Skenario A B C'!$I$14-'Skenario A B C'!$AE$14)) | H18: =IF(5<'Skenario A B C'!$E$14,0,MAX(0,'Skenario A B C'!$I$14-'Skenario A B C'!$AE$14)) | I18: =IF(6<'Skenario A B C'!$E$14,0,MAX(0,'Skenario A B C'!$I$14-'Skenario A B C'!$AE$14)) | J18: =IF(7<'Skenario A B C'!$E$14,0,MAX(0,'Skenario A B C'!$I$14-'Skenario A B C'!$AE$14)) | K18: =IF(8<'Skenario A B C'!$E$14,0,MAX(0,'Skenario A B C'!$I$14-'Skenario A B C'!$AE$14)) | L18: =IF(9<'Skenario A B C'!$E$14,0,MAX(0,'Skenario A B C'!$I$14-'Skenario A B C'!$AE$14)) | M18: =IF(10<'Skenario A B C'!$E$14,0,MAX(0,'Skenario A B C'!$I$14-'Skenario A B C'!$AE$14)) | N18: =IF(11<'Skenario A B C'!$E$14,0,MAX(0,'Skenario A B C'!$I$14-'Skenario A B C'!$AE$14)) | O18: =IF(12<'Skenario A B C'!$E$14,0,MAX(0,'Skenario A B C'!$I$14-'Skenario A B C'!$AE$14)) | P18: =IF(13<'Skenario A B C'!$E$14,0,MAX(0,'Skenario A B C'!$J$14-'Skenario A B C'!$AE$14)) | Q18: =IF(14<'Skenario A B C'!$E$14,0,MAX(0,'Skenario A B C'!$J$14-'Skenario A B C'!$AE$14)) | R18: =IF(15<'Skenario A B C'!$E$14,0,MAX(0,'Skenario A B C'!$J$14-'Skenario A B C'!$AE$14)) | S18: =IF(16<'Skenario A B C'!$E$14,0,MAX(0,'Skenario A B C'!$J$14-'Skenario A B C'!$AE$14)) | T18: =IF(17<'Skenario A B C'!$E$14,0,MAX(0,'Skenario A B C'!$J$14-'Skenario A B C'!$AE$14)) | U18: =IF(18<'Skenario A B C'!$E$14,0,MAX(0,'Skenario A B C'!$J$14-'Skenario A B C'!$AE$14)) | V18: =IF(19<'Skenario A B C'!$E$14,0,MAX(0,'Skenario A B C'!$J$14-'Skenario A B C'!$AE$14)) | W18: =IF(20<'Skenario A B C'!$E$14,0,MAX(0,'Skenario A B C'!$J$14-'Skenario A B C'!$AE$14)) | X18: =IF(21<'Skenario A B C'!$E$14,0,MAX(0,'Skenario A B C'!$J$14-'Skenario A B C'!$AE$14)) | Y18: =IF(22<'Skenario A B C'!$E$14,0,MAX(0,'Skenario A B C'!$J$14-'Skenario A B C'!$AE$14)) | Z18: =IF(23<'Skenario A B C'!$E$14,0,MAX(0,'Skenario A B C'!$J$14-'Skenario A B C'!$AE$14)) | AA18: =IF(24<'Skenario A B C'!$E$14,0,MAX(0,'Skenario A B C'!$J$14-'Skenario A B C'!$AE$14))
A19: Backend Engineer (Mid) | B19: ='Skenario A B C'!$F$15 | D19: =IF(1<'Skenario A B C'!$E$15,0,MAX(0,'Skenario A B C'!$H$15-'Skenario A B C'!$AE$15)) | E19: =IF(2<'Skenario A B C'!$E$15,0,MAX(0,'Skenario A B C'!$H$15-'Skenario A B C'!$AE$15)) | F19: =IF(3<'Skenario A B C'!$E$15,0,MAX(0,'Skenario A B C'!$H$15-'Skenario A B C'!$AE$15)) | G19: =IF(4<'Skenario A B C'!$E$15,0,MAX(0,'Skenario A B C'!$I$15-'Skenario A B C'!$AE$15)) | H19: =IF(5<'Skenario A B C'!$E$15,0,MAX(0,'Skenario A B C'!$I$15-'Skenario A B C'!$AE$15)) | I19: =IF(6<'Skenario A B C'!$E$15,0,MAX(0,'Skenario A B C'!$I$15-'Skenario A B C'!$AE$15)) | J19: =IF(7<'Skenario A B C'!$E$15,0,MAX(0,'Skenario A B C'!$I$15-'Skenario A B C'!$AE$15)) | K19: =IF(8<'Skenario A B C'!$E$15,0,MAX(0,'Skenario A B C'!$I$15-'Skenario A B C'!$AE$15)) | L19: =IF(9<'Skenario A B C'!$E$15,0,MAX(0,'Skenario A B C'!$I$15-'Skenario A B C'!$AE$15)) | M19: =IF(10<'Skenario A B C'!$E$15,0,MAX(0,'Skenario A B C'!$I$15-'Skenario A B C'!$AE$15)) | N19: =IF(11<'Skenario A B C'!$E$15,0,MAX(0,'Skenario A B C'!$I$15-'Skenario A B C'!$AE$15)) | O19: =IF(12<'Skenario A B C'!$E$15,0,MAX(0,'Skenario A B C'!$I$15-'Skenario A B C'!$AE$15)) | P19: =IF(13<'Skenario A B C'!$E$15,0,MAX(0,'Skenario A B C'!$J$15-'Skenario A B C'!$AE$15)) | Q19: =IF(14<'Skenario A B C'!$E$15,0,MAX(0,'Skenario A B C'!$J$15-'Skenario A B C'!$AE$15)) | R19: =IF(15<'Skenario A B C'!$E$15,0,MAX(0,'Skenario A B C'!$J$15-'Skenario A B C'!$AE$15)) | S19: =IF(16<'Skenario A B C'!$E$15,0,MAX(0,'Skenario A B C'!$J$15-'Skenario A B C'!$AE$15)) | T19: =IF(17<'Skenario A B C'!$E$15,0,MAX(0,'Skenario A B C'!$J$15-'Skenario A B C'!$AE$15)) | U19: =IF(18<'Skenario A B C'!$E$15,0,MAX(0,'Skenario A B C'!$J$15-'Skenario A B C'!$AE$15)) | V19: =IF(19<'Skenario A B C'!$E$15,0,MAX(0,'Skenario A B C'!$J$15-'Skenario A B C'!$AE$15)) | W19: =IF(20<'Skenario A B C'!$E$15,0,MAX(0,'Skenario A B C'!$J$15-'Skenario A B C'!$AE$15)) | X19: =IF(21<'Skenario A B C'!$E$15,0,MAX(0,'Skenario A B C'!$J$15-'Skenario A B C'!$AE$15)) | Y19: =IF(22<'Skenario A B C'!$E$15,0,MAX(0,'Skenario A B C'!$J$15-'Skenario A B C'!$AE$15)) | Z19: =IF(23<'Skenario A B C'!$E$15,0,MAX(0,'Skenario A B C'!$J$15-'Skenario A B C'!$AE$15)) | AA19: =IF(24<'Skenario A B C'!$E$15,0,MAX(0,'Skenario A B C'!$J$15-'Skenario A B C'!$AE$15))
