Workbook

Sheet Asumsi Volume
A1: AntarKita — Model Biaya Infrastruktur Peta
A2: Disusun 9 September 2026. Sel berlatar KUNING adalah INPUT yang boleh diubah pemilik — seluruh lembar lain adalah rumus hidup dan ikut berubah seketika.
A4: A. PARAMETER GLOBAL
A5: Parameter | B5: Nilai | D5: Satuan | E5: Sumber / status
A6: Kurs USD → IDR (Kurs Tengah Transaksi BI) | B6: 17618 | D6: Rp per USD | E6: [S-30] bi.go.id, diakses 9 Sep 2026
A7: Kurs EUR → IDR | B7: 20459.79 | D7: Rp per EUR | E7: [S-30]
A8: Kurs CNY → IDR | B8: 2625.3 | D8: Rp per CNY | E8: [S-30]
A9: Faktor PPN PMSE penyedia luar negeri (11% efektif) | B9: 1.11 | D9: pengali | E9: [S-31] PER-12/2025: 12% x DPP nilai lain 11/12
A10: Hari per bulan | B10: 30 | D10: hari | E10: [ASUMSI]
A11: Pengali sesi menjelajah (pengguna yang tidak jadi memesan) | B11: 1.35 | D11: pengali | E11: [ASUMSI A7]
A12: Pendapatan platform per pesanan pada komisi patuh 8% | B12: 1640 | D12: Rp | E12: [INT] docs/investor/CATATAN-SUMBER-DECK.md — skenario uji S1
A13: Batas potongan roda dua (Perpres 27/2026) | B13: 0.08 | D13: proporsi | E13: [INT] migrasi 0031_batas_komisi_perpres_27_2026.sql
A15: B. SKENARIO VOLUME — UBAH TIGA SEL KUNING DI BARIS 17 DAN LIHAT SELURUH BIAYA BERUBAH
A16: Metrik | B16: A — Peluncuran | C16: B — Fase 2 | D16: C — Skala | E16: Sumber / status
A17: Pesanan per hari ← INPUT | B17: 600 | C17: 2400 | D17: 8000 | E17: [ASUMSI A8] Tidak ada angka pesanan/hari di dokumen bisnis AntarKita mana pun; ditetapkan penyusun riset.
A18: Pesanan per bulan | B18: =B17*'Asumsi Volume'!$B$10 | C18: =C17*'Asumsi Volume'!$B$10 | D18: =D17*'Asumsi Volume'!$B$10 | E18: Turunan: pesanan/hari x hari per bulan
A19: Pengguna aktif bulanan (MAU) ← INPUT | B19: 18000 | C19: 73000 | D19: 244000 | E19: [ASUMSI A9] 4 pesanan/pelanggan/bulan, 4x lipat penjelajah non-pemesan, + mitra aktif
A20: Sesi aktif per hari (termasuk penjelajah) | B20: =B17*'Asumsi Volume'!$B$11 | C20: =C17*'Asumsi Volume'!$B$11 | D20: =D17*'Asumsi Volume'!$B$11
A21: Pesanan per DAU | B21: =B17/B20 | C21: =C17/C20 | D21: =D17/D20
A23: CATATAN: Skenario A dipetakan ke Fase 0-1, B ke Fase 2, dan C ke dua kota matang (docs/organisasi/DESAIN-ORGANISASI.md §3). Ubah baris 17 untuk menguji rencana bisnis lain.

Sheet Panggilan per Pesanan
A1: Panggilan Layanan Geo per Satu Pesanan — diturunkan dari basis kode, bukan tebakan
A2: Sel KUNING adalah input. Kolom "Faktor hemat" adalah dampak strategi §5 dokumen riset.
A3: Layanan | B3: Panggilan / pesanan | C3: Pengali jelajah | D3: Faktor hemat (§5) | H3: Asal angka di basis kode
A4: Autocomplete / pencarian tempat | B4: 4 | C4: 1.35 | D4: 0.35 | H4: place-picker.tsx:44-53 debounce 400 ms, min 3 karakter; geo.ts:40-49 -> photon.komoot.io
A5: Reverse geocoding | B5: 2.5 | C5: 1.35 | D5: 0.3 | H5: ride/index.tsx:55 (pickup bawaan) + place-picker.tsx:55-60 (tiap moveend); geo.ts:82-97
A6: Rute (routing) | B6: 1.3 | C6: 1 | D6: 0.6 | H6: ride/index.tsx:59-63; geo.ts:102-119 -> router.project-osrm.org. Rute disimpan di orders.route_geometry
A7: Pemuatan peta (map load / sesi peta) | B7: 2.9 | C7: 1.35 | D7: 1 | H7: Instans <MapView>: place-picker.tsx:106, BookingExtras.tsx:15, order/detail.tsx:129, driver/order.tsx:117
A8: Permintaan ubin ke jaringan | B8: 100 | C8: 1.35 | D8: 0.45 | H8: shared.ts:22 TILE_URL; churn dari fitBounds tiap update driver (useOrder.ts:59-62 polling 6 dtk)
A9: Sesi pencarian (Mapbox Search Box / MapTiler) | B9: 1.3 | C9: 1.35 | D9: 0.35 | H9: [ASUMSI] 1,3 tempat dipilih per pesanan (pickup bawaan + tujuan)
A12: VOLUME BULANAN — RUMUS HIDUP (mengikuti Asumsi Volume baris 17)
A13: Unit | B13: A dasar | C13: B dasar | D13: C dasar | E13: A hemat | F13: B hemat | G13: C hemat | H13: Rumus
A14: Autocomplete / pencarian tempat | B14: =$B4*$C4*'Asumsi Volume'!B$18 | C14: =$B4*$C4*'Asumsi Volume'!C$18 | D14: =$B4*$C4*'Asumsi Volume'!D$18 | E14: =B14*$D4 | F14: =C14*$D4 | G14: =D14*$D4 | H14: panggilan/pesanan (B4) x pengali jelajah (C4) x pesanan per bulan; kolom hemat = kolom dasar x faktor hemat (D4)
A15: Reverse geocoding | B15: =$B5*$C5*'Asumsi Volume'!B$18 | C15: =$B5*$C5*'Asumsi Volume'!C$18 | D15: =$B5*$C5*'Asumsi Volume'!D$18 | E15: =B15*$D5 | F15: =C15*$D5 | G15: =D15*$D5 | H15: panggilan/pesanan (B5) x pengali jelajah (C5) x pesanan per bulan; kolom hemat = kolom dasar x faktor hemat (D5)
A16: Rute (routing) | B16: =$B6*$C6*'Asumsi Volume'!B$18 | C16: =$B6*$C6*'Asumsi Volume'!C$18 | D16: =$B6*$C6*'Asumsi Volume'!D$18 | E16: =B16*$D6 | F16: =C16*$D6 | G16: =D16*$D6 | H16: panggilan/pesanan (B6) x pengali jelajah (C6) x pesanan per bulan; kolom hemat = kolom dasar x faktor hemat (D6)
A17: Pemuatan peta (map load / sesi peta) | B17: =$B7*$C7*'Asumsi Volume'!B$18 | C17: =$B7*$C7*'Asumsi Volume'!C$18 | D17: =$B7*$C7*'Asumsi Volume'!D$18 | E17: =B17*$D7 | F17: =C17*$D7 | G17: =D17*$D7 | H17: panggilan/pesanan (B7) x pengali jelajah (C7) x pesanan per bulan; kolom hemat = kolom dasar x faktor hemat (D7)
A18: Permintaan ubin ke jaringan | B18: =$B8*$C8*'Asumsi Volume'!B$18 | C18: =$B8*$C8*'Asumsi Volume'!C$18 | D18: =$B8*$C8*'Asumsi Volume'!D$18 | E18: =B18*$D8 | F18: =C18*$D8 | G18: =D18*$D8 | H18: panggilan/pesanan (B8) x pengali jelajah (C8) x pesanan per bulan; kolom hemat = kolom dasar x faktor hemat (D8)
A19: Sesi pencarian (Mapbox Search Box / MapTiler) | B19: =$B9*$C9*'Asumsi Volume'!B$18 | C19: =$B9*$C9*'Asumsi Volume'!C$18 | D19: =$B9*$C9*'Asumsi Volume'!D$18 | E19: =B19*$D9 | F19: =C19*$D9 | G19: =D19*$D9 | H19: panggilan/pesanan (B9) x pengali jelajah (C9) x pesanan per bulan; kolom hemat = kolom dasar x faktor hemat (D9)
A20: Pengguna aktif bulanan (MAU) | B20: ='Asumsi Volume'!B$19 | C20: ='Asumsi Volume'!C$19 | D20: ='Asumsi Volume'!D$19 | E20: =B20 | F20: =C20 | G20: =D20 | H20: Diambil dari Asumsi Volume baris 19 (MAU tidak diturunkan dari pesanan)

Sheet Harga per Penyedia
A1: Harga Resmi per Penyedia — seluruhnya diakses 9 September 2026
A2: Harga dalam USD per 1.000 unit kecuali disebut lain. KONVENSI: kolom Batas adalah ambang atas tiap tingkat volume dihitung SETELAH kuota gratis dipotong (unit tertagih). Untuk penyedia yang menerbitkan batasnya termasuk kuota gratis (Mapbox), batas di sini sudah dikonversi ke neto — lihat kolom Sumber. BIG = 1E+15 dipakai untuk penyedia bertarif datar agar rumus berjenjang tetap berlaku.
A3: Penyedia | B3: SKU / Parameter | C3: Unit | D3: Gratis per bulan | E3: Batas 1 | F3: Harga 1 | G3: Batas 2 | H3: Harga 2 | I3: Batas 3 | J3: Harga 3 | K3: Batas 4 | L3: Harga 4 | M3: Harga >B4 | N3: Sumber
A4: Google | B4: Dynamic Maps (per map load) | C4: map load | D4: 10000 | E4: 100000 | F4: 7 | G4: 500000 | H4: 5.6 | I4: 1000000 | J4: 4.2 | K4: 5000000 | L4: 2.1 | M4: 0.53 | N4: [S-11]
A5: Google | B5: Places Autocomplete Requests | C5: permintaan | D5: 10000 | E5: 100000 | F5: 2.83 | G5: 500000 | H5: 2.27 | I5: 1000000 | J5: 1.7 | K5: 5000000 | L5: 0.85 | M5: 0.21 | N5: [S-11]
A6: Google | B6: Geocoding (termasuk reverse) | C6: permintaan | D6: 10000 | E6: 100000 | F6: 5 | G6: 500000 | H6: 4 | I6: 1000000 | J6: 3 | K6: 5000000 | L6: 1.5 | M6: 0.38 | N6: [S-11]
A7: Google | B7: Routes: Compute Routes (Essentials) | C7: permintaan | D7: 10000 | E7: 100000 | F7: 5 | G7: 500000 | H7: 4 | I7: 1000000 | J7: 3 | K7: 5000000 | L7: 1.5 | M7: 0.38 | N7: [S-11]
A8: Google | B8: Map Tiles API 2D (tidak dipakai model — Dynamic Maps sudah termasuk ubin) | C8: ubin | D8: 100000 | E8: 1000000 | F8: 0.6 | G8: 5000000 | H8: 0.48 | I8: 10000000 | J8: 0.36 | K8: 50000000 | L8: 0.18 | M8: 0.045 | N8: [S-11]
A9: Google | B9: Places Text Search (Pro) — DIPAKAI geo.ts:76, 11x lebih mahal dari Autocomplete | C9: permintaan | D9: 5000 | E9: 100000 | F9: 32 | G9: 500000 | H9: 25.6 | I9: 1e+15 | J9: 25.6 | K9: 1e+15 | L9: 25.6 | M9: 2.4 | N9: [S-11] + [INT] geo.ts:76
A10: Mapbox | B10: Maps SDK for Mobile (per MAU) | C10: MAU | D10: 25000 | E10: 100000 | F10: 4 | G10: 225000 | H10: 3.2 | I10: 1225000 | J10: 2.4 | K10: 1e+15 | L10: 2.4 | M10: 2.4 | N10: [S-13] Batas ditulis NETO setelah kuota gratis: 25.001-125.000 -> 100.000
A11: Mapbox | B11: Search Box API (per sesi) | C11: sesi | D11: 500 | E11: 99500 | F11: 3 | G11: 499500 | H11: 2.75 | I11: 1e+15 | J11: 2.5 | K11: 1e+15 | L11: 2.5 | M11: 2.5 | N11: [S-13] Batas neto: 501-100.000 -> 99.500
A12: Mapbox | B12: Directions API | C12: permintaan | D12: 100000 | E12: 400000 | F12: 2 | G12: 900000 | H12: 1.6 | I12: 1e+15 | J12: 1.2 | K12: 1e+15 | L12: 1.2 | M12: 1.2 | N12: [S-13] Batas neto: 100.001-500.000 -> 400.000
A13: Mapbox | B13: Geocoding temporary (tidak boleh disimpan permanen) | C13: permintaan | D13: 100000 | E13: 400000 | F13: 0.75 | G13: 900000 | H13: 0.6 | I13: 1e+15 | J13: 0.45 | K13: 1e+15 | L13: 0.45 | M13: 0.45 | N13: [S-13] Batas neto
A14: MapTiler | B14: Sesi peta (paket Flex) | C14: sesi | D14: 25000 | E14: 1e+15 | F14: 2.5 | G14: 1e+15 | H14: 2.5 | I14: 1e+15 | J14: 2.5 | K14: 1e+15 | L14: 2.5 | M14: 2.5 | N14: [S-14]
A15: MapTiler | B15: Sesi pencarian (paket Flex) | C15: sesi | D15: 3000 | E15: 1e+15 | F15: 2.5 | G15: 1e+15 | H15: 2.5 | I15: 1e+15 | J15: 2.5 | K15: 1e+15 | L15: 2.5 | M15: 2.5 | N15: [S-14]
... A39: AMap (TIDAK BOLEH DIPAKAI) | B39: Peta & Posisi Dasar | C39: CNY/panggilan | D39: 0 | E39: 0 | F39: 0.0003 | G39: 0 | H39: 0 | I39: 0 | J39: 0 | K39: 0 | L39: 0 | M39: 0 | N39: [S-08] ¥3/万次. TERLARANG: perjanjian Pasal 14.1 [S-06]

Sheet Biaya Bulanan 3 Skenario
A1: Biaya Bulanan per Penyedia — Tiga Skenario Volume
A2: Kolom "hemat" memakai faktor strategi §5 (cache geocoding, debounce autocomplete, tunda routing, kurangi gambar-ulang peta). Semua nilai USD kecuali blok Swasembada (Rupiah).
A4: GOOGLE MAPS PLATFORM — [S-11] [S-12]; kredit bulanan US$200 dihapus sejak 1 Mar 2025
A5: SKU / komponen | B5: Unit A | C5: Unit B | D5: Unit C | E5: Biaya A ($) | F5: Biaya B ($) | G5: Biaya C ($) | H5: Hemat A ($) | I5: Hemat B ($) | J5: Hemat C ($) | K5: Catatan
A6: Dynamic Maps (per map load; ubin sudah termasuk) | B6: ='Panggilan per Pesanan'!B17 | C6: ='Panggilan per Pesanan'!C17 | D6: ='Panggilan per Pesanan'!D17 | E6: =(MIN(MAX(0,'Panggilan per Pesanan'!B17-'Harga per Penyedia'!$D$4),'Harga per Penyedia'!$E$4)*'Harga per Penyedia'!$F$4+MAX(0,MIN(MAX(0,'Panggilan per Pesanan'!B17-'Harga per Penyedia'!$D$4),'Harga per Penyedia'!$G$4)-'Harga per Penyedia'!$E$4)*'Harga per Penyedia'!$H$4+MAX(0,MIN(MAX(0,'Panggilan per Pesanan'!B17-'Harga per Penyedia'!$D$4),'Harga per Penyedia'!$I$4)-'Harga per Penyedia'!$G$4)*'Harga per Penyedia'!$J$4+MAX(0,MIN(MAX(0,'Panggilan per Pesanan'!B17-'Harga per Penyedia'!$D$4),'Harga per Penyedia'!$K$4)-'Harga per Penyedia'!$I$4)*'Harga per Penyedia'!$L$4+MAX(0,MAX(0,'Panggilan per Pesanan'!B17-'Harga per Penyedia'!$D$4)-'Harga per Penyedia'!$K$4)*'Harga per Penyedia'!$M$4)/1000 | F6: =(MIN(MAX(0,'Panggilan per Pesanan'!C17-'Harga per Penyedia'!$D$4),'Harga per Penyedia'!$E$4)*'Harga per Penyedia'!$F$4+MAX(0,MIN(MAX(0,'Panggilan per Pesanan'!C17-'Harga per Penyedia'!$D$4),'Harga per Penyedia'!$G$4)-'Harga per Penyedia'!$E$4)*'Harga per Penyedia'!$H$4+MAX(0,MIN(MAX(0,'Panggilan per Pesanan'!C17-'Harga per Penyedia'!$D$4),'Harga per Penyedia'!$I$4)-'Harga per Penyedia'!$G$4)*'Harga per Penyedia'!$J$4+MAX(0,MIN(MAX(0,'Panggilan per Pesanan'!C17-'Harga per Penyedia'!$D$4),'Harga per Penyedia'!$K$4)-'Harga per Penyedia'!$I$4)*'Harga per Penyedia'!$L$4+MAX(0,MAX(0,'Panggilan per Pesanan'!C17-'Harga per Penyedia'!$D$4)-'Harga per Penyedia'!$K$4)*'Harga per Penyedia'!$M$4)/1000 | G6: =(MIN(MAX(0,'Panggilan per Pesanan'!D17-'Harga per Penyedia'!$D$4),'Harga per Penyedia'!$E$4)*'Harga per Penyedia'!$F$4+MAX(0,MIN(MAX(0,'Panggilan per Pesanan'!D17-'Harga per Penyedia'!$D$4),'Harga per Penyedia'!$G$4)-'Harga per Penyedia'!$E$4)*'Harga per Penyedia'!$H$4+MAX(0,MIN(MAX(0,'Panggilan per Pesanan'!D17-'Harga per Penyedia'!$D$4),'Harga per Penyedia'!$I$4)-'Harga per Penyedia'!$G$4)*'Harga per Penyedia'!$J$4+MAX(0,MIN(MAX(0,'Panggilan per Pesanan'!D17-'Harga per Penyedia'!$D$4),'Harga per Penyedia'!$K$4)-'Harga per Penyedia'!$I$4)*'Harga per Penyedia'!$L$4+MAX(0,MAX(0,'Panggilan per Pesanan'!D17-'Harga per Penyedia'!$D$4)-'Harga per Penyedia'!$K$4)*'Harga per Penyedia'!$M$4)/1000 | H6: =(MIN(MAX(0,'Panggilan per Pesanan'!E17-'Harga per Penyedia'!$D$4),'Harga per Penyedia'!$E$4)*'Harga per Penyedia'!$F$4+MAX(0,MIN(MAX(0,'Panggilan per Pesanan'!E17-'Harga per Penyedia'!$D$4),'Harga per Penyedia'!$G$4)-'Harga per Penyedia'!$E$4)*'Harga per Penyedia'!$H$4+MAX(0,MIN(MAX(0,'Panggilan per Pesanan'!E17-'Harga per Penyedia'!$D$4),'Harga per Penyedia'!$I$4)-'Harga per Penyedia'!$G$4)*'Harga per Penyedia'!$J$4+MAX(0,MIN(MAX(0,'Panggilan per Pesanan'!E17-'Harga per Penyedia'!$D$4),'Harga per Penyedia'!$K$4)-'Harga per Penyedia'!$I$4)*'Harga per Penyedia'!$L$4+MAX(0,MAX(0,'Panggilan per Pesanan'!E17-'Harga per Penyedia'!$D$4)-'Harga per Penyedia'!$K$4)*'Harga per Penyedia'!$M$4)/1000 | I6: =(MIN(MAX(0,'Panggilan per Pesanan'!F17-'Harga per Penyedia'!$D$4),'Harga per Penyedia'!$E$4)*'Harga per Penyedia'!$F$4+MAX(0,MIN(MAX(0,'Panggilan per Pesanan'!F17-'Harga per Penyedia'!$D$4),'Harga per Penyedia'!$G$4)-'Harga per Penyedia'!$E$4)*'Harga per Penyedia'!$H$4+MAX(0,MIN(MAX(0,'Panggilan per Pesanan'!F17-'Harga per Penyedia'!$D$4),'Harga per Penyedia'!$I$4)-'Harga per Penyedia'!$G$4)*'Harga per Penyedia'!$J$4+MAX(0,MIN(MAX(0,'Panggilan per Pesanan'!F17-'Harga per Penyedia'!$D$4),'Harga per Penyedia'!$K$4)-'Harga per Penyedia'!$I$4)*'Harga per Penyedia'!$L$4+MAX(0,MAX(0,'Panggilan per Pesanan'!F17-'Harga per Penyedia'!$D$4)-'Harga per Penyedia'!$K$4)*'Harga per Penyedia'!$M$4)/1000 | J6: =(MIN(MAX(0,'Panggilan per Pesanan'!G17-'Harga per Penyedia'!$D$4),'Harga per Penyedia'!$E$4)*'Harga per Penyedia'!$F$4+MAX(0,MIN(MAX(0,'Panggilan per Pesanan'!G17-'Harga per Penyedia'!$D$4),'Harga per Penyedia'!$G$4)-'Harga per Penyedia'!$E$4)*'Harga per Penyedia'!$H$4+MAX(0,MIN(MAX(0,'Panggilan per Pesanan'!G17-'Harga per Penyedia'!$D$4),'Harga per Penyedia'!$I$4)-'Harga per Penyedia'!$G$4)*'Harga per Penyedia'!$J$4+MAX(0,MIN(MAX(0,'Panggilan per Pesanan'!G17-'Harga per Penyedia'!$D$4),'Harga per Penyedia'!$K$4)-'Harga per Penyedia'!$I$4)*'Harga per Penyedia'!$L$4+MAX(0,MAX(0,'Panggilan per Pesanan'!G17-'Harga per Penyedia'!$D$4)-'Harga per Penyedia'!$K$4)*'Harga per Penyedia'!$M$4)/1000 | K6: Gratis 10.000/bulan per SKU
A7: Places Autocomplete Requests | B7: ='Panggilan per Pesanan'!B14 | C7: ='Panggilan per Pesanan'!C14 | D7: ='Panggilan per Pesanan'!D14 | E7: =(MIN(MAX(0,'Panggilan per Pesanan'!B14-'Harga per Penyedia'!$D$5),'Harga per Penyedia'!$E$5)*'Harga per Penyedia'!$F$5+MAX(0,MIN(MAX(0,'Panggilan per Pesanan'!B14-'Harga per Penyedia'!$D$5),'Harga per Penyedia'!$G$5)-'Harga per Penyedia'!$E$5)*'Harga per Penyedia'!$H$5+MAX(0,MIN(MAX(0,'Panggilan per Pesanan'!B14-'Harga per Penyedia'!$D$5),'Harga per Penyedia'!$I$5)-'Harga per Penyedia'!$G$5)*'Harga per Penyedia'!$J$5+MAX(0,MIN(MAX(0,'Panggilan per Pesanan'!B14-'Harga per Penyedia'!$D$5),'Harga per Penyedia'!$K$5)-'Harga per Penyedia'!$I$5)*'Harga per Penyedia'!$L$5+MAX(0,MAX(0,'Panggilan per Pesanan'!B14-'Harga per Penyedia'!$D$5)-'Harga per Penyedia'!$K$5)*'Harga per Penyedia'!$M$5)/1000 | F7: =(MIN(MAX(0,'Panggilan per Pesanan'!C14-'Harga per Penyedia'!$D$5),'Harga per Penyedia'!$E$5)*'Harga per Penyedia'!$F$5+MAX(0,MIN(MAX(0,'Panggilan per Pesanan'!C14-'Harga per Penyedia'!$D$5),'Harga per Penyedia'!$G$5)-'Harga per Penyedia'!$E$5)*'Harga per Penyedia'!$H$5+MAX(0,MIN(MAX(0,'Panggilan per Pesanan'!C14-'Harga per Penyedia'!$D$5),'Harga per Penyedia'!$I$5)-'Harga per Penyedia'!$G$5)*'Harga per Penyedia'!$J$5+MAX(0,MIN(MAX(0,'Panggilan per Pesanan'!C14-'Harga per Penyedia'!$D$5),'Harga per Penyedia'!$K$5)-'Harga per Penyedia'!$I$5)*'Harga per Penyedia'!$L$5+MAX(0,MAX(0,'Panggilan per Pesanan'!C14-'Harga per Penyedia'!$D$5)-'Harga per Penyedia'!$K$5)*'Harga per Penyedia'!$M$5)/1000 | G7: =(MIN(MAX(0,'Panggilan per Pesanan'!D14-'Harga per Penyedia'!$D$5),'Harga per Penyedia'!$E$5)*'Harga per Penyedia'!$F$5+MAX(0,MIN(MAX(0,'Panggilan per Pesanan'!D14-'Harga per Penyedia'!$D$5),'Harga per Penyedia'!$G$5)-'Harga per Penyedia'!$E$5)*'Harga per Penyedia'!$H$5+MAX(0,MIN(MAX(0,'Panggilan per Pesanan'!D14-'Harga per Penyedia'!$D$5),'Harga per Penyedia'!$I$5)-'Harga per Penyedia'!$G$5)*'Harga per Penyedia'!$J$5+MAX(0,MIN(MAX(0,'Panggilan per Pesanan'!D14-'Harga per Penyedia'!$D$5),'Harga per Penyedia'!$K$5)-'Harga per Penyedia'!$I$5)*'Harga per Penyedia'!$L$5+MAX(0,MAX(0,'Panggilan per Pesanan'!D14-'Harga per Penyedia'!$D$5)-'Harga per Penyedia'!$K$5)*'Harga per Penyedia'!$M$5)/1000 | H7: =(MIN(MAX(0,'Panggilan per Pesanan'!E14-'Harga per Penyedia'!$D$5),'Harga per Penyedia'!$E$5)*'Harga per Penyedia'!$F$5+MAX(0,MIN(MAX(0,'Panggilan per Pesanan'!E14-'Harga per Penyedia'!$D$5),'Harga per Penyedia'!$G$5)-'Harga per Penyedia'!$E$5)*'Harga per Penyedia'!$H$5+MAX(0,MIN(MAX(0,'Panggilan per Pesanan'!E14-'Harga per Penyedia'!$D$5),'Harga per Penyedia'!$I$5)-'Harga per Penyedia'!$G$5)*'Harga per Penyedia'!$J$5+MAX(0,MIN(MAX(0,'Panggilan per Pesanan'!E14-'Harga per Penyedia'!$D$5),'Harga per Penyedia'!$K$5)-'Harga per Penyedia'!$I$5)*'Harga per Penyedia'!$L$5+MAX(0,MAX(0,'Panggilan per Pesanan'!E14-'Harga per Penyedia'!$D$5)-'Harga per Penyedia'!$K$5)*'Harga per Penyedia'!$M$5)/1000 | I7: =(MIN(MAX(0,'Panggilan per Pesanan'!F14-'Harga per Penyedia'!$D$5),'Harga per Penyedia'!$E$5)*'Harga per Penyedia'!$F$5+MAX(0,MIN(MAX(0,'Panggilan per Pesanan'!F14-'Harga per Penyedia'!$D$5),'Harga per Penyedia'!$G$5)-'Harga per Penyedia'!$E$5)*'Harga per Penyedia'!$H$5+MAX(0,MIN(MAX(0,'Panggilan per Pesanan'!F14-'Harga per Penyedia'!$D$5),'Harga per Penyedia'!$I$5)-'Harga per Penyedia'!$G$5)*'Harga per Penyedia'!$J$5+MAX(0,MIN(MAX(0,'Panggilan per Pesanan'!F14-'Harga per Penyedia'!$D$5),'Harga per Penyedia'!$K$5)-'Harga per Penyedia'!$I$5)*'Harga per Penyedia'!$L$5+MAX(0,MAX(0,'Panggilan per Pesanan'!F14-'Harga per Penyedia'!$D$5)-'Harga per Penyedia'!$K$5)*'Harga per Penyedia'!$M$5)/1000 | J7: =(MIN(MAX(0,'Panggilan per Pesanan'!G14-'Harga per Penyedia'!$D$5),'Harga per Penyedia'!$E$5)*'Harga per Penyedia'!$F$5+MAX(0,MIN(MAX(0,'Panggilan per Pesanan'!G14-'Harga per Penyedia'!$D$5),'Harga per Penyedia'!$G$5)-'Harga per Penyedia'!$E$5)*'Harga per Penyedia'!$H$5+MAX(0,MIN(MAX(0,'Panggilan per Pesanan'!G14-'Harga per Penyedia'!$D$5),'Harga per Penyedia'!$I$5)-'Harga per Penyedia'!$G$5)*'Harga per Penyedia'!$J$5+MAX(0,MIN(MAX(0,'Panggilan per Pesanan'!G14-'Harga per Penyedia'!$D$5),'Harga per Penyedia'!$K$5)-'Harga per Penyedia'!$I$5)*'Harga per Penyedia'!$L$5+MAX(0,MAX(0,'Panggilan per Pesanan'!G14-'Harga per Penyedia'!$D$5)-'Harga per Penyedia'!$K$5)*'Harga per Penyedia'!$M$5)/1000 | K7: Session token dapat menjadikannya $0 — lihat §5.2
A8: Geocoding (reverse) | B8: ='Panggilan per Pesanan'!B15 | C8: ='Panggilan per Pesanan'!C15 | D8: ='Panggilan per Pesanan'!D15 | E8: =(MIN(MAX(0,'Panggilan per Pesanan'!B15-'Harga per Penyedia'!$D$6),'Harga per Penyedia'!$E$6)*'Harga per Penyedia'!$F$6+MAX(0,MIN(MAX(0,'Panggilan per Pesanan'!B15-'Harga per Penyedia'!$D$6),'Harga per Penyedia'!$G$6)-'Harga per Penyedia'!$E$6)*'Harga per Penyedia'!$H$6+MAX(0,MIN(MAX(0,'Panggilan per Pesanan'!B15-'Harga per Penyedia'!$D$6),'Harga per Penyedia'!$I$6)-'Harga per Penyedia'!$G$6)*'Harga per Penyedia'!$J$6+MAX(0,MIN(MAX(0,'Panggilan per Pesanan'!B15-'Harga per Penyedia'!$D$6),'Harga per Penyedia'!$K$6)-'Harga per Penyedia'!$I$6)*'Harga per Penyedia'!$L$6+MAX(0,MAX(0,'Panggilan per Pesanan'!B15-'Harga per Penyedia'!$D$6)-'Harga per Penyedia'!$K$6)*'Harga per Penyedia'!$M$6)/1000 | F8: =(MIN(MAX(0,'Panggilan per Pesanan'!C15-'Harga per Penyedia'!$D$6),'Harga per Penyedia'!$E$6)*'Harga per Penyedia'!$F$6+MAX(0,MIN(MAX(0,'Panggilan per Pesanan'!C15-'Harga per Penyedia'!$D$6),'Harga per Penyedia'!$G$6)-'Harga per Penyedia'!$E$6)*'Harga per Penyedia'!$H$6+MAX(0,MIN(MAX(0,'Panggilan per Pesanan'!C15-'Harga per Penyedia'!$D$6),'Harga per Penyedia'!$I$6)-'Harga per Penyedia'!$G$6)*'Harga per Penyedia'!$J$6+MAX(0,MIN(MAX(0,'Panggilan per Pesanan'!C15-'Harga per Penyedia'!$D$6),'Harga per Penyedia'!$K$6)-'Harga per Penyedia'!$I$6)*'Harga per Penyedia'!$L$6+MAX(0,MAX(0,'Panggilan per Pesanan'!C15-'Harga per Penyedia'!$D$6)-'Harga per Penyedia'!$K$6)*'Harga per Penyedia'!$M$6)/1000 | G8: =(MIN(MAX(0,'Panggilan per Pesanan'!D15-'Harga per Penyedia'!$D$6),'Harga per Penyedia'!$E$6)*'Harga per Penyedia'!$F$6+MAX(0,MIN(MAX(0,'Panggilan per Pesanan'!D15-'Harga per Penyedia'!$D$6),'Harga per Penyedia'!$G$6)-'Harga per Penyedia'!$E$6)*'Harga per Penyedia'!$H$6+MAX(0,MIN(MAX(0,'Panggilan per Pesanan'!D15-'Harga per Penyedia'!$D$6),'Harga per Penyedia'!$I$6)-'Harga per Penyedia'!$G$6)*'Harga per Penyedia'!$J$6+MAX(0,MIN(MAX(0,'Panggilan per Pesanan'!D15-'Harga per Penyedia'!$D$6),'Harga per Penyedia'!$K$6)-'Harga per Penyedia'!$I$6)*'Harga per Penyedia'!$L$6+MAX(0,MAX(0,'Panggilan per Pesanan'!D15-'Harga per Penyedia'!$D$6)-'Harga per Penyedia'!$K$6)*'Harga per Penyedia'!$M$6)/1000 | H8: =(MIN(MAX(0,'Panggilan per Pesanan'!E15-'Harga per Penyedia'!$D$6),'Harga per Penyedia'!$E$6)*'Harga per Penyedia'!$F$6+MAX(0,MIN(MAX(0,'Panggilan per Pesanan'!E15-'Harga per Penyedia'!$D$6),'Harga per Penyedia'!$G$6)-'Harga per Penyedia'!$E$6)*'Harga per Penyedia'!$H$6+MAX(0,MIN(MAX(0,'Panggilan per Pesanan'!E15-'Harga per Penyedia'!$D$6),'Harga per Penyedia'!$I$6)-'Harga per Penyedia'!$G$6)*'Harga per Penyedia'!$J$6+MAX(0,MIN(MAX(0,'Panggilan per Pesanan'!E15-'Harga per Penyedia'!$D$6),'Harga per Penyedia'!$K$6)-'Harga per Penyedia'!$I$6)*'Harga per Penyedia'!$L$6+MAX(0,MAX(0,'Panggilan per Pesanan'!E15-'Harga per Penyedia'!$D$6)-'Harga per Penyedia'!$K$6)*'Harga per Penyedia'!$M$6)/1000 | I8: =(MIN(MAX(0,'Panggilan per Pesanan'!F15-'Harga per Penyedia'!$D$6),'Harga per Penyedia'!$E$6)*'Harga per Penyedia'!$F$6+MAX(0,MIN(MAX(0,'Panggilan per Pesanan'!F15-'Harga per Penyedia'!$D$6),'Harga per Penyedia'!$G$6)-'Harga per Penyedia'!$E$6)*'Harga per Penyedia'!$H$6+MAX(0,MIN(MAX(0,'Panggilan per Pesanan'!F15-'Harga per Penyedia'!$D$6),'Harga per Penyedia'!$I$6)-'Harga per Penyedia'!$G$6)*'Harga per Penyedia'!$J$6+MAX(0,MIN(MAX(0,'Panggilan per Pesanan'!F15-'Harga per Penyedia'!$D$6),'Harga per Penyedia'!$K$6)-'Harga per Penyedia'!$I$6)*'Harga per Penyedia'!$L$6+MAX(0,MAX(0,'Panggilan per Pesanan'!F15-'Harga per Penyedia'!$D$6)-'Harga per Penyedia'!$K$6)*'Harga per Penyedia'!$M$6)/1000 | J8: =(MIN(MAX(0,'Panggilan per Pesanan'!G15-'Harga per Penyedia'!$D$6),'Harga per Penyedia'!$E$6)*'Harga per Penyedia'!$F$6+MAX(0,MIN(MAX(0,'Panggilan per Pesanan'!G15-'Harga per Penyedia'!$D$6),'Harga per Penyedia'!$G$6)-'Harga per Penyedia'!$E$6)*'Harga per Penyedia'!$H$6+MAX(0,MIN(MAX(0,'Panggilan per Pesanan'!G15-'Harga per Penyedia'!$D$6),'Harga per Penyedia'!$I$6)-'Harga per Penyedia'!$G$6)*'Harga per Penyedia'!$J$6+MAX(0,MIN(MAX(0,'Panggilan per Pesanan'!G15-'Harga per Penyedia'!$D$6),'Harga per Penyedia'!$K$6)-'Harga per Penyedia'!$I$6)*'Harga per Penyedia'!$L$6+MAX(0,MAX(0,'Panggilan per Pesanan'!G15-'Harga per Penyedia'!$D$6)-'Harga per Penyedia'!$K$6)*'Harga per Penyedia'!$M$6)/1000
A9: Routes: Compute Routes (Essentials) | B9: ='Panggilan per Pesanan'!B16 | C9: ='Panggilan per Pesanan'!C16 | D9: ='Panggilan per Pesanan'!D16 | E9: =(MIN(MAX(0,'Panggilan per Pesanan'!B16-'Harga per Penyedia'!$D$7),'Harga per Penyedia'!$E$7)*'Harga per Penyedia'!$F$7+MAX(0,MIN(MAX(0,'Panggilan per Pesanan'!B16-'Harga per Penyedia'!$D$7),'Harga per Penyedia'!$G$7)-'Harga per Penyedia'!$E$7)*'Harga per Penyedia'!$H$7+MAX(0,MIN(MAX(0,'Panggilan per Pesanan'!B16-'Harga per Penyedia'!$D$7),'Harga per Penyedia'!$I$7)-'Harga per Penyedia'!$G$7)*'Harga per Penyedia'!$J$7+MAX(0,MIN(MAX(0,'Panggilan per Pesanan'!B16-'Harga per Penyedia'!$D$7),'Harga per Penyedia'!$K$7)-'Harga per Penyedia'!$I$7)*'Harga per Penyedia'!$L$7+MAX(0,MAX(0,'Panggilan per Pesanan'!B16-'Harga per Penyedia'!$D$7)-'Harga per Penyedia'!$K$7)*'Harga per Penyedia'!$M$7)/1000 | F9: =(MIN(MAX(0,'Panggilan per Pesanan'!C16-'Harga per Penyedia'!$D$7),'Harga per Penyedia'!$E$7)*'Harga per Penyedia'!$F$7+MAX(0,MIN(MAX(0,'Panggilan per Pesanan'!C16-'Harga per Penyedia'!$D$7),'Harga per Penyedia'!$G$7)-'Harga per Penyedia'!$E$7)*'Harga per Penyedia'!$H$7+MAX(0,MIN(MAX(0,'Panggilan per Pesanan'!C16-'Harga per Penyedia'!$D$7),'Harga per Penyedia'!$I$7)-'Harga per Penyedia'!$G$7)*'Harga per Penyedia'!$J$7+MAX(0,MIN(MAX(0,'Panggilan per Pesanan'!C16-'Harga per Penyedia'!$D$7),'Harga per Penyedia'!$K$7)-'Harga per Penyedia'!$I$7)*'Harga per Penyedia'!$L$7+MAX(0,MAX(0,'Panggilan per Pesanan'!C16-'Harga per Penyedia'!$D$7)-'Harga per Penyedia'!$K$7)*'Harga per Penyedia'!$M$7)/1000 | G9: =(MIN(MAX(0,'Panggilan per Pesanan'!D16-'Harga per Penyedia'!$D$7),'Harga per Penyedia'!$E$7)*'Harga per Penyedia'!$F$7+MAX(0,MIN(MAX(0,'Panggilan per Pesanan'!D16-'Harga per Penyedia'!$D$7),'Harga per Penyedia'!$G$7)-'Harga per Penyedia'!$E$7)*'Harga per Penyedia'!$H$7+MAX(0,MIN(MAX(0,'Panggilan per Pesanan'!D16-'Harga per Penyedia'!$D$7),'Harga per Penyedia'!$I$7)-'Harga per Penyedia'!$G$7)*'Harga per Penyedia'!$J$7+MAX(0,MIN(MAX(0,'Panggilan per Pesanan'!D16-'Harga per Penyedia'!$D$7),'Harga per Penyedia'!$K$7)-'Harga per Penyedia'!$I$7)*'Harga per Penyedia'!$L$7+MAX(0,MAX(0,'Panggilan per Pesanan'!D16-'Harga per Penyedia'!$D$7)-'Harga per Penyedia'!$K$7)*'Harga per Penyedia'!$M$7)/1000 | H9: =(MIN(MAX(0,'Panggilan per Pesanan'!E16-'Harga per Penyedia'!$D$7),'Harga per Penyedia'!$E$7)*'Harga per Penyedia'!$F$7+MAX(0,MIN(MAX(0,'Panggilan per Pesanan'!E16-'Harga per Penyedia'!$D$7),'Harga per Penyedia'!$G$7)-'Harga per Penyedia'!$E$7)*'Harga per Penyedia'!$H$7+MAX(0,MIN(MAX(0,'Panggilan per Pesanan'!E16-'Harga per Penyedia'!$D$7),'Harga per Penyedia'!$I$7)-'Harga per Penyedia'!$G$7)*'Harga per Penyedia'!$J$7+MAX(0,MIN(MAX(0,'Panggilan per Pesanan'!E16-'Harga per Penyedia'!$D$7),'Harga per Penyedia'!$K$7)-'Harga per Penyedia'!$I$7)*'Harga per Penyedia'!$L$7+MAX(0,MAX(0,'Panggilan per Pesanan'!E16-'Harga per Penyedia'!$D$7)-'Harga per Penyedia'!$K$7)*'Harga per Penyedia'!$M$7)/1000 | I9: =(MIN(MAX(0,'Panggilan per Pesanan'!F16-'Harga per Penyedia'!$D$7),'Harga per Penyedia'!$E$7)*'Harga per Penyedia'!$F$7+MAX(0,MIN(MAX(0,'Panggilan per Pesanan'!F16-'Harga per Penyedia'!$D$7),'Harga per Penyedia'!$G$7)-'Harga per Penyedia'!$E$7)*'Harga per Penyedia'!$H$7+MAX(0,MIN(MAX(0,'Panggilan per Pesanan'!F16-'Harga per Penyedia'!$D$7),'Harga per Penyedia'!$I$7)-'Harga per Penyedia'!$G$7)*'Harga per Penyedia'!$J$7+MAX(0,MIN(MAX(0,'Panggilan per Pesanan'!F16-'Harga per Penyedia'!$D$7),'Harga per Penyedia'!$K$7)-'Harga per Penyedia'!$I$7)*'Harga per Penyedia'!$L$7+MAX(0,MAX(0,'Panggilan per Pesanan'!F16-'Harga per Penyedia'!$D$7)-'Harga per Penyedia'!$K$7)*'Harga per Penyedia'!$M$7)/1000 | J9: =(MIN(MAX(0,'Panggilan per Pesanan'!G16-'Harga per Penyedia'!$D$7),'Harga per Penyedia'!$E$7)*'Harga per Penyedia'!$F$7+MAX(0,MIN(MAX(0,'Panggilan per Pesanan'!G16-'Harga per Penyedia'!$D$7),'Harga per Penyedia'!$G$7)-'Harga per Penyedia'!$E$7)*'Harga per Penyedia'!$H$7+MAX(0,MIN(MAX(0,'Panggilan per Pesanan'!G16-'Harga per Penyedia'!$D$7),'Harga per Penyedia'!$I$7)-'Harga per Penyedia'!$G$7)*'Harga per Penyedia'!$J$7+MAX(0,MIN(MAX(0,'Panggilan per Pesanan'!G16-'Harga per Penyedia'!$D$7),'Harga per Penyedia'!$K$7)-'Harga per Penyedia'!$I$7)*'Harga per Penyedia'!$L$7+MAX(0,MAX(0,'Panggilan per Pesanan'!G16-'Harga per Penyedia'!$D$7)-'Harga per Penyedia'!$K$7)*'Harga per Penyedia'!$M$7)/1000
A10: TOTAL GOOGLE | E10: =SUM(E6:E9) | F10: =SUM(F6:F9) | G10: =SUM(G6:G9) | H10: =SUM(H6:H9) | I10: =SUM(I6:I9) | J10: =SUM(J6:J9)
A12: MAPBOX — [S-13]; Maps SDK Mobile ditagih per MAU, bukan per pemuatan peta atau ubin
A13: SKU / komponen | B13: Unit A | C13: Unit B | D13: Unit C | E13: Biaya A ($) | F13: Biaya B ($) | G13: Biaya C ($) | H13: Hemat A ($) | I13: Hemat B ($) | J13: Hemat C ($) | K13: Catatan
A14: Maps SDK for Mobile (per MAU) | B14: ='Panggilan per Pesanan'!B20 | C14: ='Panggilan per Pesanan'!C20 | D14: ='Panggilan per Pesanan'!D20 | E14: =(MIN(MAX(0,'Panggilan per Pesanan'!B20-'Harga per Penyedia'!$D$10),'Harga per Penyedia'!$E$10)*'Harga per Penyedia'!$F$10+MAX(0,MIN(MAX(0,'Panggilan per Pesanan'!B20-'Harga per Penyedia'!$D$10),'Harga per Penyedia'!$G$10)-'Harga per Penyedia'!$E$10)*'Harga per Penyedia'!$H$10+MAX(0,MIN(MAX(0,'Panggilan per Pesanan'!B20-'Harga per Penyedia'!$D$10),'Harga per Penyedia'!$I$10)-'Harga per Penyedia'!$G$10)*'Harga per Penyedia'!$J$10+MAX(0,MIN(MAX(0,'Panggilan per Pesanan'!B20-'Harga per Penyedia'!$D$10),'Harga per Penyedia'!$K$10)-'Harga per Penyedia'!$I$10)*'Harga per Penyedia'!$L$10+MAX(0,MAX(0,'Panggilan per Pesanan'!B20-'Harga per Penyedia'!$D$10)-'Harga per Penyedia'!$K$10)*'Harga per Penyedia'!$M$10)/1000 | F14: =(MIN(MAX(0,'Panggilan per Pesanan'!C20-'Harga per Penyedia'!$D$10),'Harga per Penyedia'!$E$10)*'Harga per Penyedia'!$F$10+MAX(0,MIN(MAX(0,'Panggilan per Pesanan'!C20-'Harga per Penyedia'!$D$10),'Harga per Penyedia'!$G$10)-'Harga per Penyedia'!$E$10)*'Harga per Penyedia'!$H$10+MAX(0,MIN(MAX(0,'Panggilan per Pesanan'!C20-'Harga per Penyedia'!$D$10),'Harga per Penyedia'!$I$10)-'Harga per Penyedia'!$G$10)*'Harga per Penyedia'!$J$10+MAX(0,MIN(MAX(0,'Panggilan per Pesanan'!C20-'Harga per Penyedia'!$D$10),'Harga per Penyedia'!$K$10)-'Harga per Penyedia'!$I$10)*'Harga per Penyedia'!$L$10+MAX(0,MAX(0,'Panggilan per Pesanan'!C20-'Harga per Penyedia'!$D$10)-'Harga per Penyedia'!$K$10)*'Harga per Penyedia'!$M$10)/1000 | G14: =(MIN(MAX(0,'Panggilan per Pesanan'!D20-'Harga per Penyedia'!$D$10),'Harga per Penyedia'!$E$10)*'Harga per Penyedia'!$F$10+MAX(0,MIN(MAX(0,'Panggilan per Pesanan'!D20-'Harga per Penyedia'!$D$10),'Harga per Penyedia'!$G$10)-'Harga per Penyedia'!$E$10)*'Harga per Penyedia'!$H$10+MAX(0,MIN(MAX(0,'Panggilan per Pesanan'!D20-'Harga per Penyedia'!$D$10),'Harga per Penyedia'!$I$10)-'Harga per Penyedia'!$G$10)*'Harga per Penyedia'!$J$10+MAX(0,MIN(MAX(0,'Panggilan per Pesanan'!D20-'Harga per Penyedia'!$D$10),'Harga per Penyedia'!$K$10)-'Harga per Penyedia'!$I$10)*'Harga per Penyedia'!$L$10+MAX(0,MAX(0,'Panggilan per Pesanan'!D20-'Harga per Penyedia'!$D$10)-'Harga per Penyedia'!$K$10)*'Harga per Penyedia'!$M$10)/1000 | H14: =(MIN(MAX(0,'Panggilan per Pesanan'!E20-'Harga per Penyedia'!$D$10),'Harga per Penyedia'!$E$10)*'Harga per Penyedia'!$F$10+MAX(0,MIN(MAX(0,'Panggilan per Pesanan'!E20-'Harga per Penyedia'!$D$10),'Harga per Penyedia'!$G$10)-'Harga per Penyedia'!$E$10)*'Harga per Penyedia'!$H$10+MAX(0,MIN(MAX(0,'Panggilan per Pesanan'!E20-'Harga per Penyedia'!$D$10),'Harga per Penyedia'!$I$10)-'Harga per Penyedia'!$G$10)*'Harga per Penyedia'!$J$10+MAX(0,MIN(MAX(0,'Panggilan per Pesanan'!E20-'Harga per Penyedia'!$D$10),'Harga per Penyedia'!$K$10)-'Harga per Penyedia'!$I$10)*'Harga per Penyedia'!$L$10+MAX(0,MAX(0,'Panggilan per Pesanan'!E20-'Harga per Penyedia'!$D$10)-'Harga per Penyedia'!$K$10)*'Harga per Penyedia'!$M$10)/1000 | I14: =(MIN(MAX(0,'Panggilan per Pesanan'!F20-'Harga per Penyedia'!$D$10),'Harga per Penyedia'!$E$10)*'Harga per Penyedia'!$F$10+MAX(0,MIN(MAX(0,'Panggilan per Pesanan'!F20-'Harga per Penyedia'!$D$10),'Harga per Penyedia'!$G$10)-'Harga per Penyedia'!$E$10)*'Harga per Penyedia'!$H$10+MAX(0,MIN(MAX(0,'Panggilan per Pesanan'!F20-'Harga per Penyedia'!$D$10),'Harga per Penyedia'!$I$10)-'Harga per Penyedia'!$G$10)*'Harga per Penyedia'!$J$10+MAX(0,MIN(MAX(0,'Panggilan per Pesanan'!F20-'Harga per Penyedia'!$D$10),'Harga per Penyedia'!$K$10)-'Harga per Penyedia'!$I$10)*'Harga per Penyedia'!$L$10+MAX(0,MAX(0,'Panggilan per Pesanan'!F20-'Harga per Penyedia'!$D$10)-'Harga per Penyedia'!$K$10)*'Harga per Penyedia'!$M$10)/1000 | J14: =(MIN(MAX(0,'Panggilan per Pesanan'!G20-'Harga per Penyedia'!$D$10),'Harga per Penyedia'!$E$10)*'Harga per Penyedia'!$F$10+MAX(0,MIN(MAX(0,'Panggilan per Pesanan'!G20-'Harga per Penyedia'!$D$10),'Harga per Penyedia'!$G$10)-'Harga per Penyedia'!$E$10)*'Harga per Penyedia'!$H$10+MAX(0,MIN(MAX(0,'Panggilan per Pesanan'!G20-'Harga per Penyedia'!$D$10),'Harga per Penyedia'!$I$10)-'Harga per Penyedia'!$G$10)*'Harga per Penyedia'!$J$10+MAX(0,MIN(MAX(0,'Panggilan per Pesanan'!G20-'Harga per Penyedia'!$D$10),'Harga per Penyedia'!$K$10)-'Harga per Penyedia'!$I$10)*'Harga per Penyedia'!$L$10+MAX(0,MAX(0,'Panggilan per Pesanan'!G20-'Harga per Penyedia'!$D$10)-'Harga per Penyedia'!$K$10)*'Harga per Penyedia'!$M$10)/1000 | K14: Ubin & gambar-ulang TIDAK menambah biaya
A15: Search Box API (per sesi) | B15: ='Panggilan per Pesanan'!B19 | C15: ='Panggilan per Pesanan'!C19 | D15: ='Panggilan per Pesanan'!D19 | E15: =(MIN(MAX(0,'Panggilan per Pesanan'!B19-'Harga per Penyedia'!$D$11),'Harga per Penyedia'!$E$11)*'Harga per Penyedia'!$F$11+MAX(0,MIN(MAX(0,'Panggilan per Pesanan'!B19-'Harga per Penyedia'!$D$11),'Harga per Penyedia'!$G$11)-'Harga per Penyedia'!$E$11)*'Harga per Penyedia'!$H$11+MAX(0,MIN(MAX(0,'Panggilan per Pesanan'!B19-'Harga per Penyedia'!$D$11),'Harga per Penyedia'!$I$11)-'Harga per Penyedia'!$G$11)*'Harga per Penyedia'!$J$11+MAX(0,MIN(MAX(0,'Panggilan per Pesanan'!B19-'Harga per Penyedia'!$D$11),'Harga per Penyedia'!$K$11)-'Harga per Penyedia'!$I$11)*'Harga per Penyedia'!$L$11+MAX(0,MAX(0,'Panggilan per Pesanan'!B19-'Harga per Penyedia'!$D$11)-'Harga per Penyedia'!$K$11)*'Harga per Penyedia'!$M$11)/1000 | F15: =(MIN(MAX(0,'Panggilan per Pesanan'!C19-'Harga per Penyedia'!$D$11),'Harga per Penyedia'!$E$11)*'Harga per Penyedia'!$F$11+MAX(0,MIN(MAX(0,'Panggilan per Pesanan'!C19-'Harga per Penyedia'!$D$11),'Harga per Penyedia'!$G$11)-'Harga per Penyedia'!$E$11)*'Harga per Penyedia'!$H$11+MAX(0,MIN(MAX(0,'Panggilan per Pesanan'!C19-'Harga per Penyedia'!$D$11),'Harga per Penyedia'!$I$11)-'Harga per Penyedia'!$G$11)*'Harga per Penyedia'!$J$11+MAX(0,MIN(MAX(0,'Panggilan per Pesanan'!C19-'Harga per Penyedia'!$D$11),'Harga per Penyedia'!$K$11)-'Harga per Penyedia'!$I$11)*'Harga per Penyedia'!$L$11+MAX(0,MAX(0,'Panggilan per Pesanan'!C19-'Harga per Penyedia'!$D$11)-'Harga per Penyedia'!$K$11)*'Harga per Penyedia'!$M$11)/1000 | G15: =(MIN(MAX(0,'Panggilan per Pesanan'!D19-'Harga per Penyedia'!$D$11),'Harga per Penyedia'!$E$11)*'Harga per Penyedia'!$F$11+MAX(0,MIN(MAX(0,'Panggilan per Pesanan'!D19-'Harga per Penyedia'!$D$11),'Harga per Penyedia'!$G$11)-'Harga per Penyedia'!$E$11)*'Harga per Penyedia'!$H$11+MAX(0,MIN(MAX(0,'Panggilan per Pesanan'!D19-'Harga per Penyedia'!$D$11),'Harga per Penyedia'!$I$11)-'Harga per Penyedia'!$G$11)*'Harga per Penyedia'!$J$11+MAX(0,MIN(MAX(0,'Panggilan per Pesanan'!D19-'Harga per Penyedia'!$D$11),'Harga per Penyedia'!$K$11)-'Harga per Penyedia'!$I$11)*'Harga per Penyedia'!$L$11+MAX(0,MAX(0,'Panggilan per Pesanan'!D19-'Harga per Penyedia'!$D$11)-'Harga per Penyedia'!$K$11)*'Harga per Penyedia'!$M$11)/1000 | H15: =(MIN(MAX(0,'Panggilan per Pesanan'!E19-'Harga per Penyedia'!$D$11),'Harga per Penyedia'!$E$11)*'Harga per Penyedia'!$F$11+MAX(0,MIN(MAX(0,'Panggilan per Pesanan'!E19-'Harga per Penyedia'!$D$11),'Harga per Penyedia'!$G$11)-'Harga per Penyedia'!$E$11)*'Harga per Penyedia'!$H$11+MAX(0,MIN(MAX(0,'Panggilan per Pesanan'!E19-'Harga per Penyedia'!$D$11),'Harga per Penyedia'!$I$11)-'Harga per Penyedia'!$G$11)*'Harga per Penyedia'!$J$11+MAX(0,MIN(MAX(0,'Panggilan per Pesanan'!E19-'Harga per Penyedia'!$D$11),'Harga per Penyedia'!$K$11)-'Harga per Penyedia'!$I$11)*'Harga per Penyedia'!$L$11+MAX(0,MAX(0,'Panggilan per Pesanan'!E19-'Harga per Penyedia'!$D$11)-'Harga per Penyedia'!$K$11)*'Harga per Penyedia'!$M$11)/1000 | I15: =(MIN(MAX(0,'Panggilan per Pesanan'!F19-'Harga per Penyedia'!$D$11),'Harga per Penyedia'!$E$11)*'Harga per Penyedia'!$F$11+MAX(0,MIN(MAX(0,'Panggilan per Pesanan'!F19-'Harga per Penyedia'!$D$11),'Harga per Penyedia'!$G$11)-'Harga per Penyedia'!$E$11)*'Harga per Penyedia'!$H$11+MAX(0,MIN(MAX(0,'Panggilan per Pesanan'!F19-'Harga per Penyedia'!$D$11),'Harga per Penyedia'!$I$11)-'Harga per Penyedia'!$G$11)*'Harga per Penyedia'!$J$11+MAX(0,MIN(MAX(0,'Panggilan per Pesanan'!F19-'Harga per Penyedia'!$D$11),'Harga per Penyedia'!$K$11)-'Harga per Penyedia'!$I$11)*'Harga per Penyedia'!$L$11+MAX(0,MAX(0,'Panggilan per Pesanan'!F19-'Harga per Penyedia'!$D$11)-'Harga per Penyedia'!$K$11)*'Harga per Penyedia'!$M$11)/1000 | J15: =(MIN(MAX(0,'Panggilan per Pesanan'!G19-'Harga per Penyedia'!$D$11),'Harga per Penyedia'!$E$11)*'Harga per Penyedia'!$F$11+MAX(0,MIN(MAX(0,'Panggilan per Pesanan'!G19-'Harga per Penyedia'!$D$11),'Harga per Penyedia'!$G$11)-'Harga per Penyedia'!$E$11)*'Harga per Penyedia'!$H$11+MAX(0,MIN(MAX(0,'Panggilan per Pesanan'!G19-'Harga per Penyedia'!$D$11),'Harga per Penyedia'!$I$11)-'Harga per Penyedia'!$G$11)*'Harga per Penyedia'!$J$11+MAX(0,MIN(MAX(0,'Panggilan per Pesanan'!G19-'Harga per Penyedia'!$D$11),'Harga per Penyedia'!$K$11)-'Harga per Penyedia'!$I$11)*'Harga per Penyedia'!$L$11+MAX(0,MAX(0,'Panggilan per Pesanan'!G19-'Harga per Penyedia'!$D$11)-'Harga per Penyedia'!$K$11)*'Harga per Penyedia'!$M$11)/1000
A16: Directions API | B16: ='Panggilan per Pesanan'!B16 | C16: ='Panggilan per Pesanan'!C16 | D16: ='Panggilan per Pesanan'!D16 | E16: =(MIN(MAX(0,'Panggilan per Pesanan'!B16-'Harga per Penyedia'!$D$12),'Harga per Penyedia'!$E$12)*'Harga per Penyedia'!$F$12+MAX(0,MIN(MAX(0,'Panggilan per Pesanan'!B16-'Harga per Penyedia'!$D$12),'Harga per Penyedia'!$G$12)-'Harga per Penyedia'!$E$12)*'Harga per Penyedia'!$H$12+MAX(0,MIN(MAX(0,'Panggilan per Pesanan'!B16-'Harga per Penyedia'!$D$12),'Harga per Penyedia'!$I$12)-'Harga per Penyedia'!$G$12)*'Harga per Penyedia'!$J$12+MAX(0,MIN(MAX(0,'Panggilan per Pesanan'!B16-'Harga per Penyedia'!$D$12),'Harga per Penyedia'!$K$12)-'Harga per Penyedia'!$I$12)*'Harga per Penyedia'!$L$12+MAX(0,MAX(0,'Panggilan per Pesanan'!B16-'Harga per Penyedia'!$D$12)-'Harga per Penyedia'!$K$12)*'Harga per Penyedia'!$M$12)/1000 | F16: =(MIN(MAX(0,'Panggilan per Pesanan'!C16-'Harga per Penyedia'!$D$12),'Harga per Penyedia'!$E$12)*'Harga per Penyedia'!$F$12+MAX(0,MIN(MAX(0,'Panggilan per Pesanan'!C16-'Harga per Penyedia'!$D$12),'Harga per Penyedia'!$G$12)-'Harga per Penyedia'!$E$12)*'Harga per Penyedia'!$H$12+MAX(0,MIN(MAX(0,'Panggilan per Pesanan'!C16-'Harga per Penyedia'!$D$12),'Harga per Penyedia'!$I$12)-'Harga per Penyedia'!$G$12)*'Harga per Penyedia'!$J$12+MAX(0,MIN(MAX(0,'Panggilan per Pesanan'!C16-'Harga per Penyedia'!$D$12),'Harga per Penyedia'!$K$12)-'Harga per Penyedia'!$I$12)*'Harga per Penyedia'!$L$12+MAX(0,MAX(0,'Panggilan per Pesanan'!C16-'Harga per Penyedia'!$D$12)-'Harga per Penyedia'!$K$12)*'Harga per Penyedia'!$M$12)/1000 | G16: =(MIN(MAX(0,'Panggilan per Pesanan'!D16-'Harga per Penyedia'!$D$12),'Harga per Penyedia'!$E$12)*'Harga per Penyedia'!$F$12+MAX(0,MIN(MAX(0,'Panggilan per Pesanan'!D16-'Harga per Penyedia'!$D$12),'Harga per Penyedia'!$G$12)-'Harga per Penyedia'!$E$12)*'Harga per Penyedia'!$H$12+MAX(0,MIN(MAX(0,'Panggilan per Pesanan'!D16-'Harga per Penyedia'!$D$12),'Harga per Penyedia'!$I$12)-'Harga per Penyedia'!$G$12)*'Harga per Penyedia'!$J$12+MAX(0,MIN(MAX(0,'Panggilan per Pesanan'!D16-'Harga per Penyedia'!$D$12),'Harga per Penyedia'!$K$12)-'Harga per Penyedia'!$I$12)*'Harga per Penyedia'!$L$12+MAX(0,MAX(0,'Panggilan per Pesanan'!D16-'Harga per Penyedia'!$D$12)-'Harga per Penyedia'!$K$12)*'Harga per Penyedia'!$M$12)/1000 | H16: =(MIN(MAX(0,'Panggilan per Pesanan'!E16-'Harga per Penyedia'!$D$12),'Harga per Penyedia'!$E$12)*'Harga per Penyedia'!$F$12+MAX(0,MIN(MAX(0,'Panggilan per Pesanan'!E16-'Harga per Penyedia'!$D$12),'Harga per Penyedia'!$G$12)-'Harga per Penyedia'!$E$12)*'Harga per Penyedia'!$H$12+MAX(0,MIN(MAX(0,'Panggilan per Pesanan'!E16-'Harga per Penyedia'!$D$12),'Harga per Penyedia'!$I$12)-'Harga per Penyedia'!$G$12)*'Harga per Penyedia'!$J$12+MAX(0,MIN(MAX(0,'Panggilan per Pesanan'!E16-'Harga per Penyedia'!$D$12),'Harga per Penyedia'!$K$12)-'Harga per Penyedia'!$I$12)*'Harga per Penyedia'!$L$12+MAX(0,MAX(0,'Panggilan per Pesanan'!E16-'Harga per Penyedia'!$D$12)-'Harga per Penyedia'!$K$12)*'Harga per Penyedia'!$M$12)/1000 | I16: =(MIN(MAX(0,'Panggilan per Pesanan'!F16-'Harga per Penyedia'!$D$12),'Harga per Penyedia'!$E$12)*'Harga per Penyedia'!$F$12+MAX(0,MIN(MAX(0,'Panggilan per Pesanan'!F16-'Harga per Penyedia'!$D$12),'Harga per Penyedia'!$G$12)-'Harga per Penyedia'!$E$12)*'Harga per Penyedia'!$H$12+MAX(0,MIN(MAX(0,'Panggilan per Pesanan'!F16-'Harga per Penyedia'!$D$12),'Harga per Penyedia'!$I$12)-'Harga per Penyedia'!$G$12)*'Harga per Penyedia'!$J$12+MAX(0,MIN(MAX(0,'Panggilan per Pesanan'!F16-'Harga per Penyedia'!$D$12),'Harga per Penyedia'!$K$12)-'Harga per Penyedia'!$I$12)*'Harga per Penyedia'!$L$12+MAX(0,MAX(0,'Panggilan per Pesanan'!F16-'Harga per Penyedia'!$D$12)-'Harga per Penyedia'!$K$12)*'Harga per Penyedia'!$M$12)/1000 | J16: =(MIN(MAX(0,'Panggilan per Pesanan'!G16-'Harga per Penyedia'!$D$12),'Harga per Penyedia'!$E$12)*'Harga per Penyedia'!$F$12+MAX(0,MIN(MAX(0,'Panggilan per Pesanan'!G16-'Harga per Penyedia'!$D$12),'Harga per Penyedia'!$G$12)-'Harga per Penyedia'!$E$12)*'Harga per Penyedia'!$H$12+MAX(0,MIN(MAX(0,'Panggilan per Pesanan'!G16-'Harga per Penyedia'!$D$12),'Harga per Penyedia'!$I$12)-'Harga per Penyedia'!$G$12)*'Harga per Penyedia'!$J$12+MAX(0,MIN(MAX(0,'Panggilan per Pesanan'!G16-'Harga per Penyedia'!$D$12),'Harga per Penyedia'!$K$12)-'Harga per Penyedia'!$I$12)*'Harga per Penyedia'!$L$12+MAX(0,MAX(0,'Panggilan per Pesanan'!G16-'Harga per Penyedia'!$D$12)-'Harga per Penyedia'!$K$12)*'Harga per Penyedia'!$M$12)/1000
A17: TOTAL MAPBOX | E17: =SUM(E14:E16) | F17: =SUM(F14:F16) | G17: =SUM(G14:G16) | H17: =SUM(H14:H16) | I17: =SUM(I14:I16) | J17: =SUM(J14:J16)
A19: MAPTILER (paket Flex) — [S-14]; TIDAK menyediakan routing, perlu penyedia rute terpisah
A20: SKU / komponen | B20: Unit A | C20: Unit B | D20: Unit C | E20: Biaya A ($) | F20: Biaya B ($) | G20: Biaya C ($) | H20: Hemat A ($) | I20: Hemat B ($) | J20: Hemat C ($) | K20: Catatan
A21: Sesi peta | B21: ='Panggilan per Pesanan'!B17 | C21: ='Panggilan per Pesanan'!C17 | D21: ='Panggilan per Pesanan'!D17 | E21: =(MIN(MAX(0,'Panggilan per Pesanan'!B17-'Harga per Penyedia'!$D$14),'Harga per Penyedia'!$E$14)*'Harga per Penyedia'!$F$14+MAX(0,MIN(MAX(0,'Panggilan per Pesanan'!B17-'Harga per Penyedia'!$D$14),'Harga per Penyedia'!$G$14)-'Harga per Penyedia'!$E$14)*'Harga per Penyedia'!$H$14+MAX(0,MIN(MAX(0,'Panggilan per Pesanan'!B17-'Harga per Penyedia'!$D$14),'Harga per Penyedia'!$I$14)-'Harga per Penyedia'!$G$14)*'Harga per Penyedia'!$J$14+MAX(0,MIN(MAX(0,'Panggilan per Pesanan'!B17-'Harga per Penyedia'!$D$14),'Harga per Penyedia'!$K$14)-'Harga per Penyedia'!$I$14)*'Harga per Penyedia'!$L$14+MAX(0,MAX(0,'Panggilan per Pesanan'!B17-'Harga per Penyedia'!$D$14)-'Harga per Penyedia'!$K$14)*'Harga per Penyedia'!$M$14)/1000 | F21: =(MIN(MAX(0,'Panggilan per Pesanan'!C17-'Harga per Penyedia'!$D$14),'Harga per Penyedia'!$E$14)*'Harga per Penyedia'!$F$14+MAX(0,MIN(MAX(0,'Panggilan per Pesanan'!C17-'Harga per Penyedia'!$D$14),'Harga per Penyedia'!$G$14)-'Harga per Penyedia'!$E$14)*'Harga per Penyedia'!$H$14+MAX(0,MIN(MAX(0,'Panggilan per Pesanan'!C17-'Harga per Penyedia'!$D$14),'Harga per Penyedia'!$I$14)-'Harga per Penyedia'!$G$14)*'Harga per Penyedia'!$J$14+MAX(0,MIN(MAX(0,'Panggilan per Pesanan'!C17-'Harga per Penyedia'!$D$14),'Harga per Penyedia'!$K$14)-'Harga per Penyedia'!$I$14)*'Harga per Penyedia'!$L$14+MAX(0,MAX(0,'Panggilan per Pesanan'!C17-'Harga per Penyedia'!$D$14)-'Harga per Penyedia'!$K$14)*'Harga per Penyedia'!$M$14)/1000 | G21: =(MIN(MAX(0,'Panggilan per Pesanan'!D17-'Harga per Penyedia'!$D$14),'Harga per Penyedia'!$E$14)*'Harga per Penyedia'!$F$14+MAX(0,MIN(MAX(0,'Panggilan per Pesanan'!D17-'Harga per Penyedia'!$D$14),'Harga per Penyedia'!$G$14)-'Harga per Penyedia'!$E$14)*'Harga per Penyedia'!$H$14+MAX(0,MIN(MAX(0,'Panggilan per Pesanan'!D17-'Harga per Penyedia'!$D$14),'Harga per Penyedia'!$I$14)-'Harga per Penyedia'!$G$14)*'Harga per Penyedia'!$J$14+MAX(0,MIN(MAX(0,'Panggilan per Pesanan'!D17-'Harga per Penyedia'!$D$14),'Harga per Penyedia'!$K$14)-'Harga per Penyedia'!$I$14)*'Harga per Penyedia'!$L$14+MAX(0,MAX(0,'Panggilan per Pesanan'!D17-'Harga per Penyedia'!$D$14)-'Harga per Penyedia'!$K$14)*'Harga per Penyedia'!$M$14)/1000 | H21: =(MIN(MAX(0,'Panggilan per Pesanan'!E17-'Harga per Penyedia'!$D$14),'Harga per Penyedia'!$E$14)*'Harga per Penyedia'!$F$14+MAX(0,MIN(MAX(0,'Panggilan per Pesanan'!E17-'Harga per Penyedia'!$D$14),'Harga per Penyedia'!$G$14)-'Harga per Penyedia'!$E$14)*'Harga per Penyedia'!$H$14+MAX(0,MIN(MAX(0,'Panggilan per Pesanan'!E17-'Harga per Penyedia'!$D$14),'Harga per Penyedia'!$I$14)-'Harga per Penyedia'!$G$14)*'Harga per Penyedia'!$J$14+MAX(0,MIN(MAX(0,'Panggilan per Pesanan'!E17-'Harga per Penyedia'!$D$14),'Harga per Penyedia'!$K$14)-'Harga per Penyedia'!$I$14)*'Harga per Penyedia'!$L$14+MAX(0,MAX(0,'Panggilan per Pesanan'!E17-'Harga per Penyedia'!$D$14)-'Harga per Penyedia'!$K$14)*'Harga per Penyedia'!$M$14)/1000 | I21: =(MIN(MAX(0,'Panggilan per Pesanan'!F17-'Harga per Penyedia'!$D$14),'Harga per Penyedia'!$E$14)*'Harga per Penyedia'!$F$14+MAX(0,MIN(MAX(0,'Panggilan per Pesanan'!F17-'Harga per Penyedia'!$D$14),'Harga per Penyedia'!$G$14)-'Harga per Penyedia'!$E$14)*'Harga per Penyedia'!$H$14+MAX(0,MIN(MAX(0,'Panggilan per Pesanan'!F17-'Harga per Penyedia'!$D$14),'Harga per Penyedia'!$I$14)-'Harga per Penyedia'!$G$14)*'Harga per Penyedia'!$J$14+MAX(0,MIN(MAX(0,'Panggilan per Pesanan'!F17-'Harga per Penyedia'!$D$14),'Harga per Penyedia'!$K$14)-'Harga per Penyedia'!$I$14)*'Harga per Penyedia'!$L$14+MAX(0,MAX(0,'Panggilan per Pesanan'!F17-'Harga per Penyedia'!$D$14)-'Harga per Penyedia'!$K$14)*'Harga per Penyedia'!$M$14)/1000 | J21: =(MIN(MAX(0,'Panggilan per Pesanan'!G17-'Harga per Penyedia'!$D$14),'Harga per Penyedia'!$E$14)*'Harga per Penyedia'!$F$14+MAX(0,MIN(MAX(0,'Panggilan per Pesanan'!G17-'Harga per Penyedia'!$D$14),'Harga per Penyedia'!$G$14)-'Harga per Penyedia'!$E$14)*'Harga per Penyedia'!$H$14+MAX(0,MIN(MAX(0,'Panggilan per Pesanan'!G17-'Harga per Penyedia'!$D$14),'Harga per Penyedia'!$I$14)-'Harga per Penyedia'!$G$14)*'Harga per Penyedia'!$J$14+MAX(0,MIN(MAX(0,'Panggilan per Pesanan'!G17-'Harga per Penyedia'!$D$14),'Harga per Penyedia'!$K$14)-'Harga per Penyedia'!$I$14)*'Harga per Penyedia'!$L$14+MAX(0,MAX(0,'Panggilan per Pesanan'!G17-'Harga per Penyedia'!$D$14)-'Harga per Penyedia'!$K$14)*'Harga per Penyedia'!$M$14)/1000
A22: Sesi pencarian | B22: ='Panggilan per Pesanan'!B19 | C22: ='Panggilan per Pesanan'!C19 | D22: ='Panggilan per Pesanan'!D19 | E22: =(MIN(MAX(0,'Panggilan per Pesanan'!B19-'Harga per Penyedia'!$D$15),'Harga per Penyedia'!$E$15)*'Harga per Penyedia'!$F$15+MAX(0,MIN(MAX(0,'Panggilan per Pesanan'!B19-'Harga per Penyedia'!$D$15),'Harga per Penyedia'!$G$15)-'Harga per Penyedia'!$E$15)*'Harga per Penyedia'!$H$15+MAX(0,MIN(MAX(0,'Panggilan per Pesanan'!B19-'Harga per Penyedia'!$D$15),'Harga per Penyedia'!$I$15)-'Harga per Penyedia'!$G$15)*'Harga per Penyedia'!$J$15+MAX(0,MIN(MAX(0,'Panggilan per Pesanan'!B19-'Harga per Penyedia'!$D$15),'Harga per Penyedia'!$K$15)-'Harga per Penyedia'!$I$15)*'Harga per Penyedia'!$L$15+MAX(0,MAX(0,'Panggilan per Pesanan'!B19-'Harga per Penyedia'!$D$15)-'Harga per Penyedia'!$K$15)*'Harga per Penyedia'!$M$15)/1000 | F22: =(MIN(MAX(0,'Panggilan per Pesanan'!C19-'Harga per Penyedia'!$D$15),'Harga per Penyedia'!$E$15)*'Harga per Penyedia'!$F$15+MAX(0,MIN(MAX(0,'Panggilan per Pesanan'!C19-'Harga per Penyedia'!$D$15),'Harga per Penyedia'!$G$15)-'Harga per Penyedia'!$E$15)*'Harga per Penyedia'!$H$15+MAX(0,MIN(MAX(0,'Panggilan per Pesanan'!C19-'Harga per Penyedia'!$D$15),'Harga per Penyedia'!$I$15)-'Harga per Penyedia'!$G$15)*'Harga per Penyedia'!$J$15+MAX(0,MIN(MAX(0,'Panggilan per Pesanan'!C19-'Harga per Penyedia'!$D$15),'Harga per Penyedia'!$K$15)-'Harga per Penyedia'!$I$15)*'Harga per Penyedia'!$L$15+MAX(0,MAX(0,'Panggilan per Pesanan'!C19-'Harga per Penyedia'!$D$15)-'Harga per Penyedia'!$K$15)*'Harga per Penyedia'!$M$15)/1000 | G22: =(MIN(MAX(0,'Panggilan per Pesanan'!D19-'Harga per Penyedia'!$D$15),'Harga per Penyedia'!$E$15)*'Harga per Penyedia'!$F$15+MAX(0,MIN(MAX(0,'Panggilan per Pesanan'!D19-'Harga per Penyedia'!$D$15),'Harga per Penyedia'!$G$15)-'Harga per Penyedia'!$E$15)*'Harga per Penyedia'!$H$15+MAX(0,MIN(MAX(0,'Panggilan per Pesanan'!D19-'Harga per Penyedia'!$D$15),'Harga per Penyedia'!$I$15)-'Harga per Penyedia'!$G$15)*'Harga per Penyedia'!$J$15+MAX(0,MIN(MAX(0,'Panggilan per Pesanan'!D19-'Harga per Penyedia'!$D$15),'Harga per Penyedia'!$K$15)-'Harga per Penyedia'!$I$15)*'Harga per Penyedia'!$L$15+MAX(0,MAX(0,'Panggilan per Pesanan'!D19-'Harga per Penyedia'!$D$15)-'Harga per Penyedia'!$K$15)*'Harga per Penyedia'!$M$15)/1000 | H22: =(MIN(MAX(0,'Panggilan per Pesanan'!E19-'Harga per Penyedia'!$D$15),'Harga per Penyedia'!$E$15)*'Harga per Penyedia'!$F$15+MAX(0,MIN(MAX(0,'Panggilan per Pesanan'!E19-'Harga per Penyedia'!$D$15),'Harga per Penyedia'!$G$15)-'Harga per Penyedia'!$E$15)*'Harga per Penyedia'!$H$15+MAX(0,MIN(MAX(0,'Panggilan per Pesanan'!E19-'Harga per Penyedia'!$D$15),'Harga per Penyedia'!$I$15)-'Harga per Penyedia'!$G$15)*'Harga per Penyedia'!$J$15+MAX(0,MIN(MAX(0,'Panggilan per Pesanan'!E19-'Harga per Penyedia'!$D$15),'Harga per Penyedia'!$K$15)-'Harga per Penyedia'!$I$15)*'Harga per Penyedia'!$L$15+MAX(0,MAX(0,'Panggilan per Pesanan'!E19-'Harga per Penyedia'!$D$15)-'Harga per Penyedia'!$K$15)*'Harga per Penyedia'!$M$15)/1000 | I22: =(MIN(MAX(0,'Panggilan per Pesanan'!F19-'Harga per Penyedia'!$D$15),'Harga per Penyedia'!$E$15)*'Harga per Penyedia'!$F$15+MAX(0,MIN(MAX(0,'Panggilan per Pesanan'!F19-'Harga per Penyedia'!$D$15),'Harga per Penyedia'!$G$15)-'Harga per Penyedia'!$E$15)*'Harga per Penyedia'!$H$15+MAX(0,MIN(MAX(0,'Panggilan per Pesanan'!F19-'Harga per Penyedia'!$D$15),'Harga per Penyedia'!$I$15)-'Harga per Penyedia'!$G$15)*'Harga per Penyedia'!$J$15+MAX(0,MIN(MAX(0,'Panggilan per Pesanan'!F19-'Harga per Penyedia'!$D$15),'Harga per Penyedia'!$K$15)-'Harga per Penyedia'!$I$15)*'Harga per Penyedia'!$L$15+MAX(0,MAX(0,'Panggilan per Pesanan'!F19-'Harga per Penyedia'!$D$15)-'Harga per Penyedia'!$K$15)*'Harga per Penyedia'!$M$15)/1000 | J22: =(MIN(MAX(0,'Panggilan per Pesanan'!G19-'Harga per Penyedia'!$D$15),'Harga per Penyedia'!$E$15)*'Harga per Penyedia'!$F$15+MAX(0,MIN(MAX(0,'Panggilan per Pesanan'!G19-'Harga per Penyedia'!$D$15),'Harga per Penyedia'!$G$15)-'Harga per Penyedia'!$E$15)*'Harga per Penyedia'!$H$15+MAX(0,MIN(MAX(0,'Panggilan per Pesanan'!G19-'Harga per Penyedia'!$D$15),'Harga per Penyedia'!$I$15)-'Harga per Penyedia'!$G$15)*'Harga per Penyedia'!$J$15+MAX(0,MIN(MAX(0,'Panggilan per Pesanan'!G19-'Harga per Penyedia'!$D$15),'Harga per Penyedia'!$K$15)-'Harga per Penyedia'!$I$15)*'Harga per Penyedia'!$L$15+MAX(0,MAX(0,'Panggilan per Pesanan'!G19-'Harga per Penyedia'!$D$15)-'Harga per Penyedia'!$K$15)*'Harga per Penyedia'!$M$15)/1000
A23: Biaya tetap paket Flex | E23: ='Harga per Penyedia'!$F$16 | F23: ='Harga per Penyedia'!$F$16 | G23: ='Harga per Penyedia'!$F$16 | H23: ='Harga per Penyedia'!$F$16 | I23: ='Harga per Penyedia'!$F$16 | J23: ='Harga per Penyedia'!$F$16 | K23: $30/bulan; termasuk 25.000 sesi peta + 3.000 sesi pencarian
A24: TOTAL MAPTILER (belum termasuk routing) | E24: =SUM(E21:E23) | F24: =SUM(F21:F23) | G24: =SUM(G21:G23) | H24: =SUM(H21:H23) | I24: =SUM(I21:I23) | J24: =SUM(J21:J23)
A26: HERE — [S-15] sumber pihak ketiga (Agustus 2026); tarif routing [ASUMSI]
A27: SKU / komponen | B27: Unit A | C27: Unit B | D27: Unit C | E27: Biaya A ($) | F27: Biaya B ($) | G27: Biaya C ($) | H27: Hemat A ($) | I27: Hemat B ($) | J27: Hemat C ($) | K27: Catatan
A28: Geocoding & Search (autocomplete + reverse) | B28: ='Panggilan per Pesanan'!B14+'Panggilan per Pesanan'!B15 | C28: ='Panggilan per Pesanan'!C14+'Panggilan per Pesanan'!C15 | D28: ='Panggilan per Pesanan'!D14+'Panggilan per Pesanan'!D15 | E28: =(MIN(MAX(0,('Panggilan per Pesanan'!B14+'Panggilan per Pesanan'!B15)-'Harga per Penyedia'!$D$17),'Harga per Penyedia'!$E$17)*'Harga per Penyedia'!$F$17+MAX(0,MIN(MAX(0,('Panggilan per Pesanan'!B14+'Panggilan per Pesanan'!B15)-'Harga per Penyedia'!$D$17),'Harga per Penyedia'!$G$17)-'Harga per Penyedia'!$E$17)*'Harga per Penyedia'!$H$17+MAX(0,MIN(MAX(0,('Panggilan per Pesanan'!B14+'Panggilan per Pesanan'!B15)-'Harga per Penyedia'!$D$17),'Harga per Penyedia'!$I$17)-'Harga per Penyedia'!$G$17)*'Harga per Penyedia'!$J$17+MAX(0,MIN(MAX(0,('Panggilan per Pesanan'!B14+'Panggilan per Pesanan'!B15)-'Harga per Penyedia'!$D$17),'Harga per Penyedia'!$K$17)-'Harga per Penyedia'!$I$17)*'Harga per Penyedia'!$L$17+MAX(0,MAX(0,('Panggilan per Pesanan'!B14+'Panggilan per Pesanan'!B15)-'Harga per Penyedia'!$D$17)-'Harga per Penyedia'!$K$17)*'Harga per Penyedia'!$M$17)/1000 | F28: =(MIN(MAX(0,('Panggilan per Pesanan'!C14+'Panggilan per Pesanan'!C15)-'Harga per Penyedia'!$D$17),'Harga per Penyedia'!$E$17)*'Harga per Penyedia'!$F$17+MAX(0,MIN(MAX(0,('Panggilan per Pesanan'!C14+'Panggilan per Pesanan'!C15)-'Harga per Penyedia'!$D$17),'Harga per Penyedia'!$G$17)-'Harga per Penyedia'!$E$17)*'Harga per Penyedia'!$H$17+MAX(0,MIN(MAX(0,('Panggilan per Pesanan'!C14+'Panggilan per Pesanan'!C15)-'Harga per Penyedia'!$D$17),'Harga per Penyedia'!$I$17)-'Harga per Penyedia'!$G$17)*'Harga per Penyedia'!$J$17+MAX(0,MIN(MAX(0,('Panggilan per Pesanan'!C14+'Panggilan per Pesanan'!C15)-'Harga per Penyedia'!$D$17),'Harga per Penyedia'!$K$17)-'Harga per Penyedia'!$I$17)*'Harga per Penyedia'!$L$17+MAX(0,MAX(0,('Panggilan per Pesanan'!C14+'Panggilan per Pesanan'!C15)-'Harga per Penyedia'!$D$17)-'Harga per Penyedia'!$K$17)*'Harga per Penyedia'!$M$17)/1000 | G28: =(MIN(MAX(0,('Panggilan per Pesanan'!D14+'Panggilan per Pesanan'!D15)-'Harga per Penyedia'!$D$17),'Harga per Penyedia'!$E$17)*'Harga per Penyedia'!$F$17+MAX(0,MIN(MAX(0,('Panggilan per Pesanan'!D14+'Panggilan per Pesanan'!D15)-'Harga per Penyedia'!$D$17),'Harga per Penyedia'!$G$17)-'Harga per Penyedia'!$E$17)*'Harga per Penyedia'!$H$17+MAX(0,MIN(MAX(0,('Panggilan per Pesanan'!D14+'Panggilan per Pesanan'!D15)-'Harga per Penyedia'!$D$17),'Harga per Penyedia'!$I$17)-'Harga per Penyedia'!$G$17)*'Harga per Penyedia'!$J$17+MAX(0,MIN(MAX(0,('Panggilan per Pesanan'!D14+'Panggilan per Pesanan'!D15)-'Harga per Penyedia'!$D$17),'Harga per Penyedia'!$K$17)-'Harga per Penyedia'!$I$17)*'Harga per Penyedia'!$L$17+MAX(0,MAX(0,('Panggilan per Pesanan'!D14+'Panggilan per Pesanan'!D15)-'Harga per Penyedia'!$D$17)-'Harga per Penyedia'!$K$17)*'Harga per Penyedia'!$M$17)/1000 | H28: =(MIN(MAX(0,('Panggilan per Pesanan'!E14+'Panggilan per Pesanan'!E15)-'Harga per Penyedia'!$D$17),'Harga per Penyedia'!$E$17)*'Harga per Penyedia'!$F$17+MAX(0,MIN(MAX(0,('Panggilan per Pesanan'!E14+'Panggilan per Pesanan'!E15)-'Harga per Penyedia'!$D$17),'Harga per Penyedia'!$G$17)-'Harga per Penyedia'!$E$17)*'Harga per Penyedia'!$H$17+MAX(0,MIN(MAX(0,('Panggilan per Pesanan'!E14+'Panggilan per Pesanan'!E15)-'Harga per Penyedia'!$D$17),'Harga per Penyedia'!$I$17)-'Harga per Penyedia'!$G$17)*'Harga per Penyedia'!$J$17+MAX(0,MIN(MAX(0,('Panggilan per Pesanan'!E14+'Panggilan per Pesanan'!E15)-'Harga per Penyedia'!$D$17),'Harga per Penyedia'!$K$17)-'Harga per Penyedia'!$I$17)*'Harga per Penyedia'!$L$17+MAX(0,MAX(0,('Panggilan per Pesanan'!E14+'Panggilan per Pesanan'!E15)-'Harga per Penyedia'!$D$17)-'Harga per Penyedia'!$K$17)*'Harga per Penyedia'!$M$17)/1000 | I28: =(MIN(MAX(0,('Panggilan per Pesanan'!F14+'Panggilan per Pesanan'!F15)-'Harga per Penyedia'!$D$17),'Harga per Penyedia'!$E$17)*'Harga per Penyedia'!$F$17+MAX(0,MIN(MAX(0,('Panggilan per Pesanan'!F14+'Panggilan per Pesanan'!F15)-'Harga per Penyedia'!$D$17),'Harga per Penyedia'!$G$17)-'Harga per Penyedia'!$E$17)*'Harga per Penyedia'!$H$17+MAX(0,MIN(MAX(0,('Panggilan per Pesanan'!F14+'Panggilan per Pesanan'!F15)-'Harga per Penyedia'!$D$17),'Harga per Penyedia'!$I$17)-'Harga per Penyedia'!$G$17)*'Harga per Penyedia'!$J$17+MAX(0,MIN(MAX(0,('Panggilan per Pesanan'!F14+'Panggilan per Pesanan'!F15)-'Harga per Penyedia'!$D$17),'Harga per Penyedia'!$K$17)-'Harga per Penyedia'!$I$17)*'Harga per Penyedia'!$L$17+MAX(0,MAX(0,('Panggilan per Pesanan'!F14+'Panggilan per Pesanan'!F15)-'Harga per Penyedia'!$D$17)-'Harga per Penyedia'!$K$17)*'Harga per Penyedia'!$M$17)/1000 | J28: =(MIN(MAX(0,('Panggilan per Pesanan'!G14+'Panggilan per Pesanan'!G15)-'Harga per Penyedia'!$D$17),'Harga per Penyedia'!$E$17)*'Harga per Penyedia'!$F$17+MAX(0,MIN(MAX(0,('Panggilan per Pesanan'!G14+'Panggilan per Pesanan'!G15)-'Harga per Penyedia'!$D$17),'Harga per Penyedia'!$G$17)-'Harga per Penyedia'!$E$17)*'Harga per Penyedia'!$H$17+MAX(0,MIN(MAX(0,('Panggilan per Pesanan'!G14+'Panggilan per Pesanan'!G15)-'Harga per Penyedia'!$D$17),'Harga per Penyedia'!$I$17)-'Harga per Penyedia'!$G$17)*'Harga per Penyedia'!$J$17+MAX(0,MIN(MAX(0,('Panggilan per Pesanan'!G14+'Panggilan per Pesanan'!G15)-'Harga per Penyedia'!$D$17),'Harga per Penyedia'!$K$17)-'Harga per Penyedia'!$I$17)*'Harga per Penyedia'!$L$17+MAX(0,MAX(0,('Panggilan per Pesanan'!G14+'Panggilan per Pesanan'!G15)-'Harga per Penyedia'!$D$17)-'Harga per Penyedia'!$K$17)*'Harga per Penyedia'!$M$17)/1000
