Workbook

Sheet Asumsi
A1: Asumsi — aturan uang per layanan (service_economics) & parameter bisnis
A2: Biru = input (ubah di sini untuk simulasi; nilai produksi diubah di Panel Admin). Label per baris: FAKTA SUMBER / FAKTA KODE / ASUMSI.
A4: Tabel 1 — service_economics (nilai awal migrasi 0098 = nilai DB lokal 23 Sep 2026)
A5: Kunci layanan | B5: Layanan | C5: Komisi driver dari ongkir (%) | D5: Fee merchant / mitra (%) | E5: Biaya platform pelanggan (Rp/order) | F5: Jasa belanja (%) | G5: Jasa belanja minimum (Rp) | H5: Porsi driver dari jasa belanja (%) | I5: Kebijakan biaya PG | J5: Pemilik promo default | K5: Komisi lama pricing.commission_pct (%) | L5: Biaya platform lama pricing.platform_fee (Rp) | M5: Label | N5: Sumber
A6: ride_motor | B6: AntarRide Motor | C6: 0.08 | D6: 0 | E6: 1000 | F6: 0 | G6: 0 | H6: 0 | I6: platform | J6: platform | K6: 0.08 | L6: 1000 | M6: FAKTA SUMBER (komisi ≤ 8 %) · ASUMSI (biaya platform) | N6: Keputusan 23 Sep 2026 §0.2; pagar commission_cap_two_wheel (0031); 0098 baris ride_motor
A7: ride_car | B7: AntarRide Mobil | C7: 0.15 | D7: 0 | E7: 4000 | F7: 0 | G7: 0 | H7: 0 | I7: platform | J7: platform | K7: 0.2 | L7: 4000 | M7: ASUMSI | N7: 0098: komisi 15 % (roda empat tidak diatur cap 8 %); biaya platform = pricing lama
A8: food | B8: AntarFood | C8: 0 | D8: 0.15 | E8: 2000 | F8: 0 | G8: 0 | H8: 0 | I8: platform | J8: platform | K8: 0.2 | L8: 1000 | M8: FAKTA SUMBER (ongkir hak driver) · FAKTA KODE (fee 15 %) · ASUMSI (Rp2.000) | N8: Keputusan §0.1; pricing.merchant_commission_pct lama 15; 0098
A9: send | B9: AntarSend (Antar Barang) | C9: 0 | D9: 0 | E9: 3000 | F9: 0 | G9: 0 | H9: 0 | I9: platform | J9: platform | K9: 0.2 | L9: 1000 | M9: FAKTA SUMBER (ongkir hak driver) · ASUMSI (Rp3.000) | N9: Keputusan §0.1; 0098
A10: shop | B10: AntarShop | C10: 0 | D10: 0 | E10: 1000 | F10: 0.05 | G10: 5000 | H10: 0.7 | I10: platform | J10: platform | K10: 0.2 | L10: 1000 | M10: FAKTA SUMBER (ongkir) · FAKTA KODE (jasa 5 %/Rp5.000/70 %) · ASUMSI (Rp1.000) | N10: 0013 shop_service_pct/min, shop_driver_share_pct; 0098
A11: market | B11: AntarMarket | C11: 0 | D11: 0 | E11: 1000 | F11: 0.1 | G11: 8000 | H11: 0.7 | I11: platform | J11: platform | K11: 0.2 | L11: 1000 | M11: FAKTA SUMBER (ongkir) · FAKTA KODE (jasa 10 %/Rp8.000/70 %) · ASUMSI (Rp1.000) | N11: 0013 market_service_pct/min, market_driver_share_pct; 0098
A12: box | B12: AntarBox (kargo) | C12: 0.1 | D12: 0 | E12: 2000 | F12: 0 | G12: 0 | H12: 0 | I12: platform | J12: platform | K12: 0.2 | L12: 2000 | M12: ASUMSI | N12: 0098: kargo bukan penumpang — tidak tunduk cap roda dua
A13: travel | B13: AntarTravel (kursi/carter) | C13: 0 | D13: 0.1 | E13: 5000 | F13: 0 | G13: 0 | H13: 0 | I13: platform | J13: platform | K13: 0 | L13: 5000 | M13: FAKTA KODE | N13: travel_commission_pct 10 & travel_platform_fee 5.000 lama; 0098 (kolom komisi lama tidak berlaku: fee mitra 10 % sama)
A16: Tabel 2 — Parameter bisnis (app_settings / payment_channel_fees / ad_products)
A17: Kunci | B17: Parameter | C17: Nilai | D17: Satuan | E17: Label | F17: Sumber / tempat mengubah
A18: ppn_pct | B18: PPN atas biaya gateway (saluran yang tarifnya belum termasuk PPN) | C18: 0.11 | D18: % | E18: ASUMSI | F18: payment_channel_fees.ppn_pct (0100) — Panel Admin › Biaya Payment Gateway
A19: bonus_peak | B19: Bonus sesi driver jam sibuk (dari ongkir, dibatasi ≤ komisi) | C19: 0.05 | D19: % | E19: FAKTA KODE | F19: pricing_sessions "Jam sibuk pagi/sore" (0006); B = min(komisi, ongkir × bonus) — ledger_calc 0099
A20: travel_send_partner_pct | B20: Porsi mitra travel pada titipan antar kota | C20: 0.8 | D20: % | E20: FAKTA KODE | F20: app_settings.travel_send_partner_pct
A21: driver_debt_limit | B21: Batas saldo minus driver/mitra travel | C21: -500000 | D21: Rp | E21: ASUMSI | F21: app_settings.driver_debt_limit (0098/0104) — admin_set_settings (PIN)
A22: commission_cap_two_wheel | B22: Batas komisi roda dua (porsi driver ≥ 92 %) | C22: 0.08 | D22: % | E22: FAKTA SUMBER | F22: Keputusan 23 Sep 2026 §0.2 (acuan regulasi Sep 2026); 0031/0104
A23: take_rate_north_star_pct | B23: North-star take rate bersih portofolio matang (bukan target per order, bukan laba) | C23: 0.25 | D23: % | E23: FAKTA SUMBER | F23: Keputusan 23 Sep 2026 §0.5; app_settings (0103)
A24: gate_contribution_weeks | B24: Gerbang: minggu berturut-turut contribution > 0 | C24: 8 | D24: minggu | E24: FAKTA SUMBER | F24: Keputusan §7; app_settings (0104)
A25: gate_reconciliation_diff | B25: Gerbang: selisih rekonsiliasi | C25: 0 | D25: Rp | E25: FAKTA SUMBER | F25: Keputusan §6/§7; v_reconciliation_daily (0102)
A26: gate_payout_on_time_pct | B26: Gerbang: pencairan settled dalam SLA | C26: 0.95 | D26: % | E26: ASUMSI | F26: app_settings (0103)
A27: gate_retention_driver_pct | B27: Gerbang: retensi driver 30 hari | C27: 0.6 | D27: % | E27: ASUMSI | F27: app_settings (0103)
A28: gate_retention_merchant_pct | B28: Gerbang: retensi merchant 30 hari | C28: 0.7 | D28: % | E28: ASUMSI | F28: app_settings (0103)
A29: gate_refund_max_pct | B29: Gerbang: batas pesanan direfund | C29: 0.02 | D29: % | E29: ASUMSI | F29: app_settings (0103); plus 0 fraud_flags high terbuka
... A38: target_take_rate_pct_lama | B38: Target take rate LAMA (rekomendasi otomatis 0019) — masih aktif, berbeda dari north-star | C38: 0.18 | D38: % | E38: FAKTA KODE | F38: app_settings.target_take_rate_pct (0019) — Panel Admin › Otomasi; perlu diselaraskan
A40: Batasan data: angka FAKTA SUMBER diambil dari dokumen keputusan 23 Sep 2026, PKS Midtrans Ver.Aug-26 (M568767786_825925) dan kode migrasi 0098–0104; angka ASUMSI adalah usulan yang wajib diubah dari Panel Admin; belum ada HASIL PILOT. Volume & biaya tetap di sheet Bulanan adalah ILUSTRASI, bukan proyeksi. Uji silang memakai log DB lokal /tmp/antarkita-db-lokal/test-uji_skema_bisnis_v2.sql.log (23 Sep 2026), bukan data produksi.

Sheet Biaya PG
A1: Biaya payment gateway — PKS Midtrans Ver.Aug-26 (M568767786_825925, layanan Aggregator)
A3: Nominal transaksi (Rp) | B3: 100000 | C3: Ubah nominal untuk melihat biaya per saluran. Rumus = pg_fee_calc (0100): fee = ROUND(nominal × %) + tetap; PPN = 0 bila tarif sudah termasuk PPN, selain itu ROUND(fee × PPN).
A6: Kunci saluran | B6: Saluran | C6: Penyedia | D6: Fee (%) | E6: Fee tetap (Rp) | F6: Tarif termasuk PPN? | G6: PPN (%) | H6: Dana ditahan (H+n hari kalender) | I6: H+n khusus VA BSI/SeaBank | J6: Rujukan PKS | K6: Label | L6: Catatan | M6: Fee (Rp) | N6: PPN (Rp) | O6: Total biaya PG (Rp) | P6: Biaya efektif (%) | Q6: Dana bersih (Rp)
A7: bank_transfer | B7: Transfer bank (VA) | C7: midtrans | D7: 0 | E7: 4000 | F7: Tidak | G7: =Asumsi!$C$18 -> 0.11 | H7: 1 | I7: 2 | J7: Pasal 6 ayat 2 (VA Aggregator Rp4.000, tidak termasuk PPN); SOP B.6.a.i (VA H+1; BSI/SeaBank H+2) | K7: FAKTA SUMBER | L7: Mandiri/BNI/BRI/CIMB/Permata/Danamon/BCA/BSI/SeaBank | M7: =IF($B$3<=0,0,ROUND($B$3*D7,0)+E7) -> 4000 | N7: =IF(F7="Ya",0,ROUND(M7*G7,0)) -> 440 | O7: =M7+N7 -> 4440 | P7: =IF($B$3>0,O7/$B$3,0) -> 0.0444 | Q7: =$B$3-O7 -> 95560
A8: card | B8: Kartu kredit/debit | C8: midtrans | D8: 0.029 | E8: 2000 | F8: Tidak | G8: =Asumsi!$C$18 -> 0.11 | H8: 3 | J8: Pasal 6 ayat 2 (Transaksi Kartu Aggregator 2,9 % + Rp2.000); SOP B.6.a.i (H+3) | K8: FAKTA SUMBER | L8: Visa/MasterCard/JCB | M8: =IF($B$3<=0,0,ROUND($B$3*D8,0)+E8) -> 4900 | N8: =IF(F8="Ya",0,ROUND(M8*G8,0)) -> 539 | O8: =M8+N8 -> 5439 | P8: =IF($B$3>0,O8/$B$3,0) -> 0.05439 | Q8: =$B$3-O8 -> 94561
A9: gopay | B9: GoPay | C9: midtrans | D9: 0.02 | E9: 0 | F9: Ya | G9: =Asumsi!$C$18 -> 0.11 | H9: 1 | J9: Pasal 6 ayat 2 tabel E-Money GoPay non-digital 2 % (termasuk PPN); SOP B.6.a.i (H+1) | K9: FAKTA SUMBER | L9: Kategori digital 5 % — Midtrans berhak menentukan kategori | M9: =IF($B$3<=0,0,ROUND($B$3*D9,0)+E9) -> 2000 | N9: =IF(F9="Ya",0,ROUND(M9*G9,0)) -> 0 | O9: =M9+N9 -> 2000 | P9: =IF($B$3>0,O9/$B$3,0) -> 0.02 | Q9: =$B$3-O9 -> 98000
A10: shopeepay | B10: ShopeePay | C10: midtrans | D10: 0.02 | E10: 0 | F10: Ya | G10: =Asumsi!$C$18 -> 0.11 | H10: 2 | J10: Pasal 6 ayat 2 tabel E-Money ShopeePay non-digital 2 % (termasuk PPN); SOP B.6.a.i (H+2) | K10: FAKTA SUMBER | L10: Kategori digital 4 % | M10: =IF($B$3<=0,0,ROUND($B$3*D10,0)+E10) -> 2000 | N10: =IF(F10="Ya",0,ROUND(M10*G10,0)) -> 0 | O10: =M10+N10 -> 2000 | P10: =IF($B$3>0,O10/$B$3,0) -> 0.02 | Q10: =$B$3-O10 -> 98000
A11: qris | B11: QRIS | C11: midtrans | D11: 0.007 | E11: 0 | F11: Ya | G11: =Asumsi!$C$18 -> 0.11 | H11: 1 | J11: Pasal 6 ayat 2 tabel QRIS Reguler Umum 0,7 % (termasuk PPN); SOP B.6.a.i (H+1) | K11: FAKTA SUMBER | M11: =IF($B$3<=0,0,ROUND($B$3*D11,0)+E11) -> 700 | N11: =IF(F11="Ya",0,ROUND(M11*G11,0)) -> 0 | O11: =M11+N11 -> 700 | P11: =IF($B$3>0,O11/$B$3,0) -> 0.007 | Q11: =$B$3-O11 -> 99300
A12: dana | B12: DANA | C12: midtrans | D12: 0.015 | E12: 0 | F12: Tidak | G12: =Asumsi!$C$18 -> 0.11 | H12: 2 | J12: Pasal 6 ayat 2 (E-Money DANA 1,5 %, tidak termasuk PPN); SOP B.6.a.i (H+2) | K12: FAKTA SUMBER | M12: =IF($B$3<=0,0,ROUND($B$3*D12,0)+E12) -> 1500 | N12: =IF(F12="Ya",0,ROUND(M12*G12,0)) -> 165 | O12: =M12+N12 -> 1665 | P12: =IF($B$3>0,O12/$B$3,0) -> 0.01665 | Q12: =$B$3-O12 -> 98335
A13: ovo | B13: OVO | C13: midtrans | D13: 0.015 | E13: 0 | F13: Tidak | G13: =Asumsi!$C$18 -> 0.11 | H13: 5 | J13: Pasal 6 ayat 2 tabel OVO non-digital domestik 1,5 % (tidak termasuk PPN); SOP B.6.a.i "lainnya" H+5 | K13: FAKTA SUMBER | L13: Digital domestik 2,73 % | M13: =IF($B$3<=0,0,ROUND($B$3*D13,0)+E13) -> 1500 | N13: =IF(F13="Ya",0,ROUND(M13*G13,0)) -> 165 | O13: =M13+N13 -> 1665 | P13: =IF($B$3>0,O13/$B$3,0) -> 0.01665 | Q13: =$B$3-O13 -> 98335
A14: akulaku | B14: Akulaku PayLater | C14: midtrans | D14: 0.017 | E14: 0 | F14: Tidak | G14: =Asumsi!$C$18 -> 0.11 | H14: 5 | J14: Pasal 6 ayat 2 (1,7 %); SOP "lainnya" H+5 | K14: FAKTA SUMBER | L14: Belum dipakai aplikasi | M14: =IF($B$3<=0,0,ROUND($B$3*D14,0)+E14) -> 1700 | N14: =IF(F14="Ya",0,ROUND(M14*G14,0)) -> 187 | O14: =M14+N14 -> 1887 | P14: =IF($B$3>0,O14/$B$3,0) -> 0.01887 | Q14: =$B$3-O14 -> 98113
A15: kredivo | B15: Kredivo | C15: midtrans | D15: 0.02 | E15: 0 | F15: Tidak | G15: =Asumsi!$C$18 -> 0.11 | H15: 2 | J15: Pasal 6 ayat 2 (2 %; teks PKS terpotong "Kdi/revo"); SOP B.6.a.i (H+2) | K15: FAKTA SUMBER | L15: Belum dipakai aplikasi | M15: =IF($B$3<=0,0,ROUND($B$3*D15,0)+E15) -> 2000 | N15: =IF(F15="Ya",0,ROUND(M15*G15,0)) -> 220 | O15: =M15+N15 -> 2220 | P15: =IF($B$3>0,O15/$B$3,0) -> 0.0222 | Q15: =$B$3-O15 -> 97780
A16: alfamart | B16: Alfamart | C16: midtrans | D16: 0 | E16: 5000 | F16: Tidak | G16: =Asumsi!$C$18 -> 0.11 | H16: 5 | J16: Pasal 6 ayat 2 (OTC Alfamart Rp5.000); SOP "lainnya" H+5 | K16: FAKTA SUMBER | L16: Belum dipakai aplikasi | M16: =IF($B$3<=0,0,ROUND($B$3*D16,0)+E16) -> 5000 | N16: =IF(F16="Ya",0,ROUND(M16*G16,0)) -> 550 | O16: =M16+N16 -> 5550 | P16: =IF($B$3>0,O16/$B$3,0) -> 0.0555 | Q16: =$B$3-O16 -> 94450
A17: indomaret | B17: Indomaret | C17: midtrans | D17: 0 | E17: 1000 | F17: Tidak | G17: =Asumsi!$C$18 -> 0.11 | H17: 5 | J17: Pasal 6 ayat 2 (Partner Fee + Rp1.000); SOP "lainnya" H+5 | K17: FAKTA SUMBER + ASUMSI | L17: Partner fee Indomaret TIDAK tercantum di PKS — hanya Rp1.000 bagian Midtrans | M17: =IF($B$3<=0,0,ROUND($B$3*D17,0)+E17) -> 1000 | N17: =IF(F17="Ya",0,ROUND(M17*G17,0)) -> 110 | O17: =M17+N17 -> 1110 | P17: =IF($B$3>0,O17/$B$3,0) -> 0.0111 | Q17: =$B$3-O17 -> 98890
A18: cash | B18: Tunai/COD | C18: internal | D18: 0 | E18: 0 | F18: Ya | G18: =Asumsi!$C$18 -> 0.11 | H18: 0 | J18: Bukan gateway | K18: FAKTA KODE | L18: Tidak ada biaya PG | M18: =IF($B$3<=0,0,ROUND($B$3*D18,0)+E18) -> 0 | N18: =IF(F18="Ya",0,ROUND(M18*G18,0)) -> 0 | O18: =M18+N18 -> 0 | P18: =IF($B$3>0,O18/$B$3,0) -> 0 | Q18: =$B$3-O18 -> 100000
A19: antarpay | B19: AntarPay (saldo) | C19: internal | D19: 0 | E19: 0 | F19: Ya | G19: =Asumsi!$C$18 -> 0.11 | H19: 0 | J19: Bukan gateway | K19: FAKTA KODE | L19: Biaya top up dicatat terpisah di wallet_transactions.pg_fee | M19: =IF($B$3<=0,0,ROUND($B$3*D19,0)+E19) -> 0 | N19: =IF(F19="Ya",0,ROUND(M19*G19,0)) -> 0 | O19: =M19+N19 -> 0 | P19: =IF($B$3>0,O19/$B$3,0) -> 0 | Q19: =$B$3-O19 -> 100000
A20: emoney_nfc | B20: E-money (kartu NFC) | C20: internal | D20: 0 | E20: 0 | F20: Ya | G20: =Asumsi!$C$18 -> 0.11 | H20: 0 | J20: Bukan gateway | K20: FAKTA KODE | L20: Tidak ada biaya PG | M20: =IF($B$3<=0,0,ROUND($B$3*D20,0)+E20) -> 0 | N20: =IF(F20="Ya",0,ROUND(M20*G20,0)) -> 0 | O20: =M20+N20 -> 0 | P20: =IF($B$3>0,O20/$B$3,0) -> 0 | Q20: =$B$3-O20 -> 100000
A22: Pasal 6 ayat 3: biaya di atas belum termasuk biaya administrasi bank dan pajak sesuai hukum yang berlaku.
A23: SOP B.6.a.i: dana ditahan di rekening Midtrans H+n hari KALENDER sejak transaksi; B.6.a.iii: pencairan otomatis bila dana tertampung ≥ Rp50.000 (MAP); B.6.a.iv: permintaan sebelum 11:00 diproses hari kerja yang sama.
A24: Pasal 7 ayat 4(b): fitur uang elektronik/dompet elektronik yang butuh izin BI tanpa izin → Midtrans berhak menghentikan layanan tanpa batas waktu. Karena itu AntarPay top up harus NONAKTIF sampai review legal.
A25: Tarif GoPay/ShopeePay/QRIS termasuk PPN (tabel "termasuk PPN"); tarif lain "tidak termasuk PPN" → PPN 11 % [ASUMSI tarif efektif, konfirmasi konsultan pajak].
A27: Batasan data: angka FAKTA SUMBER diambil dari dokumen keputusan 23 Sep 2026, PKS Midtrans Ver.Aug-26 (M568767786_825925) dan kode migrasi 0098–0104; angka ASUMSI adalah usulan yang wajib diubah dari Panel Admin; belum ada HASIL PILOT. Volume & biaya tetap di sheet Bulanan adalah ILUSTRASI, bukan proyeksi. Uji silang memakai log DB lokal /tmp/antarkita-db-lokal/test-uji_skema_bisnis_v2.sql.log (23 Sep 2026), bukan data produksi.

Sheet Per Layanan
A1: Per Layanan — alokasi satu order, mencerminkan ledger_calc (0099) baris demi baris
A2: Setiap blok = satu layanan. Ubah sel biru (input). Baris hitam = rumus ledger. Blok "UJI SILANG" memakai input persis skenario log uji — jangan diubah; kolom Selisih harus 0.
A3: Ringkasan per layanan (dari blok di bawah) — termasuk dampak ke driver v1 (komisi lama) vs v2
A4: Layanan | B4: Total pelanggan (Rp) | C4: Ongkir (Rp) | D4: driver_payable (Rp) | E4: Porsi driver dari ongkir | F4: Driver dari ongkir v1 komisi lama (Rp) | G4: Driver dari ongkir v2 (Rp) | H4: Δ driver v2 − v1 (Rp) | I4: merchant_payable (Rp) | J4: platform_revenue (Rp) | K4: Biaya PG platform (Rp) | L4: Contribution (Rp) | M4: Take rate bersih order
A5: ride_motor | B5: =$B$63 -> 8000 | C5: =$B$28 -> 7000 | D5: =$B$66 -> 6440 | E5: =$B$81 -> 0.92 | F5: =IF($B$48=1,0,$B$28-INT(ROUND($B$28*INDEX(Asumsi!$K$6:$K$13,MATCH($A5,Asumsi!$A$6:$A$13,0)),6))+MIN(INT(ROUND($B$28*INDEX(Asumsi!$K$6:$K$13,MATCH($A5,Asumsi!$A$6:$A$13,0)),6)),INT(ROUND($B$28*$B$36,6)))) -> 6440 | G5: =IF($B$48=1,0,$B$28-$B$53+$B$54) -> 6440 | H5: =G5-F5 -> 0 | I5: =$B$67 -> 0 | J5: =$B$71 -> 1560 | K5: =$B$74 -> 0 | L5: =$B$75 -> 1560 | M5: =$B$80 -> 0.22285714
A6: ride_car | B6: =$B$123 -> 26000 | C6: =$B$88 -> 22000 | D6: =$B$126 -> 18700 | E6: =$B$141 -> 0.85 | F6: =IF($B$108=1,0,$B$88-INT(ROUND($B$88*INDEX(Asumsi!$K$6:$K$13,MATCH($A6,Asumsi!$A$6:$A$13,0)),6))+MIN(INT(ROUND($B$88*INDEX(Asumsi!$K$6:$K$13,MATCH($A6,Asumsi!$A$6:$A$13,0)),6)),INT(ROUND($B$88*$B$96,6)))) -> 17600 | G6: =IF($B$108=1,0,$B$88-$B$113+$B$114) -> 18700 | H6: =G6-F6 -> 1100 | I6: =$B$127 -> 0 | J6: =$B$131 -> 7300 | K6: =$B$134 -> 0 | L6: =$B$135 -> 7300 | M6: =$B$140 -> 0.33181818
A7: food | B7: =$B$183 -> 70000 | C7: =$B$148 -> 8000 | D7: =$B$186 -> 8000 | E7: =$B$201 -> 1 | F7: =IF($B$168=1,0,$B$148-INT(ROUND($B$148*INDEX(Asumsi!$K$6:$K$13,MATCH($A7,Asumsi!$A$6:$A$13,0)),6))+MIN(INT(ROUND($B$148*INDEX(Asumsi!$K$6:$K$13,MATCH($A7,Asumsi!$A$6:$A$13,0)),6)),INT(ROUND($B$148*$B$156,6)))) -> 6400 | G7: =IF($B$168=1,0,$B$148-$B$173+$B$174) -> 8000 | H7: =G7-F7 -> 1600 | I7: =$B$187 -> 51000 | J7: =$B$191 -> 11000 | K7: =$B$194 -> 490 | L7: =$B$195 -> 10510 | M7: =$B$200 -> 0.16176471
A8: send | B8: =$B$243 -> 11000 | C8: =$B$208 -> 8000 | D8: =$B$246 -> 8000 | E8: =$B$261 -> 1 | F8: =IF($B$228=1,0,$B$208-INT(ROUND($B$208*INDEX(Asumsi!$K$6:$K$13,MATCH($A8,Asumsi!$A$6:$A$13,0)),6))+MIN(INT(ROUND($B$208*INDEX(Asumsi!$K$6:$K$13,MATCH($A8,Asumsi!$A$6:$A$13,0)),6)),INT(ROUND($B$208*$B$216,6)))) -> 6400 | G8: =IF($B$228=1,0,$B$208-$B$233+$B$234) -> 8000 | H8: =G8-F8 -> 1600 | I8: =$B$247 -> 0 | J8: =$B$251 -> 3000 | K8: =$B$254 -> 0 | L8: =$B$255 -> 3000 | M8: =$B$260 -> 0.375
A9: shop | B9: =$B$303 -> 166450 | C9: =$B$268 -> 9000 | D9: =$B$306 -> 14215 | E9: =$B$321 -> 1 | F9: =IF($B$288=1,0,$B$268-INT(ROUND($B$268*INDEX(Asumsi!$K$6:$K$13,MATCH($A9,Asumsi!$A$6:$A$13,0)),6))+MIN(INT(ROUND($B$268*INDEX(Asumsi!$K$6:$K$13,MATCH($A9,Asumsi!$A$6:$A$13,0)),6)),INT(ROUND($B$268*$B$276,6)))) -> 7200 | G9: =IF($B$288=1,0,$B$268-$B$293+$B$294) -> 9000 | H9: =G9-F9 -> 1800 | I9: =$B$307 -> 0 | J9: =$B$311 -> 3235 | K9: =$B$314 -> 0 | L9: =$B$315 -> 3235 | M9: =$B$320 -> 0.020474684
A10: market | B10: =$B$363 -> 49000 | C10: =$B$328 -> 11000 | D10: =$B$366 -> 16600 | E10: =$B$381 -> 1 | F10: =IF($B$348=1,0,$B$328-INT(ROUND($B$328*INDEX(Asumsi!$K$6:$K$13,MATCH($A10,Asumsi!$A$6:$A$13,0)),6))+MIN(INT(ROUND($B$328*INDEX(Asumsi!$K$6:$K$13,MATCH($A10,Asumsi!$A$6:$A$13,0)),6)),INT(ROUND($B$328*$B$336,6)))) -> 8800 | G10: =IF($B$348=1,0,$B$328-$B$353+$B$354) -> 11000 | H10: =G10-F10 -> 2200 | I10: =$B$367 -> 0 | J10: =$B$371 -> 3400 | K10: =$B$374 -> 0 | L10: =$B$375 -> 3400 | M10: =$B$380 -> 0.085
A11: box | B11: =$B$423 -> 115000 | C11: =$B$388 -> 113000 | D11: =$B$426 -> 101700 | E11: =$B$441 -> 0.9 | F11: =IF($B$408=1,0,$B$388-INT(ROUND($B$388*INDEX(Asumsi!$K$6:$K$13,MATCH($A11,Asumsi!$A$6:$A$13,0)),6))+MIN(INT(ROUND($B$388*INDEX(Asumsi!$K$6:$K$13,MATCH($A11,Asumsi!$A$6:$A$13,0)),6)),INT(ROUND($B$388*$B$396,6)))) -> 90400 | G11: =IF($B$408=1,0,$B$388-$B$413+$B$414) -> 101700 | H11: =G11-F11 -> 11300 | I11: =$B$427 -> 0 | J11: =$B$431 -> 13300 | K11: =$B$434 -> 0 | L11: =$B$435 -> 13300 | M11: =$B$440 -> 0.11769912
A12: travel | B12: =$B$483 -> 305000 | C12: =$B$448 -> 300000 | D12: =$B$486 -> 0 | E12: =$B$501 -> 0 | F12: =IF($B$468=1,0,$B$448-INT(ROUND($B$448*INDEX(Asumsi!$K$6:$K$13,MATCH($A12,Asumsi!$A$6:$A$13,0)),6))+MIN(INT(ROUND($B$448*INDEX(Asumsi!$K$6:$K$13,MATCH($A12,Asumsi!$A$6:$A$13,0)),6)),INT(ROUND($B$448*$B$456,6)))) -> 0 | G12: =IF($B$468=1,0,$B$448-$B$473+$B$474) -> 0 | H12: =G12-F12 -> 0 | I12: =$B$487 -> 0 | J12: =$B$491 -> 35000 | K12: =$B$494 -> 0 | L12: =$B$495 -> 35000 | M12: =$B$500 -> 0.11666667
A14: Status uji silang terhadap log DB lokal (harus 0 / LULUS)
A15: Blok uji silang | B15: Σ |Selisih| (Rp) | C15: Cek keseimbangan | D15: Status
A16: UJI SILANG 1 — S13 ride_motor tunai, promo platform V2PLATFORM | B16: =SUM(F507:F562) -> 0 | C16: =$B$562 -> 0 | D16: =IF(AND(B16=0,C16=0),"LULUS","CEK") -> LULUS
A17: UJI SILANG 2 — S21 food saldo, promo merchant V2MERCHANT | B17: =SUM(F567:F622) -> 0 | C17: =$B$622 -> 0 | D17: =IF(AND(B17=0,C17=0),"LULUS","CEK") -> LULUS
A18: UJI SILANG 3 — S26 shop tunai tanpa promo | B18: =SUM(F627:F682) -> 0 | C18: =$B$682 -> 0 | D18: =IF(AND(B18=0,C18=0),"LULUS","CEK") -> LULUS
A19: UJI SILANG 4 — S45 ride_car kartu, biaya PG ditanggung pelanggan | B19: =SUM(F687:F742) -> 0 | C19: =$B$742 -> 0 | D19: =IF(AND(B19=0,C19=0),"LULUS","CEK") -> LULUS
A20: UJI SILANG 5 — S61 send VA BSI (biaya PG ditanggung platform) | B20: =SUM(F747:F802) -> 0 | C20: =$B$802 -> 0 | D20: =IF(AND(B20=0,C20=0),"LULUS","CEK") -> LULUS
A21: UJI SILANG 6 — S48a travel kursi saldo | B21: =SUM(F807:F862) -> 0 | C21: =$B$862 -> 0 | D21: =IF(AND(B21=0,C21=0),"LULUS","CEK") -> LULUS
A22: Total seluruh uji silang | B22: =SUM(B16:B21) -> 0 | C22: =SUMPRODUCT(ABS(C16:C21)) -> 0 | D22: =IF(AND(B22=0,C22=0),"LULUS","CEK") -> LULUS
A25: BLOK ride_motor — AntarRide Motor
A26: Baris | B26: Nilai | C26: Entri ledger / keterangan | D26: Nilai log uji | E26: Selisih | F26: |Selisih|
A27: Kunci layanan | B27: ride_motor | C27: service_type
A28: Ongkir / tarif jasa (travel: harga kursi/carter dasar) (Rp) | B28: 7000 | C28: delivery_fee / intercity_fare
A29: Nilai barang (subtotal) (Rp) | B29: 0 | C29: items_subtotal — hanya food/shop/market
A30: Promo diminta (Rp) | B30: 0 | C30: discount (dibatasi ≤ ongkir + barang food)
A31: Pemilik biaya promo (kosong = default layanan) | C31: promos.funded_by
A32: Saluran bayar | B32: cash | C32: pg_channel (cash = tunai)
A33: Bank VA (bsi/seabank untuk H+2; boleh kosong) | C33: hold_days_by_bank
A34: Tip (Rp) | B34: 0 | C34: tip
A35: Extras (Rp) | B35: 0 | C35: extras
A36: Bonus sesi driver (% ongkir; 0 = jam normal) | B36: 0 | C36: pricing_sessions.driver_bonus_pct
A37: Kebijakan biaya PG (kosong = dari Asumsi) | C37: pg_fee_policy
A38: Komisi driver (%) | B38: =INDEX(Asumsi!$C$6:$C$13,MATCH($B$27,Asumsi!$A$6:$A$13,0)) -> 0.08 | C38: driver_commission_pct_snap
A39: Fee merchant / mitra (%) | B39: =INDEX(Asumsi!$D$6:$D$13,MATCH($B$27,Asumsi!$A$6:$A$13,0)) -> 0 | C39: merchant_fee_pct_snap
A40: Biaya platform pelanggan (Rp) | B40: =INDEX(Asumsi!$E$6:$E$13,MATCH($B$27,Asumsi!$A$6:$A$13,0)) -> 1000 | C40: customer_platform_fee
A41: Jasa belanja (%) | B41: =INDEX(Asumsi!$F$6:$F$13,MATCH($B$27,Asumsi!$A$6:$A$13,0)) -> 0 | C41: service_fee_pct
A42: Jasa belanja minimum (Rp) | B42: =INDEX(Asumsi!$G$6:$G$13,MATCH($B$27,Asumsi!$A$6:$A$13,0)) -> 0 | C42: service_fee_min
A43: Porsi driver jasa belanja (%) | B43: =INDEX(Asumsi!$H$6:$H$13,MATCH($B$27,Asumsi!$A$6:$A$13,0)) -> 0 | C43: service_fee_driver_share_pct
...

Sheet Bulanan
A1: Bulanan — volume × unit economics per kota → GMV bersih, pendapatan per sumber, take rate bersih, contribution, EBITDA kota, gerbang
A2: Unit per order diambil dari blok Per Layanan (order tipikal). Volume, % digital, iklan, variable_ops & biaya tetap = ILUSTRASI yang WAJIB diganti. Sel kuning = isi.
A4: Saluran digital acuan (untuk biaya PG bagian order digital) | C4: qris
A6: A. Unit per order (link ke Per Layanan)
A7: Layanan | B7: GMV bersih/order | C7: Biaya platform pelanggan | D7: Komisi driver (kotor) | E7: Insentif (bonus sesi) | F7: Fee merchant/mitra | G7: Jasa belanja bagian platform | H7: Promo platform | I7: Total dasar | J7: Kebijakan PG | K7: Biaya PG/order digital (acuan) | L7: driver_payable | M7: revenue_net
A8: ride_motor | B8: ='Per Layanan'!$B$79 -> 7000 | C8: ='Per Layanan'!$B$40 -> 1000 | D8: ='Per Layanan'!$B$53 -> 560 | E8: ='Per Layanan'!$B$54 -> 0 | F8: ='Per Layanan'!$B$55 -> 0 | G8: ='Per Layanan'!$B$70 -> 0 | H8: ='Per Layanan'!$B$58 -> 0 | I8: ='Per Layanan'!$B$59 -> 8000 | J8: ='Per Layanan'!$B$44 -> platform | K8: =IF(OR(J8<>"platform",A8="travel",I8<=0),0,IFERROR(ROUND(I8*INDEX('Biaya PG'!$D$7:$D$20,MATCH($C$4,'Biaya PG'!$A$7:$A$20,0)),0)+INDEX('Biaya PG'!$E$7:$E$20,MATCH($C$4,'Biaya PG'!$A$7:$A$20,0)),0)+IF(INDEX('Biaya PG'!$F$7:$F$20,MATCH($C$4,'Biaya PG'!$A$7:$A$20,0))="Ya",0,ROUND(IFERROR(ROUND(I8*INDEX('Biaya PG'!$D$7:$D$20,MATCH($C$4,'Biaya PG'!$A$7:$A$20,0)),0)+INDEX('Biaya PG'!$E$7:$E$20,MATCH($C$4,'Biaya PG'!$A$7:$A$20,0)),0)*INDEX('Biaya PG'!$G$7:$G$20,MATCH($C$4,'Biaya PG'!$A$7:$A$20,0)),0))) -> 56 | L8: ='Per Layanan'!$B$66 -> 6440 | M8: ='Per Layanan'!$B$72 -> 1560
A9: ride_car | B9: ='Per Layanan'!$B$139 -> 22000 | C9: ='Per Layanan'!$B$100 -> 4000 | D9: ='Per Layanan'!$B$113 -> 3300 | E9: ='Per Layanan'!$B$114 -> 0 | F9: ='Per Layanan'!$B$115 -> 0 | G9: ='Per Layanan'!$B$130 -> 0 | H9: ='Per Layanan'!$B$118 -> 0 | I9: ='Per Layanan'!$B$119 -> 26000 | J9: ='Per Layanan'!$B$104 -> platform | K9: =IF(OR(J9<>"platform",A9="travel",I9<=0),0,IFERROR(ROUND(I9*INDEX('Biaya PG'!$D$7:$D$20,MATCH($C$4,'Biaya PG'!$A$7:$A$20,0)),0)+INDEX('Biaya PG'!$E$7:$E$20,MATCH($C$4,'Biaya PG'!$A$7:$A$20,0)),0)+IF(INDEX('Biaya PG'!$F$7:$F$20,MATCH($C$4,'Biaya PG'!$A$7:$A$20,0))="Ya",0,ROUND(IFERROR(ROUND(I9*INDEX('Biaya PG'!$D$7:$D$20,MATCH($C$4,'Biaya PG'!$A$7:$A$20,0)),0)+INDEX('Biaya PG'!$E$7:$E$20,MATCH($C$4,'Biaya PG'!$A$7:$A$20,0)),0)*INDEX('Biaya PG'!$G$7:$G$20,MATCH($C$4,'Biaya PG'!$A$7:$A$20,0)),0))) -> 182 | L9: ='Per Layanan'!$B$126 -> 18700 | M9: ='Per Layanan'!$B$132 -> 7300
A10: food | B10: ='Per Layanan'!$B$199 -> 68000 | C10: ='Per Layanan'!$B$160 -> 2000 | D10: ='Per Layanan'!$B$173 -> 0 | E10: ='Per Layanan'!$B$174 -> 0 | F10: ='Per Layanan'!$B$175 -> 9000 | G10: ='Per Layanan'!$B$190 -> 0 | H10: ='Per Layanan'!$B$178 -> 0 | I10: ='Per Layanan'!$B$179 -> 70000 | J10: ='Per Layanan'!$B$164 -> platform | K10: =IF(OR(J10<>"platform",A10="travel",I10<=0),0,IFERROR(ROUND(I10*INDEX('Biaya PG'!$D$7:$D$20,MATCH($C$4,'Biaya PG'!$A$7:$A$20,0)),0)+INDEX('Biaya PG'!$E$7:$E$20,MATCH($C$4,'Biaya PG'!$A$7:$A$20,0)),0)+IF(INDEX('Biaya PG'!$F$7:$F$20,MATCH($C$4,'Biaya PG'!$A$7:$A$20,0))="Ya",0,ROUND(IFERROR(ROUND(I10*INDEX('Biaya PG'!$D$7:$D$20,MATCH($C$4,'Biaya PG'!$A$7:$A$20,0)),0)+INDEX('Biaya PG'!$E$7:$E$20,MATCH($C$4,'Biaya PG'!$A$7:$A$20,0)),0)*INDEX('Biaya PG'!$G$7:$G$20,MATCH($C$4,'Biaya PG'!$A$7:$A$20,0)),0))) -> 490 | L10: ='Per Layanan'!$B$186 -> 8000 | M10: ='Per Layanan'!$B$192 -> 11000
A11: send | B11: ='Per Layanan'!$B$259 -> 8000 | C11: ='Per Layanan'!$B$220 -> 3000 | D11: ='Per Layanan'!$B$233 -> 0 | E11: ='Per Layanan'!$B$234 -> 0 | F11: ='Per Layanan'!$B$235 -> 0 | G11: ='Per Layanan'!$B$250 -> 0 | H11: ='Per Layanan'!$B$238 -> 0 | I11: ='Per Layanan'!$B$239 -> 11000 | J11: ='Per Layanan'!$B$224 -> platform | K11: =IF(OR(J11<>"platform",A11="travel",I11<=0),0,IFERROR(ROUND(I11*INDEX('Biaya PG'!$D$7:$D$20,MATCH($C$4,'Biaya PG'!$A$7:$A$20,0)),0)+INDEX('Biaya PG'!$E$7:$E$20,MATCH($C$4,'Biaya PG'!$A$7:$A$20,0)),0)+IF(INDEX('Biaya PG'!$F$7:$F$20,MATCH($C$4,'Biaya PG'!$A$7:$A$20,0))="Ya",0,ROUND(IFERROR(ROUND(I11*INDEX('Biaya PG'!$D$7:$D$20,MATCH($C$4,'Biaya PG'!$A$7:$A$20,0)),0)+INDEX('Biaya PG'!$E$7:$E$20,MATCH($C$4,'Biaya PG'!$A$7:$A$20,0)),0)*INDEX('Biaya PG'!$G$7:$G$20,MATCH($C$4,'Biaya PG'!$A$7:$A$20,0)),0))) -> 77 | L11: ='Per Layanan'!$B$246 -> 8000 | M11: ='Per Layanan'!$B$252 -> 3000
A12: shop | B12: ='Per Layanan'!$B$319 -> 158000 | C12: ='Per Layanan'!$B$280 -> 1000 | D12: ='Per Layanan'!$B$293 -> 0 | E12: ='Per Layanan'!$B$294 -> 0 | F12: ='Per Layanan'!$B$295 -> 0 | G12: ='Per Layanan'!$B$310 -> 2235 | H12: ='Per Layanan'!$B$298 -> 0 | I12: ='Per Layanan'!$B$299 -> 166450 | J12: ='Per Layanan'!$B$284 -> platform | K12: =IF(OR(J12<>"platform",A12="travel",I12<=0),0,IFERROR(ROUND(I12*INDEX('Biaya PG'!$D$7:$D$20,MATCH($C$4,'Biaya PG'!$A$7:$A$20,0)),0)+INDEX('Biaya PG'!$E$7:$E$20,MATCH($C$4,'Biaya PG'!$A$7:$A$20,0)),0)+IF(INDEX('Biaya PG'!$F$7:$F$20,MATCH($C$4,'Biaya PG'!$A$7:$A$20,0))="Ya",0,ROUND(IFERROR(ROUND(I12*INDEX('Biaya PG'!$D$7:$D$20,MATCH($C$4,'Biaya PG'!$A$7:$A$20,0)),0)+INDEX('Biaya PG'!$E$7:$E$20,MATCH($C$4,'Biaya PG'!$A$7:$A$20,0)),0)*INDEX('Biaya PG'!$G$7:$G$20,MATCH($C$4,'Biaya PG'!$A$7:$A$20,0)),0))) -> 1165 | L12: ='Per Layanan'!$B$306 -> 14215 | M12: ='Per Layanan'!$B$312 -> 3235
A13: market | B13: ='Per Layanan'!$B$379 -> 40000 | C13: ='Per Layanan'!$B$340 -> 1000 | D13: ='Per Layanan'!$B$353 -> 0 | E13: ='Per Layanan'!$B$354 -> 0 | F13: ='Per Layanan'!$B$355 -> 0 | G13: ='Per Layanan'!$B$370 -> 2400 | H13: ='Per Layanan'!$B$358 -> 0 | I13: ='Per Layanan'!$B$359 -> 49000 | J13: ='Per Layanan'!$B$344 -> platform | K13: =IF(OR(J13<>"platform",A13="travel",I13<=0),0,IFERROR(ROUND(I13*INDEX('Biaya PG'!$D$7:$D$20,MATCH($C$4,'Biaya PG'!$A$7:$A$20,0)),0)+INDEX('Biaya PG'!$E$7:$E$20,MATCH($C$4,'Biaya PG'!$A$7:$A$20,0)),0)+IF(INDEX('Biaya PG'!$F$7:$F$20,MATCH($C$4,'Biaya PG'!$A$7:$A$20,0))="Ya",0,ROUND(IFERROR(ROUND(I13*INDEX('Biaya PG'!$D$7:$D$20,MATCH($C$4,'Biaya PG'!$A$7:$A$20,0)),0)+INDEX('Biaya PG'!$E$7:$E$20,MATCH($C$4,'Biaya PG'!$A$7:$A$20,0)),0)*INDEX('Biaya PG'!$G$7:$G$20,MATCH($C$4,'Biaya PG'!$A$7:$A$20,0)),0))) -> 343 | L13: ='Per Layanan'!$B$366 -> 16600 | M13: ='Per Layanan'!$B$372 -> 3400
A14: box | B14: ='Per Layanan'!$B$439 -> 113000 | C14: ='Per Layanan'!$B$400 -> 2000 | D14: ='Per Layanan'!$B$413 -> 11300 | E14: ='Per Layanan'!$B$414 -> 0 | F14: ='Per Layanan'!$B$415 -> 0 | G14: ='Per Layanan'!$B$430 -> 0 | H14: ='Per Layanan'!$B$418 -> 0 | I14: ='Per Layanan'!$B$419 -> 115000 | J14: ='Per Layanan'!$B$404 -> platform | K14: =IF(OR(J14<>"platform",A14="travel",I14<=0),0,IFERROR(ROUND(I14*INDEX('Biaya PG'!$D$7:$D$20,MATCH($C$4,'Biaya PG'!$A$7:$A$20,0)),0)+INDEX('Biaya PG'!$E$7:$E$20,MATCH($C$4,'Biaya PG'!$A$7:$A$20,0)),0)+IF(INDEX('Biaya PG'!$F$7:$F$20,MATCH($C$4,'Biaya PG'!$A$7:$A$20,0))="Ya",0,ROUND(IFERROR(ROUND(I14*INDEX('Biaya PG'!$D$7:$D$20,MATCH($C$4,'Biaya PG'!$A$7:$A$20,0)),0)+INDEX('Biaya PG'!$E$7:$E$20,MATCH($C$4,'Biaya PG'!$A$7:$A$20,0)),0)*INDEX('Biaya PG'!$G$7:$G$20,MATCH($C$4,'Biaya PG'!$A$7:$A$20,0)),0))) -> 805 | L14: ='Per Layanan'!$B$426 -> 101700 | M14: ='Per Layanan'!$B$432 -> 13300
A15: travel | B15: ='Per Layanan'!$B$499 -> 300000 | C15: ='Per Layanan'!$B$460 -> 5000 | D15: ='Per Layanan'!$B$473 -> 0 | E15: ='Per Layanan'!$B$474 -> 0 | F15: ='Per Layanan'!$B$475 -> 30000 | G15: ='Per Layanan'!$B$490 -> 0 | H15: ='Per Layanan'!$B$478 -> 0 | I15: ='Per Layanan'!$B$479 -> 305000 | J15: ='Per Layanan'!$B$464 -> platform | K15: =IF(OR(J15<>"platform",A15="travel",I15<=0),0,IFERROR(ROUND(I15*INDEX('Biaya PG'!$D$7:$D$20,MATCH($C$4,'Biaya PG'!$A$7:$A$20,0)),0)+INDEX('Biaya PG'!$E$7:$E$20,MATCH($C$4,'Biaya PG'!$A$7:$A$20,0)),0)+IF(INDEX('Biaya PG'!$F$7:$F$20,MATCH($C$4,'Biaya PG'!$A$7:$A$20,0))="Ya",0,ROUND(IFERROR(ROUND(I15*INDEX('Biaya PG'!$D$7:$D$20,MATCH($C$4,'Biaya PG'!$A$7:$A$20,0)),0)+INDEX('Biaya PG'!$E$7:$E$20,MATCH($C$4,'Biaya PG'!$A$7:$A$20,0)),0)*INDEX('Biaya PG'!$G$7:$G$20,MATCH($C$4,'Biaya PG'!$A$7:$A$20,0)),0))) -> 0 | L15: ='Per Layanan'!$B$486 -> 0 | M15: ='Per Layanan'!$B$492 -> 35000
A17: B. Input volume & biaya per kota (ILUSTRASI — ganti dengan rencana/hasil pilot)
A18: Input | B18: Satuan | C18: Kota pilot A | D18: Kota B (opsional) | E18: Label
A19: Nama kota | C19: Kota Pilot A | D19: Kota B
A20: Order selesai/bulan — ride_motor | B20: order | C20: 0 | D20: 0 | E20: ASUMSI ILUSTRASI (pilot fokus send + food)
A21: Order selesai/bulan — ride_car | B21: order | C21: 0 | D21: 0 | E21: ASUMSI ILUSTRASI (pilot fokus send + food)
A22: Order selesai/bulan — food | B22: order | C22: 2400 | D22: 0 | E22: ASUMSI ILUSTRASI (pilot fokus send + food)
A23: Order selesai/bulan — send | B23: order | C23: 3000 | D23: 0 | E23: ASUMSI ILUSTRASI (pilot fokus send + food)
A24: Order selesai/bulan — shop | B24: order | C24: 0 | D24: 0 | E24: ASUMSI ILUSTRASI (pilot fokus send + food)
A25: Order selesai/bulan — market | B25: order | C25: 0 | D25: 0 | E25: ASUMSI ILUSTRASI (pilot fokus send + food)
A26: Order selesai/bulan — box | B26: order | C26: 0 | D26: 0 | E26: ASUMSI ILUSTRASI (pilot fokus send + food)
A27: Order selesai/bulan — travel | B27: order | C27: 0 | D27: 0 | E27: ASUMSI ILUSTRASI (pilot fokus send + food)
A28: % order dibayar lewat gateway (digital) | B28: % | C28: 0.3 | D28: 0 | E28: ASUMSI — gateway per order default OFF; AntarPay harus OFF
A29: Hari iklan "Boost Terdekat" terjual/bulan | B29: hari | C29: 60 | D29: 0 | E29: ASUMSI ILUSTRASI (mis. 2 merchant × 30 hari)
A30: Hari iklan "Unggulan Beranda" terjual/bulan | B30: hari | C30: 30 | D30: 0 | E30: ASUMSI ILUSTRASI
A31: Minggu "Banner Kategori" terjual/bulan | B31: minggu | C31: 4 | D31: 0 | E31: ASUMSI ILUSTRASI
... A39: Biaya tetap — lainnya | B39: Rp | C39: 1000000 | D39: 0 | E39: ASUMSI ILUSTRASI
A41: C. Hasil per kota (rumus) — definisi exec_report_v2 (0103)
A42: Baris | B42: Rumus | C42: Kota pilot A | D42: Kota B | E42: Total
A43: Order selesai | B43: Σ order | C43: =SUM(C$20:C$27) -> 5400 | D43: =SUM(D$20:D$27) -> 0 | E43: =C43+D43 -> 5400
A44: GMV bersih | B44: Σ order × (barang + ongkir) | C44: =SUMPRODUCT(C$20:C$27,$B$8:$B$15) -> 187200000 | D44: =SUMPRODUCT(D$20:D$27,$B$8:$B$15) -> 0 | E44: =C44+D44 -> 187200000
A45: Pendapatan — fee merchant/mitra | B45: Σ order × fee | C45: =SUMPRODUCT(C$20:C$27,$F$8:$F$15) -> 21600000 | D45: =SUMPRODUCT(D$20:D$27,$F$8:$F$15) -> 0 | E45: =C45+D45 -> 21600000
A46: Pendapatan — biaya platform pelanggan | B46: Σ order × biaya platform | C46: =SUMPRODUCT(C$20:C$27,$C$8:$C$15) -> 13800000 | D46: =SUMPRODUCT(D$20:D$27,$C$8:$C$15) -> 0 | E46: =C46+D46 -> 13800000
A47: Pendapatan — komisi driver (kotor) | B47: Σ order × komisi | C47: =SUMPRODUCT(C$20:C$27,$D$8:$D$15) -> 0 | D47: =SUMPRODUCT(D$20:D$27,$D$8:$D$15) -> 0 | E47: =C47+D47 -> 0
A48: Pendapatan — jasa belanja bagian platform | B48: Σ order × jasa platform | C48: =SUMPRODUCT(C$20:C$27,$G$8:$G$15) -> 0 | D48: =SUMPRODUCT(D$20:D$27,$G$8:$G$15) -> 0 | E48: =C48+D48 -> 0
A49: Pendapatan — iklan/boost | B49: hari × harga (Asumsi) | C49: =C29*Asumsi!$C$35+C30*Asumsi!$C$34+C31*Asumsi!$C$36 -> 1850000 | D49: =D29*Asumsi!$C$35+D30*Asumsi!$C$34+D31*Asumsi!$C$36 -> 0 | E49: =C49+D49 -> 1850000
A50: Dikurangi — promo ditanggung platform | B50: Σ order × promo platform | C50: =SUMPRODUCT(C$20:C$27,$H$8:$H$15) -> 0 | D50: =SUMPRODUCT(D$20:D$27,$H$8:$H$15) -> 0 | E50: =C50+D50 -> 0
A51: revenue_net (pembilang take rate) | B51: Σ sumber − promo platform | C51: =C45+C46+C47+C48+C49-C50 -> 37250000 | D51: =D45+D46+D47+D48+D49-D50 -> 0 | E51: =C51+D51 -> 37250000
...

Sheet Legenda
A1: Legenda & cara pakai
A3: Kode | B3: Arti
A4: Teks biru | B4: Input / asumsi yang boleh diubah untuk simulasi.
A5: Teks hitam | B5: Rumus — jangan ditimpa.
A6: Teks hijau | B6: Tautan ke sheet lain.
A7: Isian kuning | B7: Sel yang diharapkan diisi pengguna (volume, biaya, hasil pilot).
A8: Isian hijau muda | B8: Keluaran kunci (driver_payable, platform_revenue, contribution, take rate, EBITDA).
A9: FAKTA SUMBER | B9: Dari dokumen keputusan 23 Sep 2026 atau PKS Midtrans Ver.Aug-26.
A10: FAKTA KODE | B10: Nilai yang sudah ada di kode/DB sebelum v2 (pricing, app_settings, pricing_sessions).
A11: ASUMSI | B11: Usulan; wajib bisa diubah dari Panel Admin (PIN + audit). Ganti dengan keputusan komisaris / data.
A12: HASIL PILOT | B12: Belum ada. Diisi dari exec_report_v2 setelah pilot berjalan.
A13: ILUSTRASI | B13: Angka contoh supaya model menghitung — BUKAN proyeksi dan bukan target.
A16: Cara pakai:
A17: 1. Asumsi: ubah komisi/fee/biaya platform per layanan (Tabel 1) dan parameter (Tabel 2). Nilai produksi diubah di Panel Admin › Aturan Bisnis (service_economics) dan Otomasi/app_settings.
A18: 2. Biaya PG: tarif PKS per saluran; ubah nominal di B3 untuk melihat biaya & dana bersih per saluran.
A19: 3. Per Layanan: ubah input biru pada blok layanan (ongkir, nilai barang, promo & pemiliknya, saluran, tip, bonus sesi). Semua baris alokasi = ledger_calc 0099.
A20: 4. Blok UJI SILANG jangan diubah: input = skenario log uji; kolom Selisih harus 0 dan status LULUS.
A21: 5. Bulanan: isi volume order per layanan per kota, % digital, iklan, variable_ops, biaya tetap → take rate bersih, contribution, EBITDA kota. Isi nilai pilot di tabel gerbang.
A22: Rumus kunci: take rate bersih = (fee merchant + biaya platform pelanggan + komisi + jasa belanja platform + iklan − promo platform) ÷ GMV bersih (barang + ongkir order selesai tidak direfund).
A23: Contribution = revenue_net − insentif driver − biaya PG ditanggung platform − biaya PG hangus (refund) − variable_ops − biaya payout. EBITDA kota = Σ contribution − biaya tetap kota.
A24: Keterbatasan: pembulatan mengikuti PostgreSQL (floor untuk komisi/fee, round untuk PG). Travel titipan antar kota, helper AntarBox terpisah, refund & biaya PG hangus tidak dimodelkan per order.
A25: Batasan data: angka FAKTA SUMBER diambil dari dokumen keputusan 23 Sep 2026, PKS Midtrans Ver.Aug-26 (M568767786_825925) dan kode migrasi 0098–0104; angka ASUMSI adalah usulan yang wajib diubah dari Panel Admin; belum ada HASIL PILOT. Volume & biaya tetap di sheet Bulanan adalah ILUSTRASI, bukan proyeksi. Uji silang memakai log DB lokal /tmp/antarkita-db-lokal/test-uji_skema_bisnis_v2.sql.log (23 Sep 2026), bukan data produksi.
